<?xml version='1.0' encoding='utf-8'?>
<mujoco model="zhiyuan scene">
  <compiler angle="radian" eulerseq="XYZ" meshdir="../meshes" autolimits="true" />

  <option timestep="0.001" />

  <visual>
    <global azimuth="150" elevation="-20" />
    <headlight ambient="0.3 0.3 0.3" diffuse="0.6 0.6 0.6" specular="0 0 0" />
    <scale forcewidth="0.03" contactwidth="0.01" contactheight="0.02" com="1" framelength="0.6" framewidth="0.05" />
    <rgba haze="0.15 0.25 0.35 1" com="0.502 1 0 0.5" contactpoint="1 1 0.6 0.4" contactforce="0.98 0.4 0.4 1" />
  </visual>

  <default>
    <geom contype="0" conaffinity="0" solref="0.005 1" condim="3" friction="1 1" />
    <joint />
    <equality solref="0.005 1" />
    <default class="zhiyuan">
    </default>
    <default class="collision">
      <geom contype="1" group="3" type="capsule" />
      <default class="collision-left">
        <geom contype="2" conaffinity="4" />
      </default>
      <default class="collision-right">
        <geom contype="4" conaffinity="2" />
      </default>
    </default>
  </default>
  <asset>
    <mesh name="base_link_simple" file="base_link_simple.STL" />
    <mesh name="body_yaw" file="lumbar_yaw.STL" />
    <mesh name="body_roll" file="lumbar_roll.STL" />
    <mesh name="body_pitch" file="lumbar_pitch.stl" />
    <mesh name="left_shoulder_pitch" file="left_shoulder_pitch.STL" />
    <mesh name="left_shoulder_roll" file="left_shoulder_roll.STL" />
    <mesh name="left_shoulder_yaw" file="left_shoulder_yaw.STL" />
    <mesh name="left_elbow_pitch" file="left_elbow_pitch.STL" />
    <mesh name="left_elbow_yaw" file="left_elbow_yaw.STL" />
    <mesh name="left_wrist_pitch" file="left_wrist_pitch.STL" />
    <mesh name="left_wrist_roll" file="left_wrist_roll.STL" />
    <mesh name="right_shoulder_pitch" file="right_shoulder_pitch.STL" />
    <mesh name="right_shoulder_roll" file="right_shoulder_roll.STL" />
    <mesh name="right_shoulder_yaw" file="right_shoulder_yaw.STL" />
    <mesh name="right_elbow_pitch" file="right_elbow_pitch.STL" />
    <mesh name="right_elbow_yaw" file="right_elbow_yaw.STL" />
    <mesh name="right_wrist_pitch" file="right_wrist_pitch.STL" />
    <mesh name="right_wrist_roll" file="right_wrist_roll.STL" />
    <mesh name="left_hip_pitch" file="left_hip_pitch.STL" />
    <mesh name="left_hip_roll" file="left_hip_roll.STL" />
    <mesh name="left_hip_yaw" file="left_hip_yaw.STL" />
    <mesh name="left_knee_pitch" file="left_knee_pitch.STL" />
    <mesh name="left_ankle_pitch" file="left_ankle_pitch.STL" />
    <mesh name="left_ankle_roll" file="left_ankle_roll.STL" />
    <mesh name="right_hip_pitch" file="right_hip_pitch.STL" />
    <mesh name="right_hip_roll" file="right_hip_roll.STL" />
    <mesh name="right_hip_yaw" file="right_hip_yaw.STL" />
    <mesh name="right_knee_pitch" file="right_knee_pitch.STL" />
    <mesh name="right_ankle_pitch" file="right_ankle_pitch.STL" />
    <mesh name="right_ankle_roll" file="right_ankle_roll.STL" />
    <mesh name="waist_motor_a" file="waist_motor_a_link.STL" />
    <mesh name="waist_motor_a_ball" file="waist_motor_a_ball.STL" />
    <mesh name="waist_motor_a_loop" file="waist_motor_a_loop.STL" />
    <mesh name="waist_motor_b" file="waist_motor_b_link.STL" />
    <mesh name="waist_motor_b_ball" file="waist_motor_b_ball.STL" />
    <mesh name="waist_motor_b_loop" file="waist_motor_b_loop.STL" />
    <mesh name="leg_l_toe_a" file="leg_l_toe_a_link.STL" />
    <mesh name="leg_l_toe_a_ball" file="leg_l_toe_a_ball.STL" />
    <mesh name="leg_l_toe_a_loop" file="leg_l_toe_a_loop.STL" />
    <mesh name="leg_l_toe_b" file="leg_l_toe_b_link.STL" />
    <mesh name="leg_l_toe_b_ball" file="leg_l_toe_b_ball.STL" />
    <mesh name="leg_l_toe_b_loop" file="leg_l_toe_b_loop.STL" />
    <mesh name="leg_r_toe_a" file="leg_r_toe_a_link.STL" />
    <mesh name="leg_r_toe_a_ball" file="leg_r_toe_a_ball.STL" />
    <mesh name="leg_r_toe_a_loop" file="leg_r_toe_a_loop.STL" />
    <mesh name="leg_r_toe_b" file="leg_r_toe_b_link.STL" />
    <mesh name="leg_r_toe_b_ball" file="leg_r_toe_b_ball.STL" />
    <mesh name="leg_r_toe_b_loop" file="leg_r_toe_b_loop.STL" />
    <mesh name="arm_r_wrist_a_ball" file="arm_r_wrist_a_ball.STL" />
    <mesh name="arm_r_wrist_motor_a" file="arm_r_wrist_motor_a_link.STL" />
    <mesh name="arm_r_wrist_a_loop" file="arm_r_wrist_a_loop.STL" />
    <mesh name="arm_r_wrist_b_ball" file="arm_r_wrist_b_ball.STL" />
    <mesh name="arm_r_wrist_motor_b" file="arm_r_wrist_motor_b_link.STL" />
    <mesh name="arm_r_wrist_b_loop" file="arm_r_wrist_b_loop.STL" />
    <!-- arm_l wrist uses same STL files as arm_r (symmetric geometry, no separate left mesh exists) -->
    <mesh name="arm_l_wrist_a_ball" file="arm_r_wrist_a_ball.STL" />
    <mesh name="arm_l_wrist_motor_a" file="arm_r_wrist_motor_a_link.STL" />
    <mesh name="arm_l_wrist_a_loop" file="arm_r_wrist_a_loop.STL" />
    <mesh name="arm_l_wrist_b_ball" file="arm_r_wrist_b_ball.STL" />
    <mesh name="arm_l_wrist_motor_b" file="arm_r_wrist_motor_b_link.STL" />
    <mesh name="arm_l_wrist_b_loop" file="arm_r_wrist_b_loop.STL" />
    <mesh name="neck_motor_base" file="neck_motor_base.stl" />
    <mesh name="neck_motor_bracket" file="neck_motor_bracket.stl" />
    <mesh name="head_face_bracket" file="head_face_bracket.stl" />
    <mesh name="camera_mesh" file="Camera.stl" />
    <mesh name="radar_mesh" file="radar.stl" />
  </asset>
  <worldbody>
    <body name="base_link" pos="0 0 0.7">
      <inertial pos="0.00252285 -0.00063439 0.03023409" mass="4.3041648" quat="-0.49993409 0.50022042 0.50515004 -0.49464013" diaginertia="0.01083013 0.021810116 0.026806174" />
      <freejoint name="floating_base" />
      <geom type="mesh" rgba="0.8 0.4 0 1" mesh="base_link_simple" />
      <geom type="mesh" rgba="0.8 0.4 0 1" mesh="base_link_simple" class="collision" />
      <camera name="track" pos="0 -3 1" quat="0.850651 0.525731 0 0" mode="track" />
      <site name="imu" size="0.01" pos="0 0 0" />
      <body name="lumbar_yaw_link" pos="0.00245 0 0.11553403" quat="1 0 0 -2.274557e-05">
        <inertial pos="-0.01800066 1.4e-06 0.02432982" mass="0.36251906" quat="0.99348394 2.3462644e-05 0.11397217 -1.2536067e-05" diaginertia="0.00034245685 0.00045823 0.00065509315" />
        <joint name="lumbar_yaw_joint" type="hinge" pos="0 0 0" axis="0 0 1" range="-1 1" damping="1" /><geom type="mesh" mesh="body_yaw" pos="0 0 0" rgba="1 0.4 0.4 1" />
        <body name="lumbar_roll_link" pos="0 0 0.0405" quat="0.5 0.5 -0.5 -0.5">
          <inertial pos="-0.00029919 0.0003642 -0.00019197" mass="0.03412073" quat="0.53529739 0.56270362 0.3392439 -0.53078707" diaginertia="4.8125283e-06 4.9030789e-06 5.4643928e-06" />
          <joint name="lumbar_roll_joint" type="hinge" pos="0 0 0" axis="0 0 1" range="-0.25 0.25" damping="1" /><geom type="mesh" mesh="body_roll" pos="0 0 0" rgba="1 1 0.4 1" />
          <body name="lumbar_pitch_link" pos="0 0 0" quat="0.70710678 0 0.70710678 0">
            <inertial pos="0.00070244 0.14952141 -0.00117164" mass="6.0571074" quat="-0.69573022 0.11263744 0.70350979 0.091357738" diaginertia="0.027806014 0.05075072 0.065134366" />
            <joint name="lumbar_pitch_joint" type="hinge" pos="0 0 0" axis="0 0 -1" range="-0.15 0.45" damping="1" /><geom type="mesh" mesh="body_pitch" pos="0 0 0" rgba="0.4 1 0.4 1" />
            <geom type="mesh" mesh="body_pitch" pos="0 0 0" rgba="0.4 1 0.4 1" class="collision" />
            <!-- ============================================================ -->
            <!-- Head and Sensor Assembly (with STL meshes)                   -->
            <!-- Hierarchy: lumbar_pitch(under_head) -> neck_motor_base       -->
            <!--   -> neck_motor_bracket -> head_face_bracket -> camera/radar -->
            <!-- ============================================================ -->
            <body name="neck_motor_base_link" pos="0.00346 0.33192 0" quat="0.70710548 0 -0.70710808 0">
              <inertial pos="0 0 0" mass="0.541" quat="0.51059377 0.48668698 -0.49324001 0.50906196" diaginertia="0.0004726761 0.00049075728 0.00058445244" />
              <geom type="mesh" mesh="neck_motor_base" pos="-0.05299 -0.11067 -0.09204" rgba="0.4 1 0.4 1" />
              <body name="neck_motor_bracket_link" pos="8e-05 0.04576 0.00221" quat="1 0 0 0">
                <inertial pos="0 0 0" mass="0.446" quat="0.70919188 0 0 0.70501552" diaginertia="0.00016127002 0.00017751895 0.00022081585" />
                <geom type="mesh" mesh="neck_motor_bracket" pos="-0.05307 -0.15643 -0.09425" rgba="1 1 0.4 1" />
                <body name="head_face_bracket_link" pos="0 0.02357 0" quat="1 0 0 0">
                  <inertial pos="2e-05 0.06697 -0.01725" mass="0.275" quat="-0.70208279 -0.050490755 -0.053323741 0.70829868" diaginertia="0.00058251156 0.00068126691 0.00091370933" />
                  <geom type="mesh" mesh="head_face_bracket" pos="-0.05307 -0.18000 -0.09425" rgba="1 0.4 0.4 1" />
                  <body name="camera_link" pos="-2e-05 0.10364 -0.03848" quat="1 0 0 0">
                    <inertial pos="0 0 0" mass="0.072" quat="0.79234407 0.61007448 -1.2972609e-05 3.5506836e-05" diaginertia="6.3485711e-06 4.3137042e-05 4.357833e-05" />
                    <geom type="mesh" mesh="camera_mesh" pos="-0.05305 -0.28364 -0.05577" rgba="0.4 1 0.4 1" />
                    <geom type="mesh" mesh="camera_mesh" pos="-0.05305 -0.28364 -0.05577" class="collision" />
                    <camera name="front_camera" pos="0 0 0" resolution="640 480" fovy="45" mode="fixed" />
                  </body>
                  <body name="radar_link" pos="0.00015 0.07105 0.00663" quat="1 0 0 0">
                    <inertial pos="0 0 0" mass="0.223" quat="-0.70705773 0.70713572 0.0025899536 -0.0046613302" diaginertia="0.00010892929 0.00011018791 0.00013338995" />
                    <geom type="mesh" mesh="radar_mesh" pos="-0.05322 -0.25105 -0.10088" rgba="0.2 0.2 0.8 1" />
                    <geom type="mesh" mesh="radar_mesh" pos="-0.05322 -0.25105 -0.10088" class="collision" />
                    <site name="lidar_site" pos="0 0 0" size="0.01" rgba="1 0 0 0" euler="0 1.57 0" />
                  </body>
                </body>
              </body>
            </body>
            <body name="left_shoulder_pitch_link" pos="0 0.256 -0.1458" quat="0 0 0 -1" gravcomp="0">
              <inertial pos="-0.00251212 -0.00149141 -0.05674475" mass="1.0067875" quat="-0.67979561 -0.055012575 0.72872618 -0.061722725" diaginertia="0.0008533978 0.00095816181 0.0010856204" />
              <joint name="left_shoulder_pitch_joint" type="hinge" pos="0 0 0" axis="0 0 -1" range="-2.5 1.5" damping="1" /><geom type="mesh" mesh="left_shoulder_pitch" pos="0 0 0" rgba="1 0.4 0.4 1" />
              <body name="left_shoulder_roll_link" pos="-0.0313 0 -0.0592" quat="0.70710548 0 -0.70710808 0" gravcomp="0">
                <inertial pos="0.000154 0.07784637 -0.02711338" mass="0.69169508" quat="-0.53585784 -0.46185342 0.5464353 0.44828145" diaginertia="0.00063698245 0.0011961138 0.0013367737" />
                <joint name="left_shoulder_roll_joint" type="hinge" pos="0 0 0" axis="0 0 -1" range="-2 0" damping="1" /><geom type="mesh" mesh="left_shoulder_roll" pos="0 0 0" rgba="1 1 0.4 1" />
                <body name="left_shoulder_yaw_link" pos="0 0.1252 -0.0313" quat="0.5 0.5 0.5 -0.5" gravcomp="0">
                  <inertial pos="-2.68e-06 0.00182113 -0.00392718" mass="0.72559372" quat="-0.46931073 0.5297545 -0.51442063 -0.48423033" diaginertia="0.0004812039 0.0011604112 0.0011833549" />
                  <joint name="left_shoulder_yaw_joint" type="hinge" pos="0 0 0" axis="0 0 1" range="-1.8 1.8" damping="1" /><geom type="mesh" mesh="left_shoulder_yaw" pos="0 0 0" rgba="0.4 1 0.4 1" />
                  <body name="left_elbow_pitch_link" pos="0 -0.031 -0.0365" quat="0.70710678 -0.70710678 0 0" gravcomp="0">
                    <inertial pos="2.604e-05 0.07528242 0.0268658" mass="0.69780135" quat="0.42216492 0.56749847 -0.42219566 -0.56698597" diaginertia="0.00061435924 0.0010006506 0.0011626702" />
                    <joint name="left_elbow_pitch_joint" type="hinge" pos="0 0 0" axis="0 0 1" range="0 2" damping="1" /><geom type="mesh" mesh="left_elbow_pitch" pos="0 0 0" rgba="0 0.5 1 1" />
                    <body name="left_elbow_yaw_link" pos="0 0.117 0.031" quat="0.49999908 0.49999908 -0.50000092 0.50000092" gravcomp="0">
                      <inertial pos="3.656e-05 0.00424199 -0.05421422" mass="0.28787886" quat="0.70530782 0.060241355 -0.70390283 -0.058588874" diaginertia="0.00054032221 0.0007024769 0.00071486088" />
                      <joint name="left_elbow_yaw_joint" type="hinge" pos="0 0 0" axis="0 0 1" range="-1.8 1.8" damping="1" /><geom type="mesh" mesh="left_elbow_yaw" pos="0 0 0" rgba="0.8 1 0.8 1" />
                      <body name="left_wrist_pitch_link" pos="0.006 9.9998e-05 -0.1394" quat="0.707105 0.707108 0 0" gravcomp="0">
                        <inertial pos="-9.994e-05 0 0.00229425" mass="0.00900738" quat="0 0 0.70710678 0.70710678" diaginertia="2.4e-07 3.8e-07 5.7e-07" />
                        <joint name="left_wrist_pitch_joint" type="hinge" pos="0 0 0" axis="0 0 -1" range="-0.4 0.4" damping="1" /><geom type="mesh" mesh="left_wrist_pitch" pos="0 0 0" rgba="1 0.5 1 1" />
                        <body name="left_wrist_roll_link" pos="0 0 0" quat="0.707106 7.94894e-07 0.707108 7.94894e-07" gravcomp="0">
                          <inertial pos="-0.019731143 0.0013385766 -0.032177575" mass="0.370899" quat="-0.4749023 0.52488147 0.48897771 -0.50977255" diaginertia="0.000211598 0.000356841 0.000404077" />
                          <joint name="left_wrist_roll_joint" type="hinge" pos="0 0 0" axis="0 0 -1" range="-0.4 0.4" damping="1" />
                          <geom type="mesh" mesh="left_wrist_roll" pos="0 0 0" rgba="1 0.4 0.4 1" />
                        </body>
                      </body>

                    </body>
                  </body>
                </body>
              </body>
            </body>
            <body name="right_shoulder_pitch_link" pos="0 0.256 0.1458" quat="-3.6732051e-06 1 0 0" gravcomp="0">
              <inertial pos="0.00250704 -0.00149173 -0.05674328" mass="1.0067875" quat="0.72873245 -0.062328101 -0.67979179 -0.054289459" diaginertia="0.00085339593 0.00095816816 0.0010856159" />
              <joint name="right_shoulder_pitch_joint" type="hinge" pos="0 0 0" axis="0 0 1" range="-2.5 1.5" damping="1" /><geom type="mesh" mesh="right_shoulder_pitch" pos="0 0 0" rgba="1 0.4 0.4 1" />
              <body name="right_shoulder_roll_link" pos="0.0313 0 -0.0592" quat="-2.5973435e-06 0.70710548 2.597353e-06 0.70710808" gravcomp="0">
                <inertial pos="9.998e-05 -0.07787239 -0.02705625" mass="0.69142604" quat="-0.4594695 -0.53694627 0.45064727 0.54542967" diaginertia="0.00063629365 0.0011970435 0.0013376129" />
                <joint name="right_shoulder_roll_joint" type="hinge" pos="0 0 0" axis="0 0 1" range="-2 0" damping="1" /><geom type="mesh" mesh="right_shoulder_roll" pos="0 0 0" rgba="1 1 0.4 1" />
                <body name="right_shoulder_yaw_link" pos="0 -0.1252 -0.0313" quat="0.70710548 0.70710808 0 0" gravcomp="0">
                  <inertial pos="-0.00189082 -0.00017102 0.03175107" mass="0.604503" quat="0.61216355 0.63014189 0.32261048 -0.35227755" diaginertia="0.00049190455 0.00050515813 0.00055056732" />
                  <joint name="right_shoulder_yaw_joint" type="hinge" pos="0 0 0" axis="0 0 1" range="-1.8 1.8" damping="1" /><geom type="mesh" mesh="right_shoulder_yaw" pos="0 0 0" rgba="0.4 1 0.4 1" />
                  <body name="right_elbow_pitch_link" pos="-0.031 0 0.0365" quat="0.5 -0.5 0.5 -0.5" gravcomp="0">
                    <inertial pos="-2.604e-05 -0.07529828 0.02685625" mass="0.69780135" quat="0.56738015 0.42232355 -0.56686736 -0.42235527" diaginertia="0.00061417119 0.0010011586 0.0011630202" />
                    <joint name="right_elbow_pitch_joint" type="hinge" pos="0 0 0" axis="0 0 -1" range="0 2" damping="1" /><geom type="mesh" mesh="right_elbow_pitch" pos="0 0 0" rgba="0 0.5 1 1" />
                    <body name="right_elbow_yaw_link" pos="0 -0.117 0.031" quat="0.49999908 -0.49999908 -0.50000092 -0.50000092" gravcomp="0">
                      <inertial pos="-3.65e-05 -0.00422926 -0.05414537" mass="0.28835476" quat="0.060262671 0.70530237 -0.058608682 -0.70390483" diaginertia="0.00054035512 0.000703364 0.00071572088" />
                      <joint name="right_elbow_yaw_joint" type="hinge" pos="0 0 0" axis="0 0 -1" range="-1.8 1.8" damping="1" /><geom type="mesh" mesh="right_elbow_yaw" pos="0 0 0" rgba="0.8 1 0.8 1" />
                      <body name="right_wrist_pitch_link" pos="0.006 9.9998e-05 -0.1394" quat="0.707105 0.707108 0 0" gravcomp="0">
                        <inertial pos="-9.994e-05 0 0.00229425" mass="0.00900738" quat="0 0 0.70710678 0.70710678" diaginertia="2.4e-07 3.8e-07 5.7e-07" />
                        <joint name="right_wrist_pitch_joint" type="hinge" pos="0 0 0" axis="0 0 -1" range="-0.4 0.4" damping="1" /><geom type="mesh" mesh="right_wrist_pitch" pos="0 0 0" rgba="1 0.5 1 1" />
                        <body name="right_wrist_roll_link" pos="0 0 0" quat="0.707106 7.94894e-07 0.707108 7.94894e-07" gravcomp="0">
                          <inertial pos="-0.020122254 -0.025856909 -0.01878886" mass="0.370899" quat="-0.67504778 -0.17747674 0.69505523 0.172368" diaginertia="0.000211598 0.000356841 0.000404077" />
                          <joint name="right_wrist_roll_joint" type="hinge" pos="0 0 0" axis="0 0 1" range="-0.4 0.4" damping="1" />
                          <geom type="mesh" mesh="right_wrist_roll" pos="0 0 0" rgba="1 0.4 0.4 1" />
                        </body>
                      </body>

                    </body>
                  </body>
                </body>
              </body>
            </body>

          </body>
        </body>
      </body>
      <body name="left_hip_pitch_link" pos="0.00245 0.092277 -0.012143" quat="0.65328003 0.27059915 -0.27059815 0.65328243" gravcomp="0">
        <inertial pos="-4.816e-05 -0.01075844 -0.05407776" mass="1.6733645" quat="-0.55583853 -0.41053313 -0.43015369 0.58092502" diaginertia="0.0021514249 0.0023446612 0.0025641839" />
        <joint name="left_hip_pitch_joint" type="hinge" pos="0 0 0" axis="0 0 1" range="-1 2" damping="1" />
        <geom type="mesh" mesh="left_hip_pitch" pos="0 0 0" rgba="1 0.4 0.4 1" />
        <body name="left_hip_roll_link" pos="0 -0.0405 -0.0589" quat="0.65328148 0.65328148 0.27059805 -0.27059805" gravcomp="0">
          <inertial pos="0.00014604 -0.04123483 -0.01015339" mass="0.28562185" quat="-0.23594177 0.6650998 0.66693304 0.23911095" diaginertia="0.00027528831 0.00055729377 0.00061295792" />
          <joint name="left_hip_roll_joint" type="hinge" pos="0 0 0" axis="0 0 -1" range="-1.5 0.2" damping="1" />
          <geom type="mesh" mesh="left_hip_roll" pos="0 0 0" rgba="1 1 0.4 1" />
          <body name="left_hip_yaw_link" pos="0 -0.083804916 -0.0406" quat="0.70710678 0.70710678 0 0" gravcomp="0">
            <inertial pos="-0.00212295 -3.062e-05 0.09164842" mass="2.7369623" quat="-0.68378267 0.0022403155 0.72967696 0.0027883451" diaginertia="0.0033874369 0.012449468 0.012747356" />
            <joint name="left_hip_yaw_joint" type="hinge" pos="0 0 0" axis="0 0 -1" range="-1.5 1.5" damping="1" />
            <geom type="mesh" mesh="left_hip_yaw" pos="0 0 0" rgba="0.4 1 0.4 1" />
            <body name="left_knee_pitch_link" pos="-0.0337 0 0.1422" quat="0.5 -0.5 0.5 -0.5" gravcomp="0">
              <inertial pos="-0.000466573 -0.136803 0.0283565" quat="0.549096 0.504801 -0.427727 0.510606" mass="1.68649" diaginertia="0.00989796 0.00939201 0.00196477" />
              <joint name="left_knee_pitch_joint" type="hinge" pos="0 0 0" axis="0 0 1" range="0 2" damping="1" />
              <geom type="mesh" mesh="left_knee_pitch" pos="0 0 0" rgba="0 0.5 1 1" />
              <body name="left_ankle_pitch_link" pos="0 -0.30494 0.0336" quat="0 0 -1 0" gravcomp="0">
                <inertial pos="-2.32e-06 7.077e-05 -2.048e-05" mass="0.06217211" quat="-0.5 0.5 0.5 0.5" diaginertia="6.68e-06 2.273e-05 2.373e-05" />
                <joint name="left_ankle_pitch_joint" type="hinge" pos="0 0 0" axis="0 0 -1" range="-0.41 0.35" damping="1" />
                <geom type="mesh" mesh="left_ankle_pitch" pos="0 0 0" rgba="0.8 1 0.8 1" />
                <body name="left_ankle_roll_link" pos="0 0 0" quat="0.70710678 0 0.70710678 0" gravcomp="0">
                  <inertial pos="0.00017156 -0.02524695 -0.00019936" mass="0.58971207" quat="-0.50741897 0.49044917 0.49158279 0.51022737" diaginertia="0.00054139113 0.0015211445 0.0019006944" />
                  <joint name="left_ankle_roll_joint" type="hinge" pos="0 0 0" axis="0 0 1" range="-0.64 0.64" damping="1" />
                  <geom type="mesh" mesh="left_ankle_roll" pos="0 0 0" rgba="1 0.5 1 1" />
                  <geom type="sphere" size="0.002" pos="0.03 -0.0408 0.07" class="collision" />
                  <geom type="sphere" size="0.02" pos="0.03 -0.0408 0.07" rgba="255 0 0 0.5" />
                  <geom type="sphere" size="0.002" pos="0.03 -0.0408 -0.07" class="collision" />
                  <geom type="sphere" size="0.02" pos="0.03 -0.0408 -0.07" rgba="255 0 0 0.5" />
                  <geom type="sphere" size="0.002" pos="-0.03 -0.0408 0.07" class="collision" />
                  <geom type="sphere" size="0.02" pos="-0.03 -0.0408 0.07" rgba="255 0 0 0.5" />
                  <geom type="sphere" size="0.002" pos="-0.03 -0.0408 -0.07" class="collision" />
                  <geom type="sphere" size="0.02" pos="-0.03 -0.0408 -0.07" rgba="255 0 0 0.5" />
                </body>
              </body>

            </body>
          </body>
        </body>
      </body>
      <body name="right_hip_pitch_link" pos="0.00245 -0.092277 -0.012143" quat="0.65328003 -0.27059915 -0.27059815 -0.65328243" gravcomp="0">
        <inertial pos="-0.00011915 0.01061483 -0.05407727" mass="1.6665735" quat="0.5736407 -0.43321111 -0.40738862 -0.56329298" diaginertia="0.0021331293 0.0023212051 0.0025451856" />
        <joint name="right_hip_pitch_joint" type="hinge" pos="0 0 0" axis="0 0 1" range="-2 1" damping="1" />
        <geom type="mesh" mesh="right_hip_pitch" pos="0 0 0" rgba="1 0.4 0.4 1" />
        <body name="right_hip_roll_link" pos="0 0.0405 -0.0589" quat="0.65328148 0.65328148 0.27059805 -0.27059805" gravcomp="0">
          <inertial pos="-0.00027058 -0.04164617 0.01034263" mass="0.28768793" quat="-0.66237136 0.22470499 0.24666334 0.6707675" diaginertia="0.00028038909 0.00056679462 0.00062656629" />
          <joint name="right_hip_roll_joint" type="hinge" pos="0 0 0" axis="0 0 1" range="-0.2 1.5" damping="1" />
          <geom type="mesh" mesh="right_hip_roll" pos="0 0 0" rgba="1 1 0.4 1" />
          <body name="right_hip_yaw_link" pos="0 -0.077754916 0.0406" quat="0.70710023 -0.70710023 -0.0030441826 0.0030441826" gravcomp="0">
            <inertial pos="-0.00241642 1.672e-05 -0.09704704" mass="2.6963535" quat="0.00054247237 -0.68390305 0.00090981878 0.72957213" diaginertia="0.003325326 0.01225062 0.012579424" />
            <joint name="right_hip_yaw_joint" type="hinge" pos="0 0 0" axis="0 0 1" range="-1.5 1.5" damping="1" />
            <geom type="mesh" mesh="right_hip_yaw" pos="0 0 0" rgba="0.4 1 0.4 1" />
            <body name="right_knee_pitch_link" pos="-0.034775216 0 -0.14795606" quat="0.4978428 0.50214793 0.50214793 0.4978428" gravcomp="0">
              <inertial pos="0.000491832 -0.13745 0.0283321" quat="0.511647 0.42723 -0.504967 0.548361" mass="1.68377" diaginertia="0.00984174 0.00933685 0.00195957" />
              <joint name="right_knee_pitch_joint" type="hinge" pos="0 0 0" axis="0 0 -1" range="0 2" damping="1" />
              <geom type="mesh" mesh="right_knee_pitch" pos="0 0 0" rgba="0 0.5 1 1" />
              <body name="right_ankle_pitch_link" pos="0 -0.30494 0.0336" quat="0 1 0 0" gravcomp="0">
                <inertial pos="2.47e-06 -7.076e-05 -1.763e-05" mass="0.06217211" quat="-0.50014661 -0.49985335 -0.49985335 0.50014661" diaginertia="6.6799941e-06 2.273e-05 2.3730006e-05" />
                <joint name="right_ankle_pitch_joint" type="hinge" pos="0 0 0" axis="0 0 1" range="-0.41 0.35" damping="1" />
                <geom type="mesh" mesh="right_ankle_pitch" pos="0 0 0" rgba="0.8 1 0.8 1" />
                <body name="right_ankle_roll_link" pos="0 0 0" quat="0.70710678 0 0.70710678 0" gravcomp="0">
                  <inertial pos="-2.32e-06 0.02507893 0.00010556" mass="0.59182763" quat="-0.49119535 0.50862693 0.50864236 0.49123185" diaginertia="0.00054236958 0.00151845 0.0018940604" />
                  <joint name="right_ankle_roll_joint" type="hinge" pos="0 0 0" axis="0 0 1" range="-0.64 0.64" damping="1" />
                  <geom type="mesh" mesh="right_ankle_roll" pos="0 0 0" rgba="1 0.5 1 1" />
                  <geom type="sphere" size="0.002" pos="0.03 0.0408 0.07" class="collision" />
                  <geom type="sphere" size="0.02" pos="0.03 0.0408 0.07" rgba="255 0 0 0.5" />
                  <geom type="sphere" size="0.002" pos="0.03 0.0408 -0.07" class="collision" />
                  <geom type="sphere" size="0.02" pos="0.03 0.0408 -0.07" rgba="255 0 0 0.5" />
                  <geom type="sphere" size="0.002" pos="-0.03 0.0408 0.07" class="collision" />
                  <geom type="sphere" size="0.02" pos="-0.03 0.0408 0.07" rgba="255 0 0 0.5" />
                  <geom type="sphere" size="0.002" pos="-0.03 0.0408 -0.07" class="collision" />
                  <geom type="sphere" size="0.02" pos="-0.03 0.0408 -0.07" rgba="255 0 0 0.5" />
                </body>
              </body>

            </body>
          </body>
        </body>
      </body>
    </body>
  </worldbody>
  <actuator>
    <motor name="motor_left_hip_pitch" joint="left_hip_pitch_joint" ctrlrange="-180 180" />
    <motor name="motor_left_hip_roll" joint="left_hip_roll_joint" ctrlrange="-150 150" />
    <motor name="motor_left_hip_yaw" joint="left_hip_yaw_joint" ctrlrange="-150 150" />
    <motor name="motor_left_knee_pitch" joint="left_knee_pitch_joint" ctrlrange="-180 180" />
    <motor name="motor_left_ankle_pitch" joint="left_ankle_pitch_joint" ctrlrange="-80 80" />
    <motor name="motor_left_ankle_roll" joint="left_ankle_roll_joint" ctrlrange="-80 80" />
    <motor name="motor_right_hip_pitch" joint="right_hip_pitch_joint" ctrlrange="-180 180" />
    <motor name="motor_right_hip_roll" joint="right_hip_roll_joint" ctrlrange="-150 150" />
    <motor name="motor_right_hip_yaw" joint="right_hip_yaw_joint" ctrlrange="-150 150" />
    <motor name="motor_right_knee_pitch" joint="right_knee_pitch_joint" ctrlrange="-180 180" />
    <motor name="motor_right_ankle_pitch" joint="right_ankle_pitch_joint" ctrlrange="-80 80" />
    <motor name="motor_right_ankle_roll" joint="right_ankle_roll_joint" ctrlrange="-80 80" />
    <motor name="motor_lumbar_yaw" joint="lumbar_yaw_joint" ctrlrange="-150 150" />
    <motor name="motor_lumbar_roll" joint="lumbar_roll_joint" ctrlrange="-150 150" />
    <motor name="motor_lumbar_pitch" joint="lumbar_pitch_joint" ctrlrange="-180 180" />
    <motor name="motor_left_shoulder_pitch" joint="left_shoulder_pitch_joint" ctrlrange="-20 20" />
    <motor name="motor_left_shoulder_roll" joint="left_shoulder_roll_joint" ctrlrange="-20 20" />
    <motor name="motor_left_shoulder_yaw" joint="left_shoulder_yaw_joint" ctrlrange="-20 20" />
    <motor name="motor_left_elbow_pitch" joint="left_elbow_pitch_joint" ctrlrange="-20 20" />
    <motor name="motor_left_elbow_yaw" joint="left_elbow_yaw_joint" ctrlrange="-20 20" />
    <motor name="motor_left_wrist_pitch" joint="left_wrist_pitch_joint" ctrlrange="-10 10" />
    <motor name="motor_right_shoulder_pitch" joint="right_shoulder_pitch_joint" ctrlrange="-20 20" />
    <motor name="motor_right_shoulder_roll" joint="right_shoulder_roll_joint" ctrlrange="-20 20" />
    <motor name="motor_right_shoulder_yaw" joint="right_shoulder_yaw_joint" ctrlrange="-20 20" />
    <motor name="motor_right_elbow_pitch" joint="right_elbow_pitch_joint" ctrlrange="-20 20" />
    <motor name="motor_right_elbow_yaw" joint="right_elbow_yaw_joint" ctrlrange="-20 20" />
    <motor name="motor_right_wrist_pitch" joint="right_wrist_pitch_joint" ctrlrange="-10 10" />
    <motor name="motor_left_wrist_roll" joint="left_wrist_roll_joint" ctrlrange="-10 10" />
    <motor name="motor_right_wrist_roll" joint="right_wrist_roll_joint" ctrlrange="-10 10" />
  </actuator>
  <sensor>
    <!-- imu sensor -->
    <framequat name="body-orientation" objtype="site" objname="imu" noise="0" />
    <gyro name="body-angular-velocity" site="imu" noise="0.001" />
    <framepos name="body-linear-pos" objtype="site" objname="imu" />
    <velocimeter name="body-linear-vel" site="imu" />
    <accelerometer name="body-linear-acceleration" site="imu" noise="0.001" />

    <!-- pos -->
    <jointpos name="jointpos_lumbar_yaw" joint="lumbar_yaw_joint" noise="0" />
    <jointpos name="jointpos_lumbar_roll" joint="lumbar_roll_joint" noise="0" />
    <jointpos name="jointpos_lumbar_pitch" joint="lumbar_pitch_joint" noise="0" />

    <jointpos name="jointpos_left_shoulder_pitch" joint="left_shoulder_pitch_joint" noise="0" />
    <jointpos name="jointpos_left_shoulder_roll" joint="left_shoulder_roll_joint" noise="0" />
    <jointpos name="jointpos_left_shoulder_yaw" joint="left_shoulder_yaw_joint" noise="0" />
    <jointpos name="jointpos_left_elbow_pitch" joint="left_elbow_pitch_joint" noise="0" />
    <jointpos name="jointpos_left_elbow_yaw" joint="left_elbow_yaw_joint" noise="0" />
    <jointpos name="jointpos_left_wrist_pitch" joint="left_wrist_pitch_joint" noise="0" />
    <jointpos name="jointpos_left_wrist_roll" joint="left_wrist_roll_joint" noise="0" />

    <jointpos name="jointpos_right_shoulder_pitch" joint="right_shoulder_pitch_joint" noise="0" />
    <jointpos name="jointpos_right_shoulder_roll" joint="right_shoulder_roll_joint" noise="0" />
    <jointpos name="jointpos_right_shoulder_yaw" joint="right_shoulder_yaw_joint" noise="0" />
    <jointpos name="jointpos_right_elbow_pitch" joint="right_elbow_pitch_joint" noise="0" />
    <jointpos name="jointpos_right_elbow_yaw" joint="right_elbow_yaw_joint" noise="0" />
    <jointpos name="jointpos_right_wrist_pitch" joint="right_wrist_pitch_joint" noise="0" />
    <jointpos name="jointpos_right_wrist_roll" joint="right_wrist_roll_joint" noise="0" />

    <jointpos name="jointpos_left_hip_pitch" joint="left_hip_pitch_joint" noise="0" />
    <jointpos name="jointpos_left_hip_roll" joint="left_hip_roll_joint" noise="0" />
    <jointpos name="jointpos_left_hip_yaw" joint="left_hip_yaw_joint" noise="0" />
    <jointpos name="jointpos_left_knee_pitch" joint="left_knee_pitch_joint" noise="0" />
    <jointpos name="jointpos_left_ankle_pitch" joint="left_ankle_pitch_joint" noise="0" />
    <jointpos name="jointpos_left_ankle_roll" joint="left_ankle_roll_joint" noise="0" />

    <jointpos name="jointpos_right_hip_pitch" joint="right_hip_pitch_joint" noise="0" />
    <jointpos name="jointpos_right_hip_roll" joint="right_hip_roll_joint" noise="0" />
    <jointpos name="jointpos_right_hip_yaw" joint="right_hip_yaw_joint" noise="0" />
    <jointpos name="jointpos_right_knee_pitch" joint="right_knee_pitch_joint" noise="0" />
    <jointpos name="jointpos_right_ankle_pitch" joint="right_ankle_pitch_joint" noise="0" />
    <jointpos name="jointpos_right_ankle_roll" joint="right_ankle_roll_joint" noise="0" />

    <!-- vel -->
    <jointvel name="jointvel_lumbar_yaw" joint="lumbar_yaw_joint" noise="0" />
    <jointvel name="jointvel_lumbar_roll" joint="lumbar_roll_joint" noise="0" />
    <jointvel name="jointvel_lumbar_pitch" joint="lumbar_pitch_joint" noise="0" />

    <jointvel name="jointvel_left_shoulder_pitch" joint="left_shoulder_pitch_joint" noise="0" />
    <jointvel name="jointvel_left_shoulder_roll" joint="left_shoulder_roll_joint" noise="0" />
    <jointvel name="jointvel_left_shoulder_yaw" joint="left_shoulder_yaw_joint" noise="0" />
    <jointvel name="jointvel_left_elbow_pitch" joint="left_elbow_pitch_joint" noise="0" />
    <jointvel name="jointvel_left_elbow_yaw" joint="left_elbow_yaw_joint" noise="0" />
    <jointvel name="jointvel_left_wrist_pitch" joint="left_wrist_pitch_joint" noise="0" />
    <jointvel name="jointvel_left_wrist_roll" joint="left_wrist_roll_joint" noise="0" />

    <jointvel name="jointvel_right_shoulder_pitch" joint="right_shoulder_pitch_joint" noise="0" />
    <jointvel name="jointvel_right_shoulder_roll" joint="right_shoulder_roll_joint" noise="0" />
    <jointvel name="jointvel_right_shoulder_yaw" joint="right_shoulder_yaw_joint" noise="0" />
    <jointvel name="jointvel_right_elbow_pitch" joint="right_elbow_pitch_joint" noise="0" />
    <jointvel name="jointvel_right_elbow_yaw" joint="right_elbow_yaw_joint" noise="0" />
    <jointvel name="jointvel_right_wrist_pitch" joint="right_wrist_pitch_joint" noise="0" />
    <jointvel name="jointvel_right_wrist_roll" joint="right_wrist_roll_joint" noise="0" />

    <jointvel name="jointvel_left_hip_pitch" joint="left_hip_pitch_joint" noise="0" />
    <jointvel name="jointvel_left_hip_roll" joint="left_hip_roll_joint" noise="0" />
    <jointvel name="jointvel_left_hip_yaw" joint="left_hip_yaw_joint" noise="0" />
    <jointvel name="jointvel_left_knee_pitch" joint="left_knee_pitch_joint" noise="0" />
    <jointvel name="jointvel_left_ankle_pitch" joint="left_ankle_pitch_joint" noise="0" />
    <jointvel name="jointvel_left_ankle_roll" joint="left_ankle_roll_joint" noise="0" />

    <jointvel name="jointvel_right_hip_pitch" joint="right_hip_pitch_joint" noise="0" />
    <jointvel name="jointvel_right_hip_roll" joint="right_hip_roll_joint" noise="0" />
    <jointvel name="jointvel_right_hip_yaw" joint="right_hip_yaw_joint" noise="0" />
    <jointvel name="jointvel_right_knee_pitch" joint="right_knee_pitch_joint" noise="0" />
    <jointvel name="jointvel_right_ankle_pitch" joint="right_ankle_pitch_joint" noise="0" />
    <jointvel name="jointvel_right_ankle_roll" joint="right_ankle_roll_joint" noise="0" />

    <!-- extra sensors -->
    <rangefinder name="lidar_sensor" site="lidar_site" cutoff="10.0" />
  </sensor>
  <keyframe>
    <key name = "home_default" qpos='0 0 0.7 1 0 0 0 0 0 0 0 0 0 0 0 0 0 0 0 0 0 0 0 0 0 0 0 0 0 0 0 0 0 0 0 0'/>
    <key name = "check_pose" qpos = "0 0 0.7 1 0 0 0 0.3 0.3 0.3 0.3 0.3 0.3 0.3 0.3 0.3 0.3 0.3 0.3 0.3 0.3 0.3 0.3 0.3 0.48891 0.06213 -0.33853 0.63204 -0.27224 0. -0.48891 -0.06213 0.33853 0.63204 -0.27224 0."/>
  </keyframe>
</mujoco>