<?xml version='1.0' encoding='utf-8'?>
<mujoco model="f1_29dof">
  <compiler angle="radian" meshdir="../meshes/" fusestatic="false" />

  <default><geom contype="0" conaffinity="0" solref="0.005 1" condim="3" friction="1 1" /><joint /><equality solref="0.005 1" /><default class="collision"><geom contype="1" group="3" type="capsule" /><default class="collision-left"><geom contype="2" conaffinity="4" /></default><default class="collision-right"><geom contype="4" conaffinity="2" /></default></default></default><asset>
    <mesh name="base_link_simple" file="base_link_simple.STL" />
    <mesh name="lumbar_yaw" file="lumbar_yaw.STL" />
    <mesh name="lumbar_roll" file="lumbar_roll.STL" />
    <mesh name="lumbar_pitch" file="lumbar_pitch.stl" />
    <mesh name="left_shoulder_pitch" file="left_shoulder_pitch.STL" />
    <mesh name="left_shoulder_roll" file="left_shoulder_roll.STL" />
    <mesh name="left_shoulder_yaw" file="left_shoulder_yaw.STL" />
    <mesh name="left_elbow_pitch" file="left_elbow_pitch.STL" />
    <mesh name="left_elbow_yaw" file="left_elbow_yaw.STL" />
    <mesh name="left_wrist_pitch" file="left_wrist_pitch.STL" />
    <mesh name="left_wrist_roll" file="left_wrist_roll.STL" />
    <mesh name="right_shoulder_pitch_perfect_mirrored" file="right_shoulder_pitch_perfect_mirrored.STL" />
    <mesh name="right_shoulder_roll_perfect_mirrored" file="right_shoulder_roll_perfect_mirrored.STL" />
    <mesh name="right_shoulder_yaw_perfect_mirrored" file="right_shoulder_yaw_perfect_mirrored.STL" />
    <mesh name="right_elbow_pitch_perfect_mirrored" file="right_elbow_pitch_perfect_mirrored.STL" />
    <mesh name="right_elbow_yaw_perfect_mirrored" file="right_elbow_yaw_perfect_mirrored.STL" />
    <mesh name="right_wrist_pitch_perfect_mirrored" file="right_wrist_pitch_perfect_mirrored.STL" />
    <mesh name="right_wrist_roll_perfect_mirrored" file="right_wrist_roll_perfect_mirrored.STL" />
    <mesh name="waist_motor_a_link" file="waist_motor_a_link.STL" />
    <mesh name="waist_motor_a_ball" file="waist_motor_a_ball.STL" />
    <mesh name="waist_motor_a_loop" file="waist_motor_a_loop.STL" />
    <mesh name="waist_motor_b_link" file="waist_motor_b_link.STL" />
    <mesh name="waist_motor_b_ball" file="waist_motor_b_ball.STL" />
    <mesh name="waist_motor_b_loop" file="waist_motor_b_loop.STL" />
    <mesh name="left_hip_pitch" file="left_hip_pitch.STL" />
    <mesh name="left_hip_roll" file="left_hip_roll.STL" />
    <mesh name="left_hip_yaw" file="left_hip_yaw.STL" />
    <mesh name="left_knee_pitch" file="left_knee_pitch.STL" />
    <mesh name="left_ankle_pitch" file="left_ankle_pitch.STL" />
    <mesh name="left_ankle_roll" file="left_ankle_roll.STL" />
    <mesh name="leg_l_toe_a_link" file="leg_l_toe_a_link.STL" />
    <mesh name="leg_l_toe_a_ball" file="leg_l_toe_a_ball.STL" />
    <mesh name="leg_l_toe_a_loop" file="leg_l_toe_a_loop.STL" />
    <mesh name="leg_l_toe_b_link" file="leg_l_toe_b_link.STL" />
    <mesh name="leg_l_toe_b_ball" file="leg_l_toe_b_ball.STL" />
    <mesh name="leg_l_toe_b_loop" file="leg_l_toe_b_loop.STL" />
    <mesh name="right_hip_pitch_perfect_mirrored" file="right_hip_pitch_perfect_mirrored.STL" />
    <mesh name="right_hip_roll_perfect_mirrored" file="right_hip_roll_perfect_mirrored.STL" />
    <mesh name="right_hip_yaw_perfect_mirrored" file="right_hip_yaw_perfect_mirrored.STL" />
    <mesh name="right_knee_pitch_perfect_mirrored" file="right_knee_pitch_perfect_mirrored.STL" />
    <mesh name="right_ankle_pitch_perfect_mirrored" file="right_ankle_pitch_perfect_mirrored.STL" />
    <mesh name="right_ankle_roll_perfect_mirrored" file="right_ankle_roll_perfect_mirrored.STL" />
    <mesh name="leg_r_toe_a_link_perfect_mirrored" file="leg_r_toe_a_link_perfect_mirrored.STL" />
    <mesh name="leg_r_toe_a_ball_perfect_mirrored" file="leg_r_toe_a_ball_perfect_mirrored.STL" />
    <mesh name="leg_r_toe_a_loop_perfect_mirrored" file="leg_r_toe_a_loop_perfect_mirrored.STL" />
    <mesh name="leg_r_toe_b_link_perfect_mirrored" file="leg_r_toe_b_link_perfect_mirrored.STL" />
    <mesh name="leg_r_toe_b_ball_perfect_mirrored" file="leg_r_toe_b_ball_perfect_mirrored.STL" />
    <mesh name="leg_r_toe_b_loop_perfect_mirrored" file="leg_r_toe_b_loop_perfect_mirrored.STL" />
    <mesh name="arm_r_wrist_a_ball_right_perfect_mirrored" file="arm_r_wrist_a_ball_right_perfect_mirrored.STL" />
    <mesh name="arm_r_wrist_motor_a_link_right_perfect_mirrored" file="arm_r_wrist_motor_a_link_right_perfect_mirrored.STL" />
    <mesh name="arm_r_wrist_a_loop_right_perfect_mirrored" file="arm_r_wrist_a_loop_right_perfect_mirrored.STL" />
    <mesh name="arm_r_wrist_b_ball_right_perfect_mirrored" file="arm_r_wrist_b_ball_right_perfect_mirrored.STL" />
    <mesh name="arm_r_wrist_motor_b_link_right_perfect_mirrored" file="arm_r_wrist_motor_b_link_right_perfect_mirrored.STL" />
    <mesh name="arm_r_wrist_b_loop_right_perfect_mirrored" file="arm_r_wrist_b_loop_right_perfect_mirrored.STL" />
    <mesh name="arm_r_wrist_a_ball" file="arm_r_wrist_a_ball.STL" />
    <mesh name="arm_r_wrist_motor_a_link" file="arm_r_wrist_motor_a_link.STL" />
    <mesh name="arm_r_wrist_a_loop" file="arm_r_wrist_a_loop.STL" />
    <mesh name="arm_r_wrist_b_ball" file="arm_r_wrist_b_ball.STL" />
    <mesh name="arm_r_wrist_motor_b_link" file="arm_r_wrist_motor_b_link.STL" />
    <mesh name="arm_r_wrist_b_loop" file="arm_r_wrist_b_loop.STL" />
    <mesh name="neck_motor_base" file="neck_motor_base.stl" />
    <mesh name="neck_motor_bracket" file="neck_motor_bracket.stl" />
    <mesh name="head_face_bracket" file="head_face_bracket.stl" />
    <mesh name="Camera" file="Camera.stl" />
    <mesh name="radar" file="radar.stl" />
  </asset>

  <worldbody>
    <body name="base_link" pos="0 0 0.7">
      <freejoint name="floating_base" /><site name="imu" size="0.01" pos="0 0 0" /><inertial pos="0.00252285 0 0.0302341" quat="0.707097 0.707097 -0.00381301 0.00381301" mass="4.30416" diaginertia="0.0268062 0.021809 0.0108313" />
      <geom type="mesh" contype="0" conaffinity="0" group="1" density="0" rgba="0.8 0.4 0 1" mesh="base_link_simple" />
      <geom type="mesh" rgba="0.8 0.4 0 1" mesh="base_link_simple" />
      <body name="lumbar_yaw_link" pos="0.00245 0 0.115534" quat="1 0 0 -2.27456e-05">
        <inertial pos="-0.0180007 0 0.0243298" quat="0 0.78309 0 0.621909" mass="0.362519" diaginertia="0.000655093 0.00045823 0.000342457" />
        <joint name="lumbar_yaw_joint" pos="0 0 0" axis="0 0 1" range="-1 1" actuatorfrcrange="-150 150" damping="1" />
        <geom type="mesh" contype="0" conaffinity="0" group="1" density="0" rgba="1 0.4 0.4 1" mesh="lumbar_yaw" />
        <body name="lumbar_roll_link" pos="0 0 0.0405" quat="0.5 0.5 -0.5 -0.5">
          <inertial pos="0 0.0003642 -0.00019197" quat="0.70517 -0.0522985 0.0522985 0.70517" mass="0.0341207" diaginertia="5.43342e-06 4.93e-06 4.81658e-06" />
          <joint name="lumbar_roll_joint" pos="0 0 0" axis="0 0 1" range="-0.25 0.25" actuatorfrcrange="-150 150" damping="1" />
          <geom type="mesh" contype="0" conaffinity="0" group="1" density="0" rgba="1 0.4 0.4 1" mesh="lumbar_roll" />
          <body name="lumbar_pitch_link" quat="0.707107 0 0.707107 0">
            <inertial pos="0.00070244 0.149521 0" quat="0.989604 0 0 -0.14382" mass="6.05711" diaginertia="0.0651257 0.0507325 0.0278329" />
            <joint name="lumbar_pitch_joint" pos="0 0 0" axis="0 0 -1" range="-0.15 0.45" actuatorfrcrange="-180 180" damping="1" />
            <geom type="mesh" contype="0" conaffinity="0" group="1" density="0" rgba="0.4 1 0.4 1" mesh="lumbar_pitch" />
            <body name="left_shoulder_pitch_link" pos="0 0.256 -0.1458" quat="0 0 0 -1">
              <inertial pos="-0.00251212 0 -0.0567447" quat="0.999398 0 -0.0347038 0" mass="1.00679" diaginertia="0.00108216 0.00096162 0.000853399" />
              <joint name="left_shoulder_pitch_joint" pos="0 0 0" axis="0 0 -1" range="-2.5 1.5" actuatorfrcrange="-20 20" damping="1" />
              <geom type="mesh" contype="0" conaffinity="0" group="1" density="0" rgba="1 0.4 0.4 1" mesh="left_shoulder_pitch" />
              <body name="left_shoulder_roll_link" pos="-0.0313 0 -0.0592" quat="0.707105 0 -0.707108 0">
                <inertial pos="0.000154 0 -0.0271134" quat="0.707069 0.707069 -0.00733929 0.00733929" mass="0.691695" diaginertia="0.00133676 0.00117967 0.00065344" />
                <joint name="left_shoulder_roll_joint" pos="0 0 0" axis="0 0 -1" range="-2 0" actuatorfrcrange="-20 20" damping="1" />
                <geom type="mesh" contype="0" conaffinity="0" group="1" density="0" rgba="1 1 0.4 1" mesh="left_shoulder_roll" />
                <body name="left_shoulder_yaw_link" pos="0 0.1252 -0.0313" quat="0.5 0.5 0.5 -0.5">
                  <inertial pos="-2.68e-06 0 -0.00392718" quat="0.707106 -0.000666712 -0.000666712 0.707106" mass="0.725594" diaginertia="0.00117758 0.00116043 0.000486958" />
                  <joint name="left_shoulder_yaw_joint" pos="0 0 0" axis="0 0 1" range="-1.8 1.8" actuatorfrcrange="-20 20" damping="1" />
                  <geom type="mesh" contype="0" conaffinity="0" group="1" density="0" rgba="0.4 1 0.4 1" mesh="left_shoulder_yaw" />
                  <body name="left_elbow_pitch_link" pos="0 -0.031 -0.0365" quat="0.707107 -0.707107 0 0">
                    <inertial pos="2.604e-05 0 0.0268658" quat="0.707107 0.707107 -0.000291816 0.000291816" mass="0.697801" diaginertia="0.00116267 0.00096882 0.00064619" />
                    <joint name="left_elbow_pitch_joint" pos="0 0 0" axis="0 0 1" range="0 2" actuatorfrcrange="-20 20" damping="1" />
                    <geom type="mesh" contype="0" conaffinity="0" group="1" density="0" rgba="0 0.5 1 1" mesh="left_elbow_pitch" />
                    <body name="left_elbow_yaw_link" pos="0 0.117 0.031" quat="0.499999 0.499999 -0.500001 0.500001">
                      <inertial pos="3.656e-05 0 -0.0542142" quat="0.999999 0 0.00108829 0" mass="0.287879" diaginertia="0.000714861 0.00069793 0.000544869" />
                      <joint name="left_elbow_yaw_joint" pos="0 0 0" axis="0 0 1" range="-1.8 1.8" actuatorfrcrange="-20 20" damping="1" />
                      <geom type="mesh" contype="0" conaffinity="0" group="1" density="0" rgba="0.8 1 0.8 1" mesh="left_elbow_yaw" />
                      <body name="left_wrist_pitch_link" pos="0.006 0.0001 -0.1394" quat="0.439542 0.553896 -0.439547 -0.553896">
                        <inertial pos="0.00229425 0 9.994e-05" quat="0.707107 0 0 0.707107" mass="0.00900738" diaginertia="5.7e-07 3.8e-07 2.4e-07" />
                        <joint name="left_wrist_pitch_joint" pos="0 0 0" axis="0 0 -1" range="-0.4 0.4" actuatorfrcrange="-10 10" damping="1" />
                        <geom quat="0.707105 0 0.707108 0" type="mesh" contype="0" conaffinity="0" group="1" density="0" rgba="1 0.5 1 1" mesh="left_wrist_pitch" />
                        <body name="left_wrist_roll_link" quat="0.690886 -0.150583 0.65524 -0.265823">
                          <inertial pos="-0.0197311 0 -0.00133858" quat="1 0 -0.000782388 0" mass="0.370899" diaginertia="0.00040404 0.00035616 0.00021232" />
                          <joint name="left_wrist_roll_joint" pos="0 0 0" axis="0 0 -1" range="-0.4 0.4" actuatorfrcrange="-10 10" damping="1" />
                          <geom quat="0.859973 -0.510131 -0.00744773 0.0125589" type="mesh" contype="0" conaffinity="0" group="1" density="0" rgba="1 0.4 0.4 1" mesh="left_wrist_roll" />
                        </body>
                      </body>
                      <body name="arm_l_wrist_a_ball_link" pos="-0.009 -0.02 -0.0199" quat="0.707105 0.707108 0 0">
                        <inertial pos="0 0 0.00973737" quat="0.497809 0.497809 -0.502182 0.502182" mass="0.235987" diaginertia="7.97703e-05 7.63397e-05 2.519e-05" />
                        <geom type="mesh" contype="0" conaffinity="0" group="1" density="0" rgba="1 1 1 1" mesh="arm_r_wrist_a_ball" />
                        <body name="arm_l_wrist_motor_a_link" pos="0.0027628 -0.097124 0" quat="0.707034 0.707037 0.010054 0.010054">
                          <inertial pos="0 0 0.00973737" quat="0.707107 0 0 0.707107" mass="0.00117982" diaginertia="8e-08 6e-08 2e-08" />
                          <geom type="mesh" contype="0" conaffinity="0" group="1" density="0" rgba="1 1 1 1" mesh="arm_r_wrist_motor_a_link" />
                          <body name="arm_l_wrist_a_loop_link" pos="0 0 0.0132" quat="0.707034 -0.707037 -0.010054 -0.010054">
                            <inertial pos="0 0 -1.922e-05" mass="0.00548041" diaginertia="8e-08 8e-08 7e-08" />
                            <geom type="mesh" contype="0" conaffinity="0" group="1" density="0" rgba="1 1 1 1" mesh="arm_r_wrist_a_loop" />
                          </body>
                        </body>
                      </body>
                      <body name="arm_l_wrist_b_ball_link" pos="-0.009 0.02 -0.0199" quat="0.707105 -0.707108 0 0">
                        <inertial pos="0.00121967 0 0" quat="0.5 0.5 -0.5 0.5" mass="0.0361757" diaginertia="1.731e-05 1.73e-05 4.69e-06" />
                        <geom type="mesh" contype="0" conaffinity="0" group="1" density="0" rgba="1 1 1 1" mesh="arm_r_wrist_b_ball" />
                        <body name="arm_l_wrist_motor_b_link" pos="0.0027628 0.097124 0" quat="0.707034 -0.707037 0.010054 -0.010054">
                          <inertial pos="0.00076586 0 -4.912e-05" quat="0.502182 0.502182 -0.497809 0.497809" mass="0.235987" diaginertia="7.97703e-05 7.63397e-05 2.519e-05" />
                          <geom type="mesh" contype="0" conaffinity="0" group="1" density="0" rgba="1 1 1 1" mesh="arm_r_wrist_motor_b_link" />
                          <body name="arm_l_wrist_b_loop_link" pos="0 0 0.0132" quat="0.707034 0.707037 -0.010054 0.010054">
                            <inertial pos="0 0 0.00973737" quat="0.707107 0 0 0.707107" mass="0.00117982" diaginertia="8e-08 6e-08 2e-08" />
                            <geom type="mesh" contype="0" conaffinity="0" group="1" density="0" rgba="1 1 1 1" mesh="arm_r_wrist_b_loop" />
                          </body>
                        </body>
                      </body>
                    </body>
                  </body>
                </body>
              </body>
            </body>
            <body name="right_shoulder_pitch_link" pos="1.32652e-05 0.256 0.1458" quat="-4.54911e-05 -1.32686e-06 1 -1.32686e-06">
              <inertial pos="-0.00251212 -1.57257e-07 -0.0567447" quat="0.999398 -1.28006e-06 -0.0347038 1.37205e-06" mass="1.00679" diaginertia="0.00108216 0.00096162 0.000853399" />
              <joint name="right_shoulder_pitch_joint" pos="0 0 0" axis="0 0 1" range="-2.5 1.5" actuatorfrcrange="-20 20" damping="1" />
              <geom type="mesh" contype="0" conaffinity="0" group="1" density="0" rgba="1 0.4 0.4 1" mesh="right_shoulder_pitch_perfect_mirrored" />
              <body name="right_shoulder_roll_link" pos="-0.0313 0 -0.0592" quat="-0.707105 -1.87637e-06 0.707109 -1.87637e-06">
                <inertial pos="0.000153928 -7.15389e-08 -0.0271134" quat="0.707069 0.707069 -0.00733929 0.00733929" mass="0.691695" diaginertia="0.00133676 0.00117967 0.00065344" />
                <joint name="right_shoulder_roll_joint" pos="0 0 0" axis="0 0 1" range="-2 0" actuatorfrcrange="-20 20" damping="1" />
                <geom type="mesh" contype="0" conaffinity="0" group="1" density="0" rgba="1 1 0.4 1" mesh="right_shoulder_roll_perfect_mirrored" />
                <body name="right_shoulder_yaw_link" pos="0 -0.1252 -0.0313" quat="0.499998 -0.5 0.5 0.500002">
                  <inertial pos="-2.69042e-06 4.00604e-09 -0.00392718" quat="0.707106 -0.000666712 -0.000666712 0.707106" mass="0.725594" diaginertia="0.00117758 0.00116043 0.000486958" />
                  <joint name="right_shoulder_yaw_joint" pos="0 0 0" axis="0 0 -1" range="-1.8 1.8" actuatorfrcrange="-20 20" damping="1" />
                  <geom type="mesh" contype="0" conaffinity="0" group="1" density="0" rgba="0.4 1 0.4 1" mesh="right_shoulder_yaw_perfect_mirrored" />
                  <body name="right_elbow_pitch_link" pos="0 0.031 -0.0365" quat="0.707105 0.707108 0 0">
                    <inertial pos="2.60126e-05 7.1228e-08 0.0268658" quat="0.707107 0.707107 -0.000291816 0.000291816" mass="0.697801" diaginertia="0.00116267 0.00096882 0.00064619" />
                    <joint name="right_elbow_pitch_joint" pos="0 0 0" axis="0 0 -1" range="0 2" actuatorfrcrange="-20 20" damping="1" />
                    <geom type="mesh" contype="0" conaffinity="0" group="1" density="0" rgba="0 0.5 1 1" mesh="right_elbow_pitch_perfect_mirrored" />
                    <body name="right_elbow_yaw_link" pos="0 -0.117 0.031" quat="0.5 -0.499997 -0.500003 -0.5">
                      <inertial pos="3.67039e-05 -4.86803e-07 -0.0542142" quat="0.999999 0 0.00108829 0" mass="0.287879" diaginertia="0.000714861 0.00069793 0.000544869" />
                      <joint name="right_elbow_yaw_joint" pos="0 0 0" axis="0 0 -1" range="-1.8 1.8" actuatorfrcrange="-20 20" damping="1" />
                      <geom type="mesh" contype="0" conaffinity="0" group="1" density="0" rgba="0.8 1 0.8 1" mesh="right_elbow_yaw_perfect_mirrored" />
                      <body name="right_wrist_pitch_link" pos="0.006 -0.0001 -0.1394" quat="0.439542 -0.553896 -0.439547 0.553896">
                        <inertial pos="0.00229425 2.08986e-08 9.99423e-05" quat="0.707107 0 0 0.707107" mass="0.00900738" diaginertia="5.7e-07 3.8e-07 2.4e-07" />
                        <joint name="right_wrist_pitch_joint" pos="0 0 0" axis="0 0 -1" range="-0.4 0.4" actuatorfrcrange="-10 10" damping="1" />
                        <geom quat="0.707105 0 -0.707108 0" type="mesh" contype="0" conaffinity="0" group="1" density="0" rgba="1 0.5 1 1" mesh="right_wrist_pitch_perfect_mirrored" />
                        <body name="right_wrist_roll_link" quat="0.690886 0.150583 0.65524 0.265823">
                          <inertial pos="-0.0197311 3.25321e-08 -0.00133849" quat="1 0 -0.000782388 0" mass="0.370899" diaginertia="0.00040404 0.00035616 0.00021232" />
                          <joint name="right_wrist_roll_joint" pos="0 0 0" axis="0 -0.707107 0.707107" range="-0.4 0.4" actuatorfrcrange="-10 10" damping="1" />
                          <geom quat="0.859973 0.510131 -0.00745088 -0.012557" type="mesh" contype="0" conaffinity="0" group="1" density="0" rgba="1 0.4 0.4 1" mesh="right_wrist_roll_perfect_mirrored" />
                        </body>
                      </body>
                      <body name="arm_r_wrist_a_ball_link" pos="-0.009 0.02 -0.0199" quat="0.707105 -0.707108 0 0">
                        <inertial pos="-1.59104e-08 8.74451e-08 0.00973737" quat="0.497809 0.497809 -0.502182 0.502182" mass="0.235987" diaginertia="7.97703e-05 7.63397e-05 2.519e-05" />
                        <geom type="mesh" contype="0" conaffinity="0" group="1" density="0" rgba="1 1 1 1" mesh="arm_r_wrist_a_ball_right_perfect_mirrored" />
                        <body name="arm_r_wrist_motor_a_link" pos="0.0027628 0.097124 0" quat="0.707034 -0.707037 0.010054 -0.010054">
                          <inertial pos="2.58417e-08 8.69573e-08 0.00973737" quat="0.707107 0 0 0.707107" mass="0.00117982" diaginertia="8e-08 6e-08 2e-08" />
                          <geom type="mesh" contype="0" conaffinity="0" group="1" density="0" rgba="1 1 1 1" mesh="arm_r_wrist_motor_a_link_right_perfect_mirrored" />
                          <body name="arm_r_wrist_a_loop_link" pos="0 0 0.0132" quat="0.707034 0.707037 -0.010054 0.010054">
                            <inertial pos="0 0 -1.922e-05" mass="0.00548041" diaginertia="8e-08 8e-08 7e-08" />
                            <geom type="mesh" contype="0" conaffinity="0" group="1" density="0" rgba="1 1 1 1" mesh="arm_r_wrist_a_loop_right_perfect_mirrored" />
                          </body>
                        </body>
                      </body>
                      <body name="arm_r_wrist_b_ball_link" pos="-0.009 -0.02 -0.0199" quat="0.707105 0.707108 0 0">
                        <inertial pos="0.00121967 0 0" quat="0.5 0.5 -0.5 0.5" mass="0.0361757" diaginertia="1.731e-05 1.73e-05 4.69e-06" />
                        <geom type="mesh" contype="0" conaffinity="0" group="1" density="0" rgba="1 1 1 1" mesh="arm_r_wrist_b_ball_right_perfect_mirrored" />
                        <body name="arm_r_wrist_motor_b_link" pos="0.0027628 -0.097124 0" quat="0.707034 0.707037 0.010054 0.010054">
                          <inertial pos="0.00076586 0 -4.912e-05" quat="0.502182 0.502182 -0.497809 0.497809" mass="0.235987" diaginertia="7.97703e-05 7.63397e-05 2.519e-05" />
                          <geom type="mesh" contype="0" conaffinity="0" group="1" density="0" rgba="1 1 1 1" mesh="arm_r_wrist_motor_b_link_right_perfect_mirrored" />
                          <body name="arm_r_wrist_b_loop_link" pos="0 0 0.0132" quat="0.707034 -0.707037 -0.010054 -0.010054">
                            <inertial pos="1.59106e-08 8.74451e-08 0.00973737" quat="0.707107 0 0 0.707107" mass="0.00117982" diaginertia="8e-08 6e-08 2e-08" />
                            <geom type="mesh" contype="0" conaffinity="0" group="1" density="0" rgba="1 1 1 1" mesh="arm_r_wrist_b_loop_right_perfect_mirrored" />
                          </body>
                        </body>
                      </body>
                    </body>
                  </body>
                </body>
              </body>
            </body>
            <body name="waist_motor_a_link" pos="0 0.075 0.0708">
              <inertial pos="-0.040469 0 -0.00673147" quat="-0.00694374 0.603097 -0.00566365 0.797618" mass="0.058187" diaginertia="5.09864e-05 5.05299e-05 6.75372e-06" />
              <geom type="mesh" contype="0" conaffinity="0" group="1" density="0" rgba="0.776471 0.756863 0.737255 1" mesh="waist_motor_a_link" />
              <body name="waist_motor_a_ball_link" pos="-0.065 0 -0.0108" quat="0 1 0 0">
                <inertial pos="-0.00179727 0.0374998 3.54265e-05" quat="0.499977 0.499977 -0.500023 0.500023" mass="0.036139" diaginertia="3.624e-05 3.412e-05 2.43e-06" />
                <geom type="mesh" contype="0" conaffinity="0" group="1" density="0" rgba="0.776471 0.756863 0.737255 1" mesh="waist_motor_a_ball" />
                <body name="waist_motor_a_loop_link" pos="0 0.075 0" quat="0 1 0 0">
                  <inertial pos="4.77393e-08 0 0.00052471" mass="0.017653" diaginertia="8e-07 8e-07 3.5e-07" />
                  <geom type="mesh" contype="0" conaffinity="0" group="1" density="0" rgba="1 1 1 1" mesh="waist_motor_a_loop" />
                </body>
              </body>
            </body>
            <body name="waist_motor_b_link" pos="0 0.075 -0.0708" quat="0 1 0 0">
              <inertial pos="-0.0404684 0 -0.00673515" quat="0.00694635 0.603061 0.00566511 0.797645" mass="0.058187" diaginertia="5.09864e-05 5.05299e-05 6.75372e-06" />
              <geom type="mesh" contype="0" conaffinity="0" group="1" density="0" rgba="0.776471 0.756863 0.737255 1" mesh="waist_motor_b_link" />
              <body name="waist_motor_b_ball_link" pos="-0.065 0 -0.0108" quat="0 0.707107 0 -0.707107">
                <inertial pos="3.559e-05 -0.0374998 0.00179727" quat="0.707107 0.707107 0 0" mass="0.036139" diaginertia="3.624e-05 3.412e-05 2.43e-06" />
                <geom type="mesh" contype="0" conaffinity="0" group="1" density="0" rgba="1 1 1 1" mesh="waist_motor_b_ball" />
                <body name="waist_motor_b_loop_link" pos="0 -0.075 0">
                  <inertial pos="-0.00052471 0 0" quat="0.5 0.5 0.5 0.5" mass="0.017653" diaginertia="8e-07 8e-07 3.5e-07" />
                  <geom type="mesh" contype="0" conaffinity="0" group="1" density="0" rgba="1 1 1 1" mesh="waist_motor_b_loop" />
                </body>
              </body>
            </body>
            <body name="neck_motor_base_link" pos="0.00346 0.33192 0" quat="0.707105 0 -0.707108 0">
              <inertial pos="0 0 0" quat="0.706967 -0.0140416 0.0140416 0.706967" mass="0.541" diaginertia="0.000584446 0.000490763 0.000472677" />
              <geom pos="-0.05299 -0.11067 -0.09204" quat="1 0 0 0" type="mesh" contype="0" conaffinity="0" group="1" density="0" rgba="0.4 1 0.4 1" mesh="neck_motor_base" />
              <geom pos="-0.05299 -0.11067 -0.09204" quat="1 0 0 0" type="mesh" rgba="0.4 1 0.4 1" mesh="neck_motor_base" />
              <body name="neck_motor_bracket_link" pos="8e-05 0.04576 0.00221">
                <inertial pos="0 0 0" quat="0.5 0.5 -0.5 0.5" mass="0.446" diaginertia="0.000220816 0.000177518 0.000161271" />
                <geom pos="-0.05307 -0.15643 -0.09425" quat="1 0 0 0" type="mesh" contype="0" conaffinity="0" group="1" density="0" rgba="1 1 0.4 1" mesh="neck_motor_bracket" />
                <geom pos="-0.05307 -0.15643 -0.09425" quat="1 0 0 0" type="mesh" rgba="1 1 0.4 1" mesh="neck_motor_bracket" />
                <body name="head_face_bracket_link" pos="0 0.02357 0">
                  <inertial pos="0 0.06697 -0.01725" quat="0.461945 0.535357 -0.535357 0.461945" mass="0.275" diaginertia="0.000913707 0.000681261 0.00058252" />
                  <geom pos="-0.05307 -0.18 -0.09425" quat="1 0 0 0" type="mesh" contype="0" conaffinity="0" group="1" density="0" rgba="1 0.4 0.4 1" mesh="head_face_bracket" />
                  <geom pos="-0.05307 -0.18 -0.09425" quat="1 0 0 0" type="mesh" rgba="1 0.4 0.4 1" mesh="head_face_bracket" />
                  <body name="camera_link" pos="-2e-05 0.10364 -0.03848">
                    <inertial pos="0 0 0" quat="0.560272 0.431388 0.560272 0.431388" mass="0.072" diaginertia="4.35783e-05 4.3137e-05 6.34857e-06" />
                    <geom pos="-0.05305 -0.28364 -0.05577" quat="1 0 0 0" type="mesh" contype="0" conaffinity="0" group="1" density="0" rgba="0.4 1 0.4 1" mesh="Camera" />
                    <geom pos="-0.05305 -0.28364 -0.05577" quat="1 0 0 0" type="mesh" rgba="0.4 1 0.4 1" mesh="Camera" />
                  <geom type="mesh" mesh="Camera" contype="1" conaffinity="0" group="3" /><camera name="front_camera" pos="0 0 0" resolution="640 480" fovy="45" mode="fixed" /></body>
                  <body name="radar_link" pos="0.00015 0.07105 0.00663">
                    <inertial pos="0 0 0" quat="0.500023 0.499977 0.500023 0.499977" mass="0.223" diaginertia="0.000133387 0.000110188 0.000108932" />
                    <geom pos="-0.05322 -0.25105 -0.10088" quat="1 0 0 0" type="mesh" contype="0" conaffinity="0" group="1" density="0" rgba="0.2 0.2 0.8 1" mesh="radar" />
                    <geom pos="-0.05322 -0.25105 -0.10088" quat="1 0 0 0" type="mesh" rgba="0.2 0.2 0.8 1" mesh="radar" />
                  <geom type="mesh" mesh="radar" contype="1" conaffinity="0" group="3" /><site name="lidar_site" pos="0 0 0" size="0.01" rgba="1 0 0 0" euler="0 1.57 0" /></body>
                </body>
              </body>
            </body>
          <geom type="mesh" mesh="lumbar_pitch" contype="1" conaffinity="0" group="3" /></body>
        </body>
      </body>
      <body name="left_hip_pitch_link" pos="0.00245 0.092277 -0.012143" quat="0.65328 0.270599 -0.270598 0.653282">
        <inertial pos="-4.816e-05 0 -0.0540778" quat="0.706866 0.0184545 0.0184545 0.706866" mass="1.67336" diaginertia="0.00252881 0.0023447 0.00218676" />
        <joint name="left_hip_pitch_joint" pos="0 0 0" axis="0 0 1" range="-1 2" actuatorfrcrange="-180 180" damping="1" />
        <geom type="mesh" contype="0" conaffinity="0" group="1" density="0" rgba="1 0.4 0.4 1" mesh="left_hip_pitch" />
        <body name="left_hip_roll_link" pos="0 -0.0405 -0.0589" quat="0.653281 0.653281 0.270598 -0.270598">
          <inertial pos="0.00014604 0 -0.0101534" quat="0.707102 0.707102 -0.00248902 0.00248902" mass="0.285622" diaginertia="0.000557294 0.000477746 0.0004105" />
          <joint name="left_hip_roll_joint" pos="0 0 0" axis="0 0 -1" range="-1.5 0.2" actuatorfrcrange="-150 150" damping="1" />
          <geom type="mesh" contype="0" conaffinity="0" group="1" density="0" rgba="1 1 0.4 1" mesh="left_hip_roll" />
          <body name="left_hip_yaw_link" pos="0 -0.0838049 -0.0406" quat="0.707107 0.707107 0 0">
            <inertial pos="-0.00212295 0 0.0916484" quat="0.999473 0 -0.0324533 0" mass="2.73696" diaginertia="0.0127473 0.0124495 0.00338744" />
            <joint name="left_hip_yaw_joint" pos="0 0 0" axis="0 0 -1" range="-1.5 1.5" actuatorfrcrange="-150 150" damping="1" />
            <geom type="mesh" contype="0" conaffinity="0" group="1" density="0" rgba="0.4 1 0.4 1" mesh="left_hip_yaw" />
            <body name="left_knee_pitch_link" pos="-0.0337 0 0.1422" quat="0.5 -0.5 0.5 -0.5">
              <inertial pos="-0.00473541 0 0.0279688" quat="0.544057 0.544057 -0.451666 0.451666" mass="1.51226" diaginertia="0.00826264 0.00805976 0.00174565" />
              <joint name="left_knee_pitch_joint" pos="0 0 0" axis="0 0 1" range="0 2" actuatorfrcrange="-180 180" damping="1" />
              <geom type="mesh" contype="0" conaffinity="0" group="1" density="0" rgba="0 0.5 1 1" mesh="left_knee_pitch" />
              <body name="left_ankle_pitch_link" pos="0 -0.30494 0.0336" quat="0 0 -1 0">
                <inertial pos="-2.32e-06 0 -2.048e-05" quat="0.707107 0 0 0.707107" mass="0.0621721" diaginertia="2.373e-05 2.273e-05 6.68e-06" />
                <joint name="left_ankle_pitch_joint" pos="0 0 0" axis="0 0 -1" range="-0.41 0.35" actuatorfrcrange="-80 80" damping="1" />
                <geom type="mesh" contype="0" conaffinity="0" group="1" density="0" rgba="0 0.5 1 1" mesh="left_ankle_pitch" />
                <body name="left_ankle_roll_link" quat="0.707107 0 0.707107 0">
                  <inertial pos="0.00017156 0 -0.00019936" quat="0.707105 -0.00141346 -0.00141346 0.707105" mass="0.589712" diaginertia="0.00189897 0.00152115 0.000543114" />
                  <joint name="left_ankle_roll_joint" pos="0 0 0" axis="0 0 1" range="-0.64 0.64" actuatorfrcrange="-80 80" damping="1" />
                  <geom type="mesh" contype="0" conaffinity="0" group="1" density="0" rgba="1 0.5 1 1" mesh="left_ankle_roll" />
                  <geom type="mesh" rgba="1 0.5 1 1" mesh="left_ankle_roll" />
                  <geom size="0.002" pos="0.03 -0.0408 0.07" type="sphere" contype="1" conaffinity="1" group="3" />
                  <geom size="0.002" pos="0.03 -0.0408 -0.07" type="sphere" contype="1" conaffinity="1" group="3" />
                  <geom size="0.002" pos="-0.03 -0.0408 0.07" type="sphere" contype="1" conaffinity="1" group="3" />
                  <geom size="0.002" pos="-0.03 -0.0408 -0.07" type="sphere" contype="1" conaffinity="1" group="3" />
                <geom type="sphere" size="0.02" pos="0.03 -0.0408 0.07" rgba="255 0 0 0.5" /><geom type="sphere" size="0.02" pos="0.03 -0.0408 -0.07" rgba="255 0 0 0.5" /><geom type="sphere" size="0.02" pos="-0.03 -0.0408 0.07" rgba="255 0 0 0.5" /><geom type="sphere" size="0.02" pos="-0.03 -0.0408 -0.07" rgba="255 0 0 0.5" /></body>
              </body>
              <body name="leg_l_toe_a_link" pos="0.01985 -0.109962 0.0336568" quat="0.707107 0 -0.707107 0">
                <inertial pos="-0.00875902 0 -0.00875449" quat="0 0.588942 0 0.808175" mass="0.0311417" diaginertia="9.2716e-06 7.48e-06 3.8184e-06" />
                <geom type="mesh" contype="0" conaffinity="0" group="1" density="0" rgba="1 1 1 1" mesh="leg_l_toe_a_link" />
                <body name="leg_l_toe_a_ball_link" pos="-0.0233806 0.00902193 -0.02115">
                  <inertial pos="-1.914e-05 0 1.9e-06" quat="0.5 0.5 -0.5 0.5" mass="0.0567471" diaginertia="0.00022113 0.00022106 1.09e-06" />
                  <geom type="mesh" contype="0" conaffinity="0" group="1" density="0" rgba="1 1 1 1" mesh="leg_l_toe_a_ball" />
                  <body name="leg_l_toe_a_loop_link" pos="0 -0.195 0" quat="0.707107 0 0.707107 0">
                    <inertial pos="0 0 -0.0006502" mass="0.0062017" diaginertia="2.8e-07 2.8e-07 1.2e-07" />
                    <geom type="mesh" contype="0" conaffinity="0" group="1" density="0" rgba="1 1 1 1" mesh="leg_l_toe_a_loop" />
                  </body>
                </body>
              </body>
              <body name="leg_l_toe_b_link" pos="0.01985 -0.164962 0.0335432" quat="0.707107 0 -0.707107 0">
                <inertial pos="0.0089831 0 -0.00906395" quat="0 0.816522 0 0.577315" mass="0.03161" diaginertia="9.49182e-06 7.81e-06 3.98818e-06" />
                <geom type="mesh" contype="0" conaffinity="0" group="1" density="0" rgba="1 1 1 1" mesh="leg_l_toe_b_link" />
                <body name="leg_l_toe_b_ball_link" pos="0.0233806 0.00902193 -0.02115">
                  <inertial pos="-2.566e-05 0 2.566e-05" quat="0.5 0.5 -0.5 0.5" mass="0.0423305" diaginertia="9.179e-05 9.172e-05 9.5e-07" />
                  <geom type="mesh" contype="0" conaffinity="0" group="1" density="0" rgba="1 1 1 1" mesh="leg_l_toe_b_ball" />
                  <body name="leg_l_toe_b_loop_link" pos="0 -0.14 0" quat="0.707107 0 0.707107 0">
                    <inertial pos="0 0 0.00064901" mass="0.0062017" diaginertia="2.8e-07 2.8e-07 1.2e-07" />
                    <geom type="mesh" contype="0" conaffinity="0" group="1" density="0" rgba="1 1 1 1" mesh="leg_l_toe_b_loop" />
                  </body>
                </body>
              </body>
            </body>
          </body>
        </body>
      </body>
      <body name="right_hip_pitch_link" pos="0.00245 -0.092277 -0.012143" quat="0.65328 -0.270599 -0.270598 -0.653282">
        <inertial pos="-4.816e-05 0 -0.0540778" quat="0.706866 0.0184545 0.0184545 0.706866" mass="1.67336" diaginertia="0.00252881 0.0023447 0.00218676" />
        <joint name="right_hip_pitch_joint" pos="0 0 0" axis="0 0 1" range="-2 1" actuatorfrcrange="-180 180" damping="1" />
        <geom type="mesh" contype="0" conaffinity="0" group="1" density="0" rgba="1 0.4 0.4 1" mesh="right_hip_pitch_perfect_mirrored" />
        <body name="right_hip_roll_link" pos="0 0.0405 -0.0589" quat="0.65328 -0.653283 0.270597 0.270598">
          <inertial pos="0.00014604 3.73194e-08 -0.0101534" quat="0.707102 0.707102 -0.00248902 0.00248902" mass="0.285622" diaginertia="0.000557294 0.000477746 0.0004105" />
          <joint name="right_hip_roll_joint" pos="0 0 0" axis="0 0 -1" range="-0.2 1.5" actuatorfrcrange="-150 150" damping="1" />
          <geom type="mesh" contype="0" conaffinity="0" group="1" density="0" rgba="1 1 0.4 1" mesh="right_hip_roll_perfect_mirrored" />
          <body name="right_hip_yaw_link" pos="0 0.0838049 -0.0406" quat="0.707105 -0.707108 0 0">
            <inertial pos="-0.00212296 -6.73287e-07 0.0916484" quat="0.999473 3.66353e-06 -0.0324536 1.18957e-07" mass="2.73696" diaginertia="0.0127473 0.0124495 0.00338744" />
            <joint name="right_hip_yaw_joint" pos="0 0 0" axis="0 0 -1" range="-1.5 1.5" actuatorfrcrange="-150 150" damping="1" />
            <geom type="mesh" contype="0" conaffinity="0" group="1" density="0" rgba="0.4 1 0.4 1" mesh="right_hip_yaw_perfect_mirrored" />
            <body name="right_knee_pitch_link" pos="-0.0337 0 0.1422" quat="0.499998 0.5 0.500002 0.5">
              <inertial pos="-0.00473551 7.25168e-08 0.0279688" quat="0.544055 0.544057 -0.451664 0.45167" mass="1.51226" diaginertia="0.00826264 0.00805976 0.00174565" />
              <joint name="right_knee_pitch_joint" pos="0 0 0" axis="0 0 -1" range="0 2" actuatorfrcrange="-180 180" damping="1" />
              <geom type="mesh" contype="0" conaffinity="0" group="1" density="0" rgba="0 0.5 1 1" mesh="right_knee_pitch_perfect_mirrored" />
              <body name="right_ankle_pitch_link" pos="0 0.30494 0.0336" quat="1.76038e-12 1.32679e-06 -1 -1.32679e-06">
                <inertial pos="-2.32e-06 0 -2.048e-05" quat="0.707107 0 0 0.707107" mass="0.0621721" diaginertia="2.373e-05 2.273e-05 6.68e-06" />
                <joint name="right_ankle_pitch_joint" pos="0 0 0" axis="0 0 1" range="-0.41 0.35" actuatorfrcrange="-80 80" damping="1" />
                <geom type="mesh" contype="0" conaffinity="0" group="1" density="0" rgba="0 0.5 1 1" mesh="right_ankle_pitch_perfect_mirrored" />
                <body name="right_ankle_roll_link" quat="0.707105 0 0.707108 0">
                  <inertial pos="0.00017156 0 -0.00019936" quat="0.707105 -0.00141346 -0.00141346 0.707105" mass="0.589712" diaginertia="0.00189897 0.00152115 0.000543114" />
                  <joint name="right_ankle_roll_joint" pos="0 0 0" axis="0 0 1" range="-0.64 0.64" actuatorfrcrange="-80 80" damping="1" />
                  <geom type="mesh" contype="0" conaffinity="0" group="1" density="0" rgba="1 0.5 1 1" mesh="right_ankle_roll_perfect_mirrored" />
                  <geom type="mesh" rgba="1 0.5 1 1" mesh="right_ankle_roll_perfect_mirrored" />
                  <geom size="0.002" pos="0.03 0.0408 0.07" type="sphere" contype="1" conaffinity="1" group="3" />
                  <geom size="0.002" pos="0.03 0.0408 -0.07" type="sphere" contype="1" conaffinity="1" group="3" />
                  <geom size="0.002" pos="-0.03 0.0408 0.07" type="sphere" contype="1" conaffinity="1" group="3" />
                  <geom size="0.002" pos="-0.03 0.0408 -0.07" type="sphere" contype="1" conaffinity="1" group="3" />
                <geom type="sphere" size="0.02" pos="0.03 0.0408 0.07" rgba="255 0 0 0.5" /><geom type="sphere" size="0.02" pos="0.03 0.0408 -0.07" rgba="255 0 0 0.5" /><geom type="sphere" size="0.02" pos="-0.03 0.0408 0.07" rgba="255 0 0 0.5" /><geom type="sphere" size="0.02" pos="-0.03 0.0408 -0.07" rgba="255 0 0 0.5" /></body>
              </body>
              <body name="leg_r_toe_a_link" pos="0.01985 0.109962 0.0336568" quat="0.707105 0 -0.707108 0">
                <inertial pos="-0.00875902 3.07093e-08 -0.00875449" quat="0 0.588942 0 0.808175" mass="0.0311417" diaginertia="9.2716e-06 7.48e-06 3.8184e-06" />
                <geom type="mesh" contype="0" conaffinity="0" group="1" density="0" rgba="1 1 1 1" mesh="leg_r_toe_a_link_perfect_mirrored" />
                <body name="leg_r_toe_a_ball_link" pos="-0.0233806 -0.00902193 -0.02115">
                  <inertial pos="-1.914e-05 0 1.9e-06" quat="0.5 0.5 -0.5 0.5" mass="0.0567471" diaginertia="0.00022113 0.00022106 1.09e-06" />
                  <geom type="mesh" contype="0" conaffinity="0" group="1" density="0" rgba="1 1 1 1" mesh="leg_r_toe_a_ball_perfect_mirrored" />
                  <body name="leg_r_toe_a_loop_link" pos="0 0.195 0" quat="0.707105 0 0.707108 0">
                    <inertial pos="0 0 -0.0006502" mass="0.0062017" diaginertia="2.8e-07 2.8e-07 1.2e-07" />
                    <geom type="mesh" contype="0" conaffinity="0" group="1" density="0" rgba="1 1 1 1" mesh="leg_r_toe_a_loop_perfect_mirrored" />
                  </body>
                </body>
              </body>
              <body name="leg_r_toe_b_link" pos="0.01985 0.164962 0.0335432" quat="0.707105 0 -0.707108 0">
                <inertial pos="0.0089831 1.01052e-07 -0.00906395" quat="0 0.816522 0 0.577315" mass="0.03161" diaginertia="9.49182e-06 7.81e-06 3.98818e-06" />
                <geom type="mesh" contype="0" conaffinity="0" group="1" density="0" rgba="1 1 1 1" mesh="leg_r_toe_b_link_perfect_mirrored" />
                <body name="leg_r_toe_b_ball_link" pos="0.0233806 -0.00902193 -0.02115">
                  <inertial pos="-2.566e-05 0 2.566e-05" quat="0.5 0.5 -0.5 0.5" mass="0.0423305" diaginertia="9.179e-05 9.172e-05 9.5e-07" />
                  <geom type="mesh" contype="0" conaffinity="0" group="1" density="0" rgba="1 1 1 1" mesh="leg_r_toe_b_ball_perfect_mirrored" />
                  <body name="leg_r_toe_b_loop_link" pos="0 0.14 0" quat="0.707105 0 0.707108 0">
                    <inertial pos="0 0 0.00064901" mass="0.0062017" diaginertia="2.8e-07 2.8e-07 1.2e-07" />
                    <geom type="mesh" contype="0" conaffinity="0" group="1" density="0" rgba="1 1 1 1" mesh="leg_r_toe_b_loop_perfect_mirrored" />
                  </body>
                </body>
              </body>
            </body>
          </body>
        </body>
      </body>
    <camera name="track" pos="0 -3 1" quat="0.850651 0.525731 0 0" mode="track" /><geom type="mesh" mesh="base_link_simple" contype="1" conaffinity="0" group="3" /></body>
  </worldbody>
<option timestep="0.001" /><visual><global azimuth="150" elevation="-20" /><headlight ambient="0.3 0.3 0.3" diffuse="0.6 0.6 0.6" specular="0 0 0" /></visual><actuator><motor name="motor_left_hip_pitch" joint="left_hip_pitch_joint" ctrlrange="-180 180" gear="1.0" /><motor name="motor_left_hip_roll" joint="left_hip_roll_joint" ctrlrange="-150 150" gear="1.0" /><motor name="motor_left_hip_yaw" joint="left_hip_yaw_joint" ctrlrange="-150 150" gear="1.0" /><motor name="motor_left_knee_pitch" joint="left_knee_pitch_joint" ctrlrange="-180 180" gear="1.0" /><motor name="motor_left_ankle_pitch" joint="left_ankle_pitch_joint" ctrlrange="-80 80" gear="1.0" /><motor name="motor_left_ankle_roll" joint="left_ankle_roll_joint" ctrlrange="-80 80" gear="1.0" /><motor name="motor_right_hip_pitch" joint="right_hip_pitch_joint" ctrlrange="-180 180" gear="1.0" /><motor name="motor_right_hip_roll" joint="right_hip_roll_joint" ctrlrange="-150 150" gear="1.0" /><motor name="motor_right_hip_yaw" joint="right_hip_yaw_joint" ctrlrange="-150 150" gear="1.0" /><motor name="motor_right_knee_pitch" joint="right_knee_pitch_joint" ctrlrange="-180 180" gear="1.0" /><motor name="motor_right_ankle_pitch" joint="right_ankle_pitch_joint" ctrlrange="-80 80" gear="1.0" /><motor name="motor_right_ankle_roll" joint="right_ankle_roll_joint" ctrlrange="-80 80" gear="1.0" /><motor name="motor_lumbar_yaw" joint="lumbar_yaw_joint" ctrlrange="-150 150" gear="1.0" /><motor name="motor_lumbar_roll" joint="lumbar_roll_joint" ctrlrange="-150 150" gear="1.0" /><motor name="motor_lumbar_pitch" joint="lumbar_pitch_joint" ctrlrange="-180 180" gear="1.0" /><motor name="motor_left_shoulder_pitch" joint="left_shoulder_pitch_joint" ctrlrange="-20 20" gear="1.0" /><motor name="motor_left_shoulder_roll" joint="left_shoulder_roll_joint" ctrlrange="-20 20" gear="1.0" /><motor name="motor_left_shoulder_yaw" joint="left_shoulder_yaw_joint" ctrlrange="-20 20" gear="1.0" /><motor name="motor_left_elbow_pitch" joint="left_elbow_pitch_joint" ctrlrange="-20 20" gear="1.0" /><motor name="motor_left_elbow_yaw" joint="left_elbow_yaw_joint" ctrlrange="-20 20" gear="1.0" /><motor name="motor_left_wrist_pitch" joint="left_wrist_pitch_joint" ctrlrange="-10 10" gear="1.0" /><motor name="motor_right_shoulder_pitch" joint="right_shoulder_pitch_joint" ctrlrange="-20 20" gear="1.0" /><motor name="motor_right_shoulder_roll" joint="right_shoulder_roll_joint" ctrlrange="-20 20" gear="1.0" /><motor name="motor_right_shoulder_yaw" joint="right_shoulder_yaw_joint" ctrlrange="-20 20" gear="1.0" /><motor name="motor_right_elbow_pitch" joint="right_elbow_pitch_joint" ctrlrange="-20 20" gear="1.0" /><motor name="motor_right_elbow_yaw" joint="right_elbow_yaw_joint" ctrlrange="-20 20" gear="1.0" /><motor name="motor_right_wrist_pitch" joint="right_wrist_pitch_joint" ctrlrange="-10 10" gear="1.0" /><motor name="motor_right_wrist_roll" joint="right_wrist_roll_joint" ctrlrange="-10 10" gear="1.0" /><motor name="motor_left_wrist_roll" joint="left_wrist_roll_joint" ctrlrange="-10 10" gear="1.0" /></actuator><sensor><framequat name="body-orientation" objtype="site" objname="imu" noise="0" /><gyro name="body-angular-velocity" site="imu" noise="0.001" /><framepos name="body-linear-pos" objtype="site" objname="imu" /><velocimeter name="body-linear-vel" site="imu" /><accelerometer name="body-linear-acceleration" site="imu" noise="0.001" /><jointpos name="jointpos_lumbar_yaw" joint="lumbar_yaw_joint" noise="0" /><jointpos name="jointpos_lumbar_roll" joint="lumbar_roll_joint" noise="0" /><jointpos name="jointpos_lumbar_pitch" joint="lumbar_pitch_joint" noise="0" /><jointpos name="jointpos_left_shoulder_pitch" joint="left_shoulder_pitch_joint" noise="0" /><jointpos name="jointpos_left_shoulder_roll" joint="left_shoulder_roll_joint" noise="0" /><jointpos name="jointpos_left_shoulder_yaw" joint="left_shoulder_yaw_joint" noise="0" /><jointpos name="jointpos_left_elbow_pitch" joint="left_elbow_pitch_joint" noise="0" /><jointpos name="jointpos_left_elbow_yaw" joint="left_elbow_yaw_joint" noise="0" /><jointpos name="jointpos_left_wrist_pitch" joint="left_wrist_pitch_joint" noise="0" /><jointpos name="jointpos_left_wrist_roll" joint="left_wrist_roll_joint" noise="0" /><jointpos name="jointpos_right_shoulder_pitch" joint="right_shoulder_pitch_joint" noise="0" /><jointpos name="jointpos_right_shoulder_roll" joint="right_shoulder_roll_joint" noise="0" /><jointpos name="jointpos_right_shoulder_yaw" joint="right_shoulder_yaw_joint" noise="0" /><jointpos name="jointpos_right_elbow_pitch" joint="right_elbow_pitch_joint" noise="0" /><jointpos name="jointpos_right_elbow_yaw" joint="right_elbow_yaw_joint" noise="0" /><jointpos name="jointpos_right_wrist_pitch" joint="right_wrist_pitch_joint" noise="0" /><jointpos name="jointpos_right_wrist_roll" joint="right_wrist_roll_joint" noise="0" /><jointpos name="jointpos_left_hip_pitch" joint="left_hip_pitch_joint" noise="0" /><jointpos name="jointpos_left_hip_roll" joint="left_hip_roll_joint" noise="0" /><jointpos name="jointpos_left_hip_yaw" joint="left_hip_yaw_joint" noise="0" /><jointpos name="jointpos_left_knee_pitch" joint="left_knee_pitch_joint" noise="0" /><jointpos name="jointpos_left_ankle_pitch" joint="left_ankle_pitch_joint" noise="0" /><jointpos name="jointpos_left_ankle_roll" joint="left_ankle_roll_joint" noise="0" /><jointpos name="jointpos_right_hip_pitch" joint="right_hip_pitch_joint" noise="0" /><jointpos name="jointpos_right_hip_roll" joint="right_hip_roll_joint" noise="0" /><jointpos name="jointpos_right_hip_yaw" joint="right_hip_yaw_joint" noise="0" /><jointpos name="jointpos_right_knee_pitch" joint="right_knee_pitch_joint" noise="0" /><jointpos name="jointpos_right_ankle_pitch" joint="right_ankle_pitch_joint" noise="0" /><jointpos name="jointpos_right_ankle_roll" joint="right_ankle_roll_joint" noise="0" /><jointvel name="jointvel_lumbar_yaw" joint="lumbar_yaw_joint" noise="0" /><jointvel name="jointvel_lumbar_roll" joint="lumbar_roll_joint" noise="0" /><jointvel name="jointvel_lumbar_pitch" joint="lumbar_pitch_joint" noise="0" /><jointvel name="jointvel_left_shoulder_pitch" joint="left_shoulder_pitch_joint" noise="0" /><jointvel name="jointvel_left_shoulder_roll" joint="left_shoulder_roll_joint" noise="0" /><jointvel name="jointvel_left_shoulder_yaw" joint="left_shoulder_yaw_joint" noise="0" /><jointvel name="jointvel_left_elbow_pitch" joint="left_elbow_pitch_joint" noise="0" /><jointvel name="jointvel_left_elbow_yaw" joint="left_elbow_yaw_joint" noise="0" /><jointvel name="jointvel_left_wrist_pitch" joint="left_wrist_pitch_joint" noise="0" /><jointvel name="jointvel_left_wrist_roll" joint="left_wrist_roll_joint" noise="0" /><jointvel name="jointvel_right_shoulder_pitch" joint="right_shoulder_pitch_joint" noise="0" /><jointvel name="jointvel_right_shoulder_roll" joint="right_shoulder_roll_joint" noise="0" /><jointvel name="jointvel_right_shoulder_yaw" joint="right_shoulder_yaw_joint" noise="0" /><jointvel name="jointvel_right_elbow_pitch" joint="right_elbow_pitch_joint" noise="0" /><jointvel name="jointvel_right_elbow_yaw" joint="right_elbow_yaw_joint" noise="0" /><jointvel name="jointvel_right_wrist_pitch" joint="right_wrist_pitch_joint" noise="0" /><jointvel name="jointvel_right_wrist_roll" joint="right_wrist_roll_joint" noise="0" /><jointvel name="jointvel_left_hip_pitch" joint="left_hip_pitch_joint" noise="0" /><jointvel name="jointvel_left_hip_roll" joint="left_hip_roll_joint" noise="0" /><jointvel name="jointvel_left_hip_yaw" joint="left_hip_yaw_joint" noise="0" /><jointvel name="jointvel_left_knee_pitch" joint="left_knee_pitch_joint" noise="0" /><jointvel name="jointvel_left_ankle_pitch" joint="left_ankle_pitch_joint" noise="0" /><jointvel name="jointvel_left_ankle_roll" joint="left_ankle_roll_joint" noise="0" /><jointvel name="jointvel_right_hip_pitch" joint="right_hip_pitch_joint" noise="0" /><jointvel name="jointvel_right_hip_roll" joint="right_hip_roll_joint" noise="0" /><jointvel name="jointvel_right_hip_yaw" joint="right_hip_yaw_joint" noise="0" /><jointvel name="jointvel_right_knee_pitch" joint="right_knee_pitch_joint" noise="0" /><jointvel name="jointvel_right_ankle_pitch" joint="right_ankle_pitch_joint" noise="0" /><jointvel name="jointvel_right_ankle_roll" joint="right_ankle_roll_joint" noise="0" /><rangefinder name="lidar_sensor" site="lidar_site" cutoff="10.0" /></sensor><keyframe><key name="home_default" qpos="0 0 0.7 1 0 0 0 0 0 0 0 0 0 0 0 0 0 0 0 0 0 0 0 0 0 0 0 0 0 0 0 0 0 0 0 0" /><key name="check_pose" qpos="0 0 0.7 1 0 0 0 0.3 0.3 0.3 0.3 0.3 0.3 0.3 0.3 0.3 0.3 0.3 0.3 0.3 0.3 0.3 0.3 0.3 0.3 0.3 0.3 0.3 0.3 0.3 0.3 0.3 0.3 0.3 0.3 0.3" /></keyframe></mujoco>