<?xml version='1.0' encoding='utf-8'?>
<robot name="x1">
  <mujoco>
        <compiler meshdir="../meshes/" balanceinertia="true" discardvisual="false" fusestatic="false" />
  </mujoco>
  <link name="base_link">
    <visual>
      <origin xyz="0 0 0" rpy="0 0 0" />
      <geometry>
        <mesh filename="../meshes/base_link_simple.STL" />
      </geometry>
      <material name="base_link_material">
        <color rgba="0.8 0.4 0 1" />
      </material>
    </visual>
    <collision>
      <origin xyz="0 0 0" rpy="0 0 0" />
      <geometry>
        <mesh filename="../meshes/base_link_simple.STL" />
      </geometry>
    </collision>
  <inertial>
      <origin xyz="0.00252285 0 0.0302341" rpy="0 0 0" />
      <mass value="4.3041648" />
      <inertia ixx="0.02680559" ixy="0" ixz="5.389e-05" iyy="0.01083128" iyz="0" izz="0.02180955" />
    </inertial>
    </link>
  <link name="lumbar_yaw_link">
    <visual>
      <origin xyz="0 0 0" rpy="0 0 0" />
      <geometry>
        <mesh filename="../meshes/lumbar_yaw.STL" />
      </geometry>
      <material name="lumbar_yaw_material">
        <color rgba="1 0.4 0.4 1" />
      </material>
    </visual>
    
  <inertial>
      <origin xyz="-0.0180007 0 0.0243298" rpy="0 0 0" />
      <mass value="0.36251906" />
      <inertia ixx="0.00035849" ixy="0" ixz="6.896e-05" iyy="0.00045823" iyz="0" izz="0.00063906" />
    </inertial>
    </link>
  <joint name="lumbar_yaw_joint" type="fixed">
    <origin xyz="0.00244999999994827 0 0.115534033809005" rpy="0 0 -4.54911392613975E-05" />
    <parent link="base_link" />
    <child link="lumbar_yaw_link" />
    <axis xyz="0 0 1" />
    <limit lower="-3.14" upper="3.14" effort="0" velocity="0" />
  </joint>
  <link name="lumbar_roll_link">
    <visual>
      <origin xyz="0 0 0" rpy="0 0 0" />
      <geometry>
        <mesh filename="../meshes/lumbar_roll.STL" />
      </geometry>
      <material name="lumbar_roll_material">
        <color rgba="1 0.4 0.4 1" />
      </material>
    </visual>
    
  <inertial>
      <origin xyz="0 0.0003642 -0.00019197" rpy="0 0 0" />
      <mass value="0.03412073" />
      <inertia ixx="4.93e-06" ixy="0" ixz="0" iyy="5.42e-06" iyz="-9e-08" izz="4.83e-06" />
    </inertial>
    </link>
  <joint name="lumbar_roll_joint" type="fixed">
    <origin xyz="0 0 0.0405" rpy="1.57079632679491 0 -1.5707963267949" />
    <parent link="lumbar_yaw_link" />
    <child link="lumbar_roll_link" />
    <axis xyz="0 0 1" />
    <limit lower="-3.14" upper="3.14" effort="0" velocity="0" />
  </joint>
  <link name="lumbar_pitch_link">
    <visual>
      <origin xyz="0 0 0" rpy="0 0 0" />
      <geometry>
        <mesh filename="../meshes/lumbar_pitch_x1.STL" />
      </geometry>
      <material name="lumbar_pitch_material">
        <color rgba="0.4 1 0.4 1" />
      </material>
    </visual>
    
  <inertial>
      <origin xyz="0.00070244 0.210726 0" rpy="0 0 0" />
      <mass value="8.8571074" />
      <inertia ixx="0.14777412" ixy="-0.00392755" ixz="0" iyy="0.06085873" iyz="0" izz="0.11164753" />
    </inertial>
    </link>
  <joint name="lumbar_pitch_joint" type="fixed">
    <origin xyz="0 0 0" rpy="0 1.5707963267949 0" />
    <parent link="lumbar_roll_link" />
    <child link="lumbar_pitch_link" />
    <axis xyz="0 0 -1" />
    <limit lower="-3.14" upper="3.14" effort="0" velocity="0" />
  </joint>
  <link name="left_shoulder_pitch_link">
    <inertial>
      <origin xyz="-0.00251212 0 -0.0567447" rpy="0 0 0" />
      <mass value="1.0067875" />
      <inertia ixx="0.00108106" ixy="0" ixz="1.583e-05" iyy="0.00096162" iyz="0" izz="0.0008545" />
    </inertial>
    <visual>
      <origin xyz="0 0 0" rpy="0 0 0" />
      <geometry>
        <mesh filename="../meshes/left_shoulder_pitch.STL" />
      </geometry>
      <material name="left_shoulder_pitch_material">
        <color rgba="1 0.4 0.4 1" />
      </material>
    </visual>
    
  </link>
  <joint name="left_shoulder_pitch_joint" type="fixed">
    <origin xyz="0 0.255999999999995 -0.145800000000004" rpy="0 0 -3.14159265358978" />
    <parent link="lumbar_pitch_link" />
    <child link="left_shoulder_pitch_link" />
    <axis xyz="0 0 -1" />
    <limit lower="-3.14" upper="3.14" effort="0" velocity="0" />
  </joint>
  <link name="left_shoulder_roll_link">
    <inertial>
      <origin xyz="0.000154 0 -0.0271134" rpy="0 0 0" />
      <mass value="0.69169508" />
      <inertia ixx="0.00133669" ixy="0" ixz="3.26e-06" iyy="0.00065344" iyz="0" izz="0.00117974" />
    </inertial>
    <visual>
      <origin xyz="0 0 0" rpy="0 0 0" />
      <geometry>
        <mesh filename="../meshes/left_shoulder_roll.STL" />
      </geometry>
      <material name="left_shoulder_roll_material">
        <color rgba="1 1 0.4 1" />
      </material>
    </visual>
    
  </link>
  <joint name="left_shoulder_roll_joint" type="fixed">
    <origin xyz="-0.0313 0 -0.0592" rpy="0 -1.5708 0" />
    <parent link="left_shoulder_pitch_link" />
    <child link="left_shoulder_roll_link" />
    <axis xyz="0 0 -1" />
    <limit lower="-3.14" upper="3.14" effort="0" velocity="0" />
  </joint>
  <link name="left_shoulder_yaw_link">
    <inertial>
      <origin xyz="-2.68e-06 0 -0.00392718" rpy="0 0 0" />
      <mass value="0.72559372" />
      <inertia ixx="0.00116043" ixy="0" ixz="1.27e-06" iyy="0.00117758" iyz="0" izz="0.00048696" />
    </inertial>
    <visual>
      <origin xyz="0 0 0" rpy="0 0 0" />
      <geometry>
        <mesh filename="../meshes/left_shoulder_yaw.STL" />
      </geometry>
      <material name="left_shoulder_yaw_material">
        <color rgba="0.4 1 0.4 1" />
      </material>
    </visual>
    
  </link>
  <joint name="left_shoulder_yaw_joint" type="fixed">
    <origin xyz="0 0.1252 -0.0313000000000029" rpy="1.57079632679488 1.5707963267949 0" />
    <parent link="left_shoulder_roll_link" />
    <child link="left_shoulder_yaw_link" />
    <axis xyz="0 0 1" />
    <limit lower="-3.14" upper="3.14" effort="0" velocity="0" />
  </joint>
  <link name="left_elbow_pitch_link">
    <inertial>
      <origin xyz="2.604e-05 0 0.0268658" rpy="0 0 0" />
      <mass value="0.69780135" />
      <inertia ixx="0.00116267" ixy="0" ixz="1.6e-07" iyy="0.00064619" iyz="0" izz="0.00096882" />
    </inertial>
    <visual>
      <origin xyz="0 0 0" rpy="0 0 0" />
      <geometry>
        <mesh filename="../meshes/left_elbow_pitch.STL" />
      </geometry>
      <material name="left_elbow_pitch_material">
        <color rgba="0 0.5 1 1" />
      </material>
    </visual>
    
  </link>
  <joint name="left_elbow_pitch_joint" type="fixed">
    <origin xyz="0 -0.031 -0.0365000000000021" rpy="-1.5707963267949 0 0" />
    <parent link="left_shoulder_yaw_link" />
    <child link="left_elbow_pitch_link" />
    <axis xyz="0 0 1" />
    <limit lower="-3.14" upper="3.14" effort="0" velocity="0" />
  </joint>
  <link name="left_elbow_yaw_link">
    <inertial>
      <origin xyz="3.656e-05 0 -0.0542142" rpy="0 0 0" />
      <mass value="0.28787886" />
      <inertia ixx="0.00071486" ixy="0" ixz="-3.7e-07" iyy="0.00069793" iyz="0" izz="0.00054487" />
    </inertial>
    <visual>
      <origin xyz="0 0 0" rpy="0 0 0" />
      <geometry>
        <mesh filename="../meshes/left_elbow_yaw.STL" />
      </geometry>
      <material name="left_elbow_yaw_material">
        <color rgba="0.8 1.0 0.8 1" />
      </material>
    </visual>
    
  </link>
  <joint name="left_elbow_yaw_joint" type="fixed">
    <origin xyz="0 0.116999999999998 0.0310000000000001" rpy="1.5707963267949  -1.5708 0" />
    <parent link="left_elbow_pitch_link" />
    <child link="left_elbow_yaw_link" />
    <axis xyz="0 0 1" />
    <limit lower="-3.14" upper="3.14" effort="0" velocity="0" />
  </joint>
  <link name="left_wrist_pitch_link">
    <inertial>
        <origin xyz="0.00229425 0 9.994e-05" rpy="-0 1.5708 0" />
        <mass value="0.00900738" />
        <inertia ixx="3.8e-07" ixy="0" ixz="0" iyy="5.7e-07" iyz="0" izz="2.4e-07" />
      </inertial>
    <visual>
      <origin xyz="0 0 0" rpy="0 0 0" />
      <geometry>
        <mesh filename="../meshes/left_wrist_pitch.STL" />
      </geometry>
      <material name="left_wrist_pitch_material">
        <color rgba="1 0.5 1 1" />
      </material>
    </visual>
    
  </link>
  <joint name="left_wrist_pitch_joint" type="fixed">
    <origin xyz="0.006 0.0001 -0.1394" rpy="1.5708 0.229204 -1.5708" />
    <parent link="left_elbow_yaw_link" />
    <child link="left_wrist_pitch_link" />
    <axis xyz="-1 0 0" />
    <limit lower="-3.14" upper="3.14" effort="0" velocity="0" />
  </joint>
  <link name="left_wrist_roll_link">
    <inertial>
        <origin xyz="-0.0197311 0 -0.00133858" rpy="2.40323 -0.654807 -0.449771" />
        <mass value="0.370899" />
        <inertia ixx="0.00040404" ixy="0" ixz="3e-07" iyy="0.00035616" iyz="0" izz="0.00021232" />
      </inertial>
  </link>

  <joint name="left_wrist_roll_joint" type="fixed">
    <origin xyz="0 0 0" rpy="-1.4 0.970796 -1.5708" />
    <parent link="left_wrist_pitch_link" />
    <child link="left_wrist_roll_link" />
  </joint>

  
  

  <link name="right_shoulder_pitch_link">
    <inertial>
      <origin xyz="-0.00251212 -1.57257e-07 -0.0567447" rpy="0 0 0" />
      <mass value="1.0067875" />
      <inertia ixx="0.00108106" ixy="3.58955e-10" ixz="1.583e-05" iyy="0.00096162" iyz="-2.42272e-10" izz="0.0008545" />
    </inertial>
    <visual>
      <origin xyz="0 0 0" rpy="0 0 0" />
      <geometry>
        <mesh filename="../meshes/right_shoulder_pitch_perfect_mirrored.STL" />
      </geometry>
      <material name="left_shoulder_pitch_material">
        <color rgba="1 0.4 0.4 1" />
      </material>
    </visual>
    
  </link>
  <joint name="right_shoulder_pitch_joint" type="fixed">
    <origin xyz="1.32652e-05 0.256 0.1458" rpy="-3.14159 -9.09823e-05 -3.14159" />
    <parent link="lumbar_pitch_link" />
    <child link="right_shoulder_pitch_link" />
    <axis xyz="0 0 1" />
    <limit lower="-3.14" upper="3.14" effort="0" velocity="0" />
  </joint>
  <link name="right_shoulder_roll_link">
<inertial>
  <mass value="0.69169508" />
      <origin xyz="0.000153928 -7.15389e-08 -0.0271134" rpy="0 0 0" />
      <inertia ixx="0.00133669" ixy="0" ixz="3.26e-06" iyy="0.00065344" iyz="0" izz="0.00117974" />
    </inertial>

    <visual>
      <origin xyz="0 0 0" rpy="0 0 0" />
      <geometry>
        <mesh filename="../meshes/right_shoulder_roll_perfect_mirrored.STL" />
      </geometry>
      <material name="left_shoulder_roll_material">
        <color rgba="1 1 0.4 1" />
      </material>
    </visual>
    
  </link>
  <joint name="right_shoulder_roll_joint" type="fixed">
    <origin xyz="-0.0313 0 -0.0592" rpy="-3.14159 -1.57079 -3.14159" />
    <parent link="right_shoulder_pitch_link" />
    <child link="right_shoulder_roll_link" />
    <axis xyz="0 0 1" />
    <limit lower="-3.14" upper="3.14" effort="0" velocity="0" />
  </joint>
  <link name="right_shoulder_yaw_link">
    <inertial>
      <origin xyz="-2.69042e-06 4.00604e-09 -0.00392718" rpy="0 0 0" />
      <mass value="0.72559372" />
      <inertia ixx="0.00116043" ixy="0" ixz="1.27e-06" iyy="0.00117758" iyz="0" izz="0.00048696" />
    </inertial>

    <visual>
      <origin xyz="0 0 0" rpy="0 0 0" />
      <geometry>
        <mesh filename="../meshes/right_shoulder_yaw_perfect_mirrored.STL" />
      </geometry>
      <material name="left_shoulder_yaw_material">
        <color rgba="0.4 1 0.4 1" />
      </material>
    </visual>
    
  </link>
  <joint name="right_shoulder_yaw_joint" type="fixed">
    <origin xyz="0 -0.1252 -0.0313" rpy="-1.5708 1.5708 0" />
    <parent link="right_shoulder_roll_link" />
    <child link="right_shoulder_yaw_link" />
    <axis xyz="0 0 -1" />
    <limit lower="-3.14" upper="3.14" effort="0" velocity="0" />
  </joint>
  <link name="right_elbow_pitch_link">
<inertial>
  <origin xyz="2.60126e-05 7.1228e-08 0.0268658" rpy="0 0 0" />
  <mass value="0.69780135" />
  <inertia ixx="0.00116267" ixy="0" ixz="1.6e-07" iyy="0.00064619" iyz="0" izz="0.00096882" />
</inertial>

    <visual>
      <origin xyz="0 0 0" rpy="0 0 0" />
      <geometry>
        <mesh filename="../meshes/right_elbow_pitch_perfect_mirrored.STL" />
      </geometry>
      <material name="left_elbow_pitch_material">
        <color rgba="0 0.5 1 1" />
      </material>
    </visual>
    
  </link>
  <joint name="right_elbow_pitch_joint" type="fixed">
    <origin xyz="0 0.031 -0.0365" rpy="1.5708 0 0" />
    <parent link="right_shoulder_yaw_link" />
    <child link="right_elbow_pitch_link" />
    <axis xyz="0 0 -1" />
    <limit lower="-3.14" upper="3.14" effort="0" velocity="0" />
  </joint>
  <link name="right_elbow_yaw_link">
    <inertial>
      <mass value="0.28787886" />
      <origin xyz="3.67039e-05 -4.86803e-07 -0.0542142" rpy="0 0 0" />
      <inertia ixx="0.00071486" ixy="0" ixz="-3.7e-07" iyy="0.00069793" iyz="0" izz="0.00054487" />
    </inertial>
    <visual>
      <origin xyz="0 0 0" rpy="0 0 0" />
      <geometry>
        <mesh filename="../meshes/right_elbow_yaw_perfect_mirrored.STL" />
      </geometry>
      <material name="left_elbow_yaw_material">
        <color rgba="0.8 1.0 0.8 1" />
      </material>
    </visual>
    
  </link>
  <joint name="right_elbow_yaw_joint" type="fixed">
    <origin xyz="0 -0.117 0.031" rpy="1.5708 -1.57079 -3.14159" />
    <parent link="right_elbow_pitch_link" />
    <child link="right_elbow_yaw_link" />
    <axis xyz="0 0 -1" />
    <limit lower="-3.14" upper="3.14" effort="0" velocity="0" />
  </joint>
  <link name="right_wrist_pitch_link">
    <inertial>
        <origin xyz="0.00229425 2.08986e-08 9.99423e-05" rpy="0 -1.5708 0" />
        <mass value="0.00900738" />
        <inertia ixx="3.8e-07" ixy="0" ixz="0" iyy="5.7e-07" iyz="0" izz="2.4e-07" />
      </inertial>
    <visual>
      <origin xyz="0 0 0" rpy="0 0 0" />
      <geometry>
        <mesh filename="../meshes/right_wrist_pitch_perfect_mirrored.STL" />
      </geometry>
      <material name="left_wrist_pitch_material">
        <color rgba="1 0.5 1 1" />
      </material>
    </visual>
    
  </link>
  <joint name="right_wrist_pitch_joint" type="fixed">
    <origin xyz="0.006 -0.0001 -0.1394" rpy="-1.5708 0.229204 1.5708" />
    <parent link="right_elbow_yaw_link" />
    <child link="right_wrist_pitch_link" />
    <axis xyz="-1 0 0" />
    <limit lower="-3.14" upper="3.14" effort="0" velocity="0" />
  </joint>
  <link name="right_wrist_roll_link">
    <inertial>
        <origin xyz="-0.0197311 3.25321e-08 -0.00133849" rpy="-2.40323 0.654807 0.449771" />
        <mass value="0.370899" />
        <inertia ixx="0.00040404" ixy="0" ixz="3e-07" iyy="0.00035616" iyz="0" izz="0.00021232" />
      </inertial>
  </link>

  <joint name="right_wrist_roll_joint" type="fixed">
    <origin xyz="0 0 0" rpy="1.4 0.970796 1.5708" />
    <parent link="right_wrist_pitch_link" />
    <child link="right_wrist_roll_link" />
  </joint>

  
  <link name="waist_motor_a_link">
    <visual>
      <origin xyz="0 0 0" rpy="0 0 0" />
      <geometry>
        <mesh filename="../meshes/waist_motor_a_link.STL" />
      </geometry>
      <material name="">
        <color rgba="0.776470588235294 0.756862745098039 0.737254901960784 1" />
      </material>
    </visual>
    
  <inertial>
      <origin xyz="-0.040469 0 -0.00673147" rpy="0 0 0" />
      <mass value="0.05818703" />
      <inertia ixx="1.00379e-05" ixy="3e-08" ixz="-1.15966e-05" iyy="5.053e-05" iyz="0" izz="4.77021e-05" />
    </inertial>
    </link>
  <joint name="waist_motor_a_link_joint" type="fixed">
    <origin xyz="0 0.0749999999999926 0.0708000000001417" rpy="0 0 0" />
    <parent link="lumbar_pitch_link" />
    <child link="waist_motor_a_link" />
    <axis xyz="0 0 1" />
    <limit lower="-3.14" upper="3.14" effort="0" velocity="0" />
  </joint>
  <link name="waist_motor_a_ball_link">
    <visual>
      <origin xyz="0 0 0" rpy="0 0 0" />
      <geometry>
        <mesh filename="../meshes/waist_motor_a_ball.STL" />
      </geometry>
      <material name="">
        <color rgba="0.776470588235294 0.756862745098039 0.737254901960784 1" />
      </material>
    </visual>
    
  <inertial>
      <origin xyz="-0.00179727 0.0374998 3.54265e-05" rpy="0 0 0" />
      <mass value="0.03613902" />
      <inertia ixx="3.412e-05" ixy="0" ixz="-1.92882e-10" iyy="2.43e-06" iyz="0" izz="3.624e-05" />
    </inertial>
    </link>
  <joint name="waist_motor_a_ball_joint" type="fixed">
    <origin xyz="-0.065 0 -0.0108000000001461" rpy="3.14159265358979 0 0" />
    <parent link="waist_motor_a_link" />
    <child link="waist_motor_a_ball_link" />
    <axis xyz="0 0 0" />
  </joint>
  <link name="waist_motor_a_loop_link">
    <visual>
      <origin xyz="0 0 0" rpy="0 0 0" />
      <geometry>
        <mesh filename="../meshes/waist_motor_a_loop.STL" />
      </geometry>
      <material name="">
        <color rgba="1 1 1 1" />
      </material>
    </visual>
    
  <inertial>
      <origin xyz="4.77393e-08 0 0.00052471" rpy="0 0 0" />
      <mass value="0.01765296" />
      <inertia ixx="8e-07" ixy="0" ixz="0" iyy="8e-07" iyz="0" izz="3.5e-07" />
    </inertial>
    </link>
  <joint name="waist_motor_a_loop_joint" type="fixed">
    <origin xyz="0 0.0749999999999924 0" rpy="3.14159265358979 0 0" />
    <parent link="waist_motor_a_ball_link" />
    <child link="waist_motor_a_loop_link" />
    <axis xyz="0 0 0" />
  </joint>
  <link name="waist_motor_b_link">
    <visual>
      <origin xyz="0 0 0" rpy="0 0 0" />
      <geometry>
        <mesh filename="../meshes/waist_motor_b_link.STL" />
      </geometry>
      <material name="">
        <color rgba="0.776470588235294 0.756862745098039 0.737254901960784 1" />
      </material>
    </visual>
    
  <inertial>
      <origin xyz="-0.04046842 0 -0.00673515" rpy="0 0 0" />
      <mass value="0.05818703" />
      <inertia ixx="1.004e-05" ixy="-3e-08" ixz="-1.16e-05" iyy="5.053e-05" iyz="0" izz="4.77e-05" />
    </inertial>
    </link>
  <joint name="waist_motor_b_link_joint" type="fixed">
    <origin xyz="0 0.0750000000000303 -0.0708000000000074" rpy="3.14159265358979 0 0" />
    <parent link="lumbar_pitch_link" />
    <child link="waist_motor_b_link" />
    <axis xyz="0 0 1" />
    <limit lower="-3.14" upper="3.14" effort="0" velocity="0" />
  </joint>
  <link name="waist_motor_b_ball_link">
    <visual>
      <origin xyz="0 0 0" rpy="0 0 0" />
      <geometry>
        <mesh filename="../meshes/waist_motor_b_ball.STL" />
      </geometry>
      <material name="">
        <color rgba="1 1 1 1" />
      </material>
    </visual>
    
  <inertial>
      <origin xyz="3.559e-05 -0.03749978 0.00179727" rpy="0 0 0" />
      <mass value="0.03613902" />
      <inertia ixx="3.624e-05" ixy="0" ixz="0" iyy="2.43e-06" iyz="0" izz="3.412e-05" />
    </inertial>
    </link>
  <joint name="waist_motor_b_ball_joint" type="fixed">
    <origin xyz="-0.0650000000000492 0 -0.0108000000000005" rpy="3.14159265358979 1.5707963267949 0" />
    <parent link="waist_motor_b_link" />
    <child link="waist_motor_b_ball_link" />
    <axis xyz="0 0 0" />
  </joint>
  <link name="waist_motor_b_loop_link">
    <visual>
      <origin xyz="0 0 0" rpy="0 0 0" />
      <geometry>
        <mesh filename="../meshes/waist_motor_b_loop.STL" />
      </geometry>
      <material name="">
        <color rgba="1 1 1 1" />
      </material>
    </visual>
    
  <inertial>
      <origin xyz="-0.00052471 0 0" rpy="0 0 0" />
      <mass value="0.01765296" />
      <inertia ixx="3.5e-07" ixy="0" ixz="0" iyy="8e-07" iyz="0" izz="8e-07" />
    </inertial>
    </link>
  <joint name="waist_motor_b_loop_joint" type="fixed">
    <origin xyz="0 -0.0749999999999924 0" rpy="0 0 0" />
    <parent link="waist_motor_b_ball_link" />
    <child link="waist_motor_b_loop_link" />
    <axis xyz="0 0 0" />
  </joint>
  <link name="left_hip_pitch_link">
    <inertial>
      <origin xyz="-4.816e-05 0 -0.0540778" rpy="0 0 0" />
      <mass value="1.6733645" />
      <inertia ixx="0.00234427" ixy="0" ixz="-8.23e-06" iyy="0.00252881" iyz="0" izz="0.00218719" />
    </inertial>
    <visual>
      <origin xyz="0 0 0" rpy="0 0 0" />
      <geometry>
        <mesh filename="../meshes/left_hip_pitch.STL" />
      </geometry>
      <material name="left_hip_pitch_material">
        <color rgba="1 0.4 0.4 1" />
      </material>
    </visual>
    
  </link>
  <joint name="left_hip_pitch_joint" type="revolute">
    <origin xyz="0.00245 0.092277 -0.012143" rpy="0 -0.7854 1.5708" />
    <parent link="base_link" />
    <child link="left_hip_pitch_link" />
    <axis xyz="0 0 1" />
    <limit lower="-1" upper="2" effort="180" velocity="8.90" />
      <dynamics damping="1.0" />
  </joint>
  <link name="left_hip_roll_link">
    <inertial>
      <origin xyz="0.00014604 0 -0.0101534" rpy="0 0 0" />
      <mass value="0.28562185" />
      <inertia ixx="0.00055729" ixy="0" ixz="5.6e-07" iyy="0.0004105" iyz="0" izz="0.00047775" />
    </inertial>
    <visual>
      <origin xyz="0 0 0" rpy="0 0 0" />
      <geometry>
        <mesh filename="../meshes/left_hip_roll.STL" />
      </geometry>
      <material name="left_hip_roll_material">
        <color rgba="1 1 0.4 1" />
      </material>
    </visual>
    
  </link>
  <joint name="left_hip_roll_joint" type="revolute">
    <origin xyz="0 -0.0405000000000076 -0.0589000000000007" rpy="1.57079632679491 0.785398163397451 0" />
    <parent link="left_hip_pitch_link" />
    <child link="left_hip_roll_link" />
    <axis xyz="0 0 -1" />
    <limit lower="-1.5" upper="0.2" effort="150.0" velocity="27.23" />
      <dynamics damping="1.0" />
  </joint>
  <link name="left_hip_yaw_link">
    <inertial>
      <origin xyz="-0.00212295 0 0.0916484" rpy="0 0 0" />
      <mass value="2.7369623" />
      <inertia ixx="0.01270795" ixy="0" ixz="0.00060592" iyy="0.01244948" iyz="0" izz="0.00342683" />
    </inertial>
    <visual>
      <origin xyz="0 0 0" rpy="0 0 0" />
      <geometry>
        <mesh filename="../meshes/left_hip_yaw.STL" />
      </geometry>
      <material name="left_hip_yaw_material">
        <color rgba="0.4 1 0.4 1" />
      </material>
    </visual>
    
  </link>
  <joint name="left_hip_yaw_joint" type="revolute">
    <origin xyz="0 -0.0838049159474928 -0.0406000000000136" rpy="1.5707963267949 0 0" />
    <parent link="left_hip_roll_link" />
    <child link="left_hip_yaw_link" />
    <axis xyz="0 0 -1" />
    <limit lower="-1.5" upper="1.5" effort="150.0" velocity="27.23" />
      <dynamics damping="1.0" />
  </joint>
  <link name="left_knee_pitch_link">
    <inertial>
      <mass value="1.51225735" />
      <origin xyz="-0.00473541 0 0.0279688" rpy="0 0 0" />
      <inertia ixx="0.00806663" ixy="0" ixz="3.669e-05" iyy="0.00174565" iyz="0" izz="0.00825577" />
    </inertial>
    <visual>
      <origin xyz="0 0 0" rpy="0 0 0" />
      <geometry>
        <mesh filename="../meshes/left_knee_pitch.STL" />
      </geometry>
      <material name="left_knee_pitch_material">
        <color rgba="0 0.5 1 1" />
      </material>
    </visual>
    
  </link>
  <joint name="left_knee_pitch_joint" type="revolute">
    <origin xyz="-0.0337000000000097 0 0.142200000000001" rpy="-1.57079632679488 0 -1.5707963267949" />
    <parent link="left_hip_yaw_link" />
    <child link="left_knee_pitch_link" />
    <axis xyz="0 0 1" />
    <limit lower="0" upper="2" effort="180.0" velocity="8.9" />
      <dynamics damping="1.0" />
  </joint>
  <link name="left_ankle_pitch_link">
    <inertial>
      <origin xyz="-2.32e-06 0 -2.048e-05" rpy="0 0 0" />
      <mass value="0.06217211" />
      <inertia ixx="2.273e-05" ixy="0" ixz="0" iyy="2.373e-05" iyz="0" izz="6.68e-06" />
    </inertial>
    <visual>
      <origin xyz="0 0 0" rpy="0 0 0" />
      <geometry>
        <mesh filename="../meshes/left_ankle_pitch.STL" />
      </geometry>
      <material name="left_ankle_pitch_material">
        <color rgba="0 0.5 1 1" />
      </material>
    </visual>
    
  </link>
  <joint name="left_ankle_pitch_joint" type="revolute">
    <origin xyz="0 -0.304939999999997 0.0336000000000411" rpy="-3.14159265358979 0 3.14159265358979" />
    <parent link="left_knee_pitch_link" />
    <child link="left_ankle_pitch_link" />
    <axis xyz="0 0 -1" />
    <limit lower="-0.41" upper="0.35" effort="80.0" velocity="13.61" />
      <dynamics damping="1.0" />
  </joint>
  <link name="left_ankle_roll_link">
    <inertial>
      <origin xyz="0.00017156 0 -0.00019936" rpy="0 0 0" />
      <mass value="0.58971207" />
      <inertia ixx="0.00152113" ixy="0" ixz="3.91e-06" iyy="0.00189897" iyz="0" izz="0.00054313" />
    </inertial>
    <visual>
      <origin xyz="0 0 0" rpy="0 0 0" />
      <geometry>
        <mesh filename="../meshes/left_ankle_roll.STL" />
      </geometry>
      <material name="left_ankle_roll_material">
        <color rgba="1 0.5 1 1" />
      </material>
    </visual>
    <collision>
      <origin xyz="0 0 0" rpy="0 0 0" />
      <geometry>
        <mesh filename="../meshes/left_ankle_roll.STL" />
      </geometry>
    </collision>
  </link>
  <joint name="left_ankle_roll_joint" type="revolute">
    <origin xyz="0 0 0" rpy="0 1.5707963267949 0" />
    <parent link="left_ankle_pitch_link" />
    <child link="left_ankle_roll_link" />
    <axis xyz="0 0 1" />
    <limit lower="-0.64" upper="0.64" effort="80.0" velocity="13.61" />
      <dynamics damping="1.0" />
  </joint>
  <link name="leg_l_toe_a_link">
    <inertial>
      <origin xyz="-0.00875902 0 -0.00875449" rpy="0 0 0" />
      <mass value="0.03114168" />
      <inertia ixx="4.33e-06" ixy="0" ixz="-1.59e-06" iyy="7.48e-06" iyz="0" izz="8.76e-06" />
    </inertial>
    <visual>
      <origin xyz="0 0 0" rpy="0 0 0" />
      <geometry>
        <mesh filename="../meshes/leg_l_toe_a_link.STL" />
      </geometry>
      <material name="">
        <color rgba="1 1 1 1" />
      </material>
    </visual>
    
  </link>
  <joint name="leg_l_toe_a_link_joint" type="fixed">
    <origin xyz="0.0198500000000011 -0.109961932116273 0.0336568378288508" rpy="0 -1.5707963267949 0" />
    <parent link="left_knee_pitch_link" />
    <child link="leg_l_toe_a_link" />
    <axis xyz="0 0 -1" />
    <limit lower="-3.14" upper="3.14" effort="0" velocity="0" />
  </joint>
  <link name="leg_l_toe_a_ball_link">
    <inertial>
      <origin xyz="-1.914e-05 0 1.9e-06" rpy="0 0 0" />
      <mass value="0.05674707" />
      <inertia ixx="0.00022106" ixy="0" ixz="0" iyy="1.09e-06" iyz="0" izz="0.00022113" />
    </inertial>
    <visual>
      <origin xyz="0 0 0" rpy="0 0 0" />
      <geometry>
        <mesh filename="../meshes/leg_l_toe_a_ball.STL" />
      </geometry>
      <material name="">
        <color rgba="1 1 1 1" />
      </material>
    </visual>
    
  </link>
  <joint name="leg_l_toe_a_ball_joint" type="fixed">
    <origin xyz="-0.0233806454082247 0.00902193211627456 -0.0211500000000038" rpy="0 0 0" />
    <parent link="leg_l_toe_a_link" />
    <child link="leg_l_toe_a_ball_link" />
    <axis xyz="0 0 0" />
  </joint>
  <link name="leg_l_toe_a_loop_link">
    <inertial>
      <origin xyz="0 0 -0.0006502" rpy="0 0 0" />
      <mass value="0.0062017" />
      <inertia ixx="2.8e-07" ixy="0" ixz="0" iyy="2.8e-07" iyz="0" izz="1.2e-07" />
    </inertial>
    <visual>
      <origin xyz="0 0 0" rpy="0 0 0" />
      <geometry>
        <mesh filename="../meshes/leg_l_toe_a_loop.STL" />
      </geometry>
      <material name="">
        <color rgba="1 1 1 1" />
      </material>
    </visual>
    
  </link>
  <joint name="leg_l_toe_a_loop_joint" type="fixed">
    <origin xyz="0 -0.195 0" rpy="0 1.5707963267949 0" />
    <parent link="leg_l_toe_a_ball_link" />
    <child link="leg_l_toe_a_loop_link" />
    <axis xyz="0 0 0" />
  </joint>
  <link name="leg_l_toe_b_link">
    <inertial>
      <origin xyz="0.0089831 0 -0.00906395" rpy="0 0 0" />
      <mass value="0.03161" />
      <inertia ixx="4.6e-06" ixy="0" ixz="1.73e-06" iyy="7.81e-06" iyz="0" izz="8.88e-06" />
    </inertial>
    <visual>
      <origin xyz="0 0 0" rpy="0 0 0" />
      <geometry>
        <mesh filename="../meshes/leg_l_toe_b_link.STL" />
      </geometry>
      <material name="">
        <color rgba="1 1 1 1" />
      </material>
    </visual>
    
  </link>
  <joint name="leg_l_toe_b_link_joint" type="fixed">
    <origin xyz="0.0198499999999967 -0.164961932116271 0.0335431621711256" rpy="0 -1.5707963267949 0" />
    <parent link="left_knee_pitch_link" />
    <child link="leg_l_toe_b_link" />
    <axis xyz="0 0 -1" />
    <limit lower="-3.14" upper="3.14" effort="0" velocity="0" />
  </joint>
  <link name="leg_l_toe_b_ball_link">
    <inertial>
      <origin xyz="-2.566e-05 0 2.566e-05" rpy="0 0 0" />
      <mass value="0.0423305" />
      <inertia ixx="9.172e-05" ixy="0" ixz="0" iyy="9.5e-07" iyz="0" izz="9.179e-05" />
    </inertial>
    <visual>
      <origin xyz="0 0 0" rpy="0 0 0" />
      <geometry>
        <mesh filename="../meshes/leg_l_toe_b_ball.STL" />
      </geometry>
      <material name="">
        <color rgba="1 1 1 1" />
      </material>
    </visual>
    
  </link>
  <joint name="leg_l_toe_b_ball_joint" type="fixed">
    <origin xyz="0.0233806454082588 0.00902193211627189 -0.0211500000000081" rpy="0 0 0" />
    <parent link="leg_l_toe_b_link" />
    <child link="leg_l_toe_b_ball_link" />
    <axis xyz="0 0 0" />
  </joint>
  <link name="leg_l_toe_b_loop_link">
    <inertial>
      <origin xyz="0 0 0.00064901" rpy="0 0 0" />
      <mass value="0.0062017" />
      <inertia ixx="2.8e-07" ixy="0" ixz="0" iyy="2.8e-07" iyz="0" izz="1.2e-07" />
    </inertial>
    <visual>
      <origin xyz="0 0 0" rpy="0 0 0" />
      <geometry>
        <mesh filename="../meshes/leg_l_toe_b_loop.STL" />
      </geometry>
      <material name="">
        <color rgba="1 1 1 1" />
      </material>
    </visual>
    
  </link>
  <joint name="leg_l_toe_b_loop_joint" type="fixed">
    <origin xyz="0 -0.14 0" rpy="0 1.5707963267949 0" />
    <parent link="leg_l_toe_b_ball_link" />
    <child link="leg_l_toe_b_loop_link" />
    <axis xyz="0 0 0" />
  </joint>
  
  <link name="right_hip_pitch_link">
    <inertial>
      <mass value="1.6733645" />
      <origin xyz="-4.816e-05 0 -0.0540778" rpy="0 0 0" />
      <inertia ixx="0.00234427" ixy="0" ixz="-8.23e-06" iyy="0.00252881" iyz="0" izz="0.00218719" />
    </inertial>
    <visual>
      <origin xyz="0 0 0" rpy="0 0 0" />
      <geometry>
        <mesh filename="../meshes/right_hip_pitch_perfect_mirrored.STL" />
      </geometry>
      <material name="left_hip_pitch_material">
        <color rgba="1 0.4 0.4 1" />
      </material>
    </visual>
    
  </link>
  <joint name="right_hip_pitch_joint" type="revolute">
    <origin xyz="0.00245 -0.092277 -0.012143" rpy="0 -0.7854 -1.5708" />
    <parent link="base_link" />
    <child link="right_hip_pitch_link" />
    <axis xyz="0 0 1" />
    <limit lower="-2" upper="1" effort="180.0" velocity="8.9" />
      <dynamics damping="1.0" />
  </joint>
  <link name="right_hip_roll_link">
    <inertial>
      <mass value="0.28562185" />
      <origin xyz="0.00014604 3.73194e-08 -0.0101534" rpy="0 0 0" />
      <inertia ixx="0.00055729" ixy="0" ixz="5.6e-07" iyy="0.0004105" iyz="0" izz="0.00047775" />
    </inertial>
    <visual>
      <origin xyz="0 0 0" rpy="0 0 0" />
      <geometry>
        <mesh filename="../meshes/right_hip_roll_perfect_mirrored.STL" />
      </geometry>
      <material name="left_hip_roll_material">
        <color rgba="1 1 0.4 1" />
      </material>
    </visual>
    
  </link>
  <joint name="right_hip_roll_joint" type="revolute">
    <origin xyz="0 0.0405 -0.0589" rpy="-1.5708 0.785398 0" />
    <parent link="right_hip_pitch_link" />
    <child link="right_hip_roll_link" />
    <axis xyz="0 0 -1" />
    <limit lower="-0.2" upper="1.5" effort="150.0" velocity="27.23" />
      <dynamics damping="1.0" />
  </joint>
  <link name="right_hip_yaw_link">
    <inertial>
      <origin xyz="-0.00212296 -6.73287e-07 0.0916484" rpy="0 0 0" />
      <mass value="2.7369623" />
      <inertia ixx="0.0127079" ixy="-4.45135e-09" ixz="0.000605922" iyy="0.0124495" iyz="6.62841e-08" izz="0.00342683" />
    </inertial>
    <visual>
      <origin xyz="0 0 0" rpy="0 0 0" />
      <geometry>
        <mesh filename="../meshes/right_hip_yaw_perfect_mirrored.STL" />
      </geometry>
      <material name="left_hip_yaw_material">
        <color rgba="0.4 1 0.4 1" />
      </material>
    </visual>
    
  </link>
  <joint name="right_hip_yaw_joint" type="revolute">
    <origin xyz="0 0.0838049 -0.0406" rpy="-1.5708 0 0" />
    <parent link="right_hip_roll_link" />
    <child link="right_hip_yaw_link" />
    <axis xyz="0 0 -1" />
    <limit lower="-1.5" upper="1.5" effort="150.0" velocity="27.23" />
      <dynamics damping="1.0" />
  </joint>
  <link name="right_knee_pitch_link">
    <inertial>
      <mass value="1.51225735" />
      <origin xyz="-0.00473551 7.25168e-08 0.0279688" rpy="0 0 0" />
      <inertia ixx="0.00806663" ixy="4.65773e-08" ixz="3.66893e-05" iyy="0.00174565" iyz="2.52465e-08" izz="0.00825577" />
    </inertial>
    <visual>
      <origin xyz="0 0 0" rpy="0 0 0" />
      <geometry>
        <mesh filename="../meshes/right_knee_pitch_perfect_mirrored.STL" />
      </geometry>
      <material name="left_knee_pitch_material">
        <color rgba="0 0.5 1 1" />
      </material>
    </visual>
    
  </link>
  <joint name="right_knee_pitch_joint" type="revolute">
    <origin xyz="-0.0337 0 0.1422" rpy="1.5708 0 1.5708" />
    <parent link="right_hip_yaw_link" />
    <child link="right_knee_pitch_link" />
    <axis xyz="0 0 -1" />
    <limit lower="0" upper="2" effort="180.0" velocity="8.9" />
      <dynamics damping="1.0" />
  </joint>
  <link name="right_ankle_pitch_link">
    
      <inertial>
      
      <origin xyz="-2.32e-06 0 -2.048e-05" rpy="0 0 0" />
      
      <mass value="0.06217211" />
      
      <inertia ixx="2.273e-05" ixy="0" ixz="0" iyy="2.373e-05" iyz="0" izz="6.68e-06" />
    
    </inertial>
    <visual>
      <origin xyz="0 0 0" rpy="0 0 0" />
      <geometry>
        <mesh filename="../meshes/right_ankle_pitch_perfect_mirrored.STL" />
      </geometry>
      <material name="left_ankle_pitch_material">
        <color rgba="0 0.5 1 1" />
      </material>
    </visual>
    
  </link>
  <joint name="right_ankle_pitch_joint" type="revolute">
    <origin xyz="0 0.30494 0.0336" rpy="3.14159 0 -3.14159" />
    <parent link="right_knee_pitch_link" />
    <child link="right_ankle_pitch_link" />
    <axis xyz="0 0 1" />
    <limit lower="-0.41" upper="0.35" effort="80.0" velocity="13.61" />
      <dynamics damping="1.0" />
  </joint>
  <link name="right_ankle_roll_link">
    <inertial>
      <mass value="0.58971207" />
      <origin xyz="0.00017156 0 -0.00019936" rpy="0 0 0" />
      <inertia ixx="0.00152113" ixy="0" ixz="3.91e-06" iyy="0.00189897" iyz="0" izz="0.00054313" />
    </inertial>
    <visual>
      <origin xyz="0 0 0" rpy="0 0 0" />
      <geometry>
        <mesh filename="../meshes/right_ankle_roll_perfect_mirrored.STL" />
      </geometry>
      <material name="left_ankle_roll_material">
        <color rgba="1 0.5 1 1" />
      </material>
    </visual>
    <collision>
      <origin xyz="0 0 0" rpy="0 0 0" />
      <geometry>
        <mesh filename="../meshes/right_ankle_roll_perfect_mirrored.STL" />
      </geometry>
    </collision>
  </link>
  <joint name="right_ankle_roll_joint" type="revolute">
    <origin xyz="0 0 0" rpy="0 1.5708 0" />
    <parent link="right_ankle_pitch_link" />
    <child link="right_ankle_roll_link" />
    <axis xyz="0 0 1" />
    <limit lower="-0.64" upper="0.64" effort="80.0" velocity="13.61" />
      <dynamics damping="1.0" />
  </joint>
  <link name="leg_r_toe_a_link">
    <inertial>
      <origin xyz="-0.00875902 3.07093e-08 -0.00875449" rpy="0 0 0" />
      <mass value="0.03114168" />
      <inertia ixx="4.33e-06" ixy="0" ixz="-1.59e-06" iyy="7.48e-06" iyz="0" izz="8.76e-06" />
    </inertial>
    <visual>
      <origin xyz="0 0 0" rpy="0 0 0" />
      <geometry>
        <mesh filename="../meshes/leg_r_toe_a_link_perfect_mirrored.STL" />
      </geometry>
      <material name="">
        <color rgba="1 1 1 1" />
      </material>
    </visual>
    
  </link>
  <joint name="leg_r_toe_a_link_joint" type="fixed">
    <origin xyz="0.01985 0.109962 0.0336568" rpy="0 -1.5708 0" />
    <parent link="right_knee_pitch_link" />
    <child link="leg_r_toe_a_link" />
    <axis xyz="0 0 -1" />
    <limit lower="-3.14" upper="3.14" effort="0" velocity="0" />
  </joint>
  <link name="leg_r_toe_a_ball_link">
    <inertial>
      <origin xyz="-1.914e-05 0 1.9e-06" rpy="0 0 0" />
      <mass value="0.05674707" />
      <inertia ixx="0.00022106" ixy="0" ixz="0" iyy="1.09e-06" iyz="0" izz="0.00022113" />
    </inertial>
    <visual>
      <origin xyz="0 0 0" rpy="0 0 0" />
      <geometry>
        <mesh filename="../meshes/leg_r_toe_a_ball_perfect_mirrored.STL" />
      </geometry>
      <material name="">
        <color rgba="1 1 1 1" />
      </material>
    </visual>
    
  </link>
  <joint name="leg_r_toe_a_ball_joint" type="fixed">
    <origin xyz="-0.0233806 -0.00902193 -0.02115" rpy="0 0 0" />
    <parent link="leg_r_toe_a_link" />
    <child link="leg_r_toe_a_ball_link" />
    <axis xyz="0 0 0" />
  </joint>
  <link name="leg_r_toe_a_loop_link">
    <inertial>
      <origin xyz="0 0 -0.0006502" rpy="0 0 0" />
      <mass value="0.0062017" />
      <inertia ixx="2.8e-07" ixy="0" ixz="0" iyy="2.8e-07" iyz="0" izz="1.2e-07" />
    </inertial>
    <visual>
      <origin xyz="0 0 0" rpy="0 0 0" />
      <geometry>
        <mesh filename="../meshes/leg_r_toe_a_loop_perfect_mirrored.STL" />
      </geometry>
      <material name="">
        <color rgba="1 1 1 1" />
      </material>
    </visual>
    
  </link>
  <joint name="leg_r_toe_a_loop_joint" type="fixed">
    <origin xyz="0 0.195 0" rpy="0 1.5708 0" />
    <parent link="leg_r_toe_a_ball_link" />
    <child link="leg_r_toe_a_loop_link" />
    <axis xyz="0 0 0" />
  </joint>
  <link name="leg_r_toe_b_link">
    <inertial>
      <origin xyz="0.0089831 1.01052e-07 -0.00906395" rpy="0 0 0" />
      <mass value="0.03161" />
      <inertia ixx="4.6e-06" ixy="0" ixz="1.73e-06" iyy="7.81e-06" iyz="0" izz="8.88e-06" />
    </inertial>
    <visual>
      <origin xyz="0 0 0" rpy="0 0 0" />
      <geometry>
        <mesh filename="../meshes/leg_r_toe_b_link_perfect_mirrored.STL" />
      </geometry>
      <material name="">
        <color rgba="1 1 1 1" />
      </material>
    </visual>
    
  </link>
  <joint name="leg_r_toe_b_link_joint" type="fixed">
    <origin xyz="0.01985 0.164962 0.0335432" rpy="0 -1.5708 0" />
    <parent link="right_knee_pitch_link" />
    <child link="leg_r_toe_b_link" />
    <axis xyz="0 0 -1" />
    <limit lower="-3.14" upper="3.14" effort="0" velocity="0" />
  </joint>
  <link name="leg_r_toe_b_ball_link">
    <inertial>
      <origin xyz="-2.566e-05 0 2.566e-05" rpy="0 0 0" />
      <mass value="0.0423305" />
      <inertia ixx="9.172e-05" ixy="0" ixz="0" iyy="9.5e-07" iyz="0" izz="9.179e-05" />
    </inertial>
    <visual>
      <origin xyz="0 0 0" rpy="0 0 0" />
      <geometry>
        <mesh filename="../meshes/leg_r_toe_b_ball_perfect_mirrored.STL" />
      </geometry>
      <material name="">
        <color rgba="1 1 1 1" />
      </material>
    </visual>
    
  </link>
  <joint name="leg_r_toe_b_ball_joint" type="fixed">
    <origin xyz="0.0233806 -0.00902193 -0.02115" rpy="0 0 0" />
    <parent link="leg_r_toe_b_link" />
    <child link="leg_r_toe_b_ball_link" />
    <axis xyz="0 0 0" />
  </joint>
  <link name="leg_r_toe_b_loop_link">
    <inertial>
      <origin xyz="0 0 0.00064901" rpy="0 0 0" />
      <mass value="0.0062017" />
      <inertia ixx="2.8e-07" ixy="0" ixz="0" iyy="2.8e-07" iyz="0" izz="1.2e-07" />
    </inertial>
    <visual>
      <origin xyz="0 0 0" rpy="0 0 0" />
      <geometry>
        <mesh filename="../meshes/leg_r_toe_b_loop_perfect_mirrored.STL" />
      </geometry>
      <material name="">
        <color rgba="1 1 1 1" />
      </material>
    </visual>
    
  </link>
  <joint name="leg_r_toe_b_loop_joint" type="fixed">
    <origin xyz="0 0.14 0" rpy="0 1.5708 0" />
    <parent link="leg_r_toe_b_ball_link" />
    <child link="leg_r_toe_b_loop_link" />
    <axis xyz="0 0 0" />
  </joint>
  <link name="arm_r_wrist_a_ball_link">
    <inertial>
      <origin xyz="-1.59104e-08 8.74451e-08 0.00973737" rpy="0 0 0" />
      <mass value="0.23598732" />
      <inertia ixx="7.634e-05" ixy="0" ixz="-3e-08" iyy="2.519e-05" iyz="0" izz="7.977e-05" />
    </inertial>
    <visual>
      <origin xyz="0 0 0" rpy="0 0 0" />
      <geometry>
        <mesh filename="../meshes/arm_r_wrist_a_ball_right_perfect_mirrored.STL" />
      </geometry>
      <material name="">
        <color rgba="1 1 1 1" />
      </material>
    </visual>
    
  </link>
  <joint name="arm_r_wrist_a_ball_joint" type="fixed">
    <origin xyz="-0.009 0.02 -0.0199" rpy="-1.5708 0 0" />
    <parent link="right_elbow_yaw_link" />
    <child link="arm_r_wrist_a_ball_link" />
    <axis xyz="0 0 0" />
  </joint>
  <link name="arm_r_wrist_motor_a_link">
    <inertial>
      <origin xyz="2.58417e-08 8.69573e-08 0.00973737" rpy="0 0 0" />
      <mass value="0.00117982" />
      <inertia ixx="6e-08" ixy="0" ixz="0" iyy="8e-08" iyz="0" izz="2e-08" />
    </inertial>
    <visual>
      <origin xyz="0 0 0" rpy="0 0 0" />
      <geometry>
        <mesh filename="../meshes/arm_r_wrist_motor_a_link_right_perfect_mirrored.STL" />
      </geometry>
      <material name="">
        <color rgba="1 1 1 1" />
      </material>
    </visual>
    
  </link>
  <joint name="arm_r_wrist_motor_a_link_joint" type="fixed">
    <origin xyz="0.0027628 0.097124 0" rpy="-1.5708 0 -0.028438" />
    <parent link="arm_r_wrist_a_ball_link" />
    <child link="arm_r_wrist_motor_a_link" />
    <axis xyz="0 0 1" />
    <limit lower="-3.14" upper="3.14" effort="0" velocity="0" />
  </joint>
  <link name="arm_r_wrist_a_loop_link">
    <inertial>
      <origin xyz="0 0 -1.922e-05" rpy="0 0 0" />
      <mass value="0.00548041" />
      <inertia ixx="8e-08" ixy="0" ixz="0" iyy="8e-08" iyz="0" izz="7e-08" />
    </inertial>
    <visual>
      <origin xyz="0 0 0" rpy="0 0 0" />
      <geometry>
        <mesh filename="../meshes/arm_r_wrist_a_loop_right_perfect_mirrored.STL" />
      </geometry>
      <material name="">
        <color rgba="1 1 1 1" />
      </material>
    </visual>
    
  </link>
  <joint name="arm_r_wrist_a_loop_joint" type="fixed">
    <origin xyz="0 0 0.0132" rpy="1.5708 -0.028438 0" />
    <parent link="arm_r_wrist_motor_a_link" />
    <child link="arm_r_wrist_a_loop_link" />
    <axis xyz="0 0 0" />
  </joint>
  <link name="arm_r_wrist_b_ball_link">
    <inertial>
      <origin xyz="0.00121967 0 0" rpy="0 0 0" />
      <mass value="0.03617567" />
      <inertia ixx="1.73e-05" ixy="0" ixz="0" iyy="4.69e-06" iyz="0" izz="1.731e-05" />
    </inertial>
    <visual>
      <origin xyz="0 0 0" rpy="0 0 0" />
      <geometry>
        <mesh filename="../meshes/arm_r_wrist_b_ball_right_perfect_mirrored.STL" />
      </geometry>
      <material name="">
        <color rgba="1 1 1 1" />
      </material>
    </visual>
    
  </link>
  <joint name="arm_r_wrist_b_ball_joint" type="fixed">
    <origin xyz="-0.009 -0.02 -0.0199" rpy="1.5708 0 0" />
    <parent link="right_elbow_yaw_link" />
    <child link="arm_r_wrist_b_ball_link" />
    <axis xyz="0 0 0" />
  </joint>
  <link name="arm_r_wrist_motor_b_link">
    <inertial>
      <mass value="0.23598732" />
      <origin xyz="0.00076586 -1.88513e-09 -4.9122e-05" rpy="0 0 0" />
      <inertia ixx="7.634e-05" ixy="0" ixz="3.00091e-08" iyy="2.519e-05" iyz="4.87358e-10" izz="7.977e-05" />
    </inertial>
    <visual>
      <origin xyz="0 0 0" rpy="0 0 0" />
      <geometry>
        <mesh filename="../meshes/arm_r_wrist_motor_b_link_right_perfect_mirrored.STL" />
      </geometry>
      <material name="">
        <color rgba="1 1 1 1" />
      </material>
    </visual>
    
  </link>
  <joint name="arm_r_wrist_motor_b_link_joint" type="fixed">
    <origin xyz="0.0027628 -0.097124 0" rpy="1.5708 0 0.028438" />
    <parent link="arm_r_wrist_b_ball_link" />
    <child link="arm_r_wrist_motor_b_link" />
    <axis xyz="0 0 1" />
    <limit lower="-3.14" upper="3.14" effort="0" velocity="0" />
  </joint>
  <link name="arm_r_wrist_b_loop_link">
    <inertial>
      <mass value="0.00117982" />
      <origin xyz="1.59106e-08 8.74451e-08 0.00973737" rpy="0 0 0" />
      <inertia ixx="6e-08" ixy="0" ixz="0" iyy="8e-08" iyz="0" izz="2e-08" />
    </inertial>
    <visual>
      <origin xyz="0 0 0" rpy="0 0 0" />
      <geometry>
        <mesh filename="../meshes/arm_r_wrist_b_loop_right_perfect_mirrored.STL" />
      </geometry>
      <material name="">
        <color rgba="1 1 1 1" />
      </material>
    </visual>
    
  </link>
  <joint name="arm_r_wrist_b_loop_joint" type="fixed">
    <origin xyz="0 0 0.0132" rpy="-1.5708 -0.028438 0" />
    <parent link="arm_r_wrist_motor_b_link" />
    <child link="arm_r_wrist_b_loop_link" />
    <axis xyz="0 0 0" />
  </joint>
  <link name="arm_l_wrist_a_ball_link">
    <inertial>
      <origin xyz="0 0 0.00973737" rpy="0 0 0" />
      <mass value="0.23598732" />
      <inertia ixx="7.634e-05" ixy="0" ixz="-3e-08" iyy="2.519e-05" iyz="0" izz="7.977e-05" />
    </inertial>
    <visual>
      <origin xyz="0 0 0" rpy="0 0 0" />
      <geometry>
        <mesh filename="../meshes/arm_r_wrist_a_ball.STL" />
      </geometry>
      <material name="">
        <color rgba="1 1 1 1" />
      </material>
    </visual>
    
  </link>
  <joint name="arm_l_wrist_a_ball_joint" type="fixed">
    <origin xyz="-0.009 -0.02 -0.0199" rpy="1.5708 0 0" />
    <parent link="left_elbow_yaw_link" />
    <child link="arm_l_wrist_a_ball_link" />
    <axis xyz="0 0 0" />
  </joint>
  <link name="arm_l_wrist_motor_a_link">
    <inertial>
      <origin xyz="0 0 0.00973737" rpy="0 0 0" />
      <mass value="0.00117982" />
      <inertia ixx="6e-08" ixy="0" ixz="0" iyy="8e-08" iyz="0" izz="2e-08" />
    </inertial>
    <visual>
      <origin xyz="0 0 0" rpy="0 0 0" />
      <geometry>
        <mesh filename="../meshes/arm_r_wrist_motor_a_link.STL" />
      </geometry>
      <material name="">
        <color rgba="1 1 1 1" />
      </material>
    </visual>
    
  </link>
  <joint name="arm_l_wrist_motor_a_link_joint" type="fixed">
    <origin xyz="0.0027628 -0.097124 0" rpy="1.5708 0 0.028438" />
    <parent link="arm_l_wrist_a_ball_link" />
    <child link="arm_l_wrist_motor_a_link" />
    <axis xyz="0 0 1" />
    <limit lower="-3.14" upper="3.14" effort="0" velocity="0" />
  </joint>
  <link name="arm_l_wrist_a_loop_link">
    <inertial>
      <origin xyz="0 0 -1.922e-05" rpy="0 0 0" />
      <mass value="0.00548041" />
      <inertia ixx="8e-08" ixy="0" ixz="0" iyy="8e-08" iyz="0" izz="7e-08" />
    </inertial>
    <visual>
      <origin xyz="0 0 0" rpy="0 0 0" />
      <geometry>
        <mesh filename="../meshes/arm_r_wrist_a_loop.STL" />
      </geometry>
      <material name="">
        <color rgba="1 1 1 1" />
      </material>
    </visual>
    
  </link>
  <joint name="arm_l_wrist_a_loop_joint" type="fixed">
    <origin xyz="0 0 0.0132" rpy="-1.5708 -0.028438 0" />
    <parent link="arm_l_wrist_motor_a_link" />
    <child link="arm_l_wrist_a_loop_link" />
    <axis xyz="0 0 0" />
  </joint>
  <link name="arm_l_wrist_b_ball_link">
    <inertial>
      <origin xyz="0.00121967 0 0" rpy="0 0 0" />
      <mass value="0.03617567" />
      <inertia ixx="1.73e-05" ixy="0" ixz="0" iyy="4.69e-06" iyz="0" izz="1.731e-05" />
    </inertial>
    <visual>
      <origin xyz="0 0 0" rpy="0 0 0" />
      <geometry>
        <mesh filename="../meshes/arm_r_wrist_b_ball.STL" />
      </geometry>
      <material name="">
        <color rgba="1 1 1 1" />
      </material>
    </visual>
    
  </link>
  <joint name="arm_l_wrist_b_ball_joint" type="fixed">
    <origin xyz="-0.009 0.02 -0.0199" rpy="-1.5708 0 0" />
    <parent link="left_elbow_yaw_link" />
    <child link="arm_l_wrist_b_ball_link" />
    <axis xyz="0 0 0" />
  </joint>
  <link name="arm_l_wrist_motor_b_link">
    <inertial>
      <origin xyz="0.00076586 0 -4.912e-05" rpy="0 0 0" />
      <mass value="0.23598732" />
      <inertia ixx="7.634e-05" ixy="0" ixz="3e-08" iyy="2.519e-05" iyz="0" izz="7.977e-05" />
    </inertial>
    <visual>
      <origin xyz="0 0 0" rpy="0 0 0" />
      <geometry>
        <mesh filename="../meshes/arm_r_wrist_motor_b_link.STL" />
      </geometry>
      <material name="">
        <color rgba="1 1 1 1" />
      </material>
    </visual>
    
  </link>
  <joint name="arm_l_wrist_motor_b_link_joint" type="fixed">
    <origin xyz="0.0027628 0.097124 0" rpy="-1.5708 0 -0.028438" />
    <parent link="arm_l_wrist_b_ball_link" />
    <child link="arm_l_wrist_motor_b_link" />
    <axis xyz="0 0 1" />
    <limit lower="-3.14" upper="3.14" effort="0" velocity="0" />
  </joint>
  <link name="arm_l_wrist_b_loop_link">
    <inertial>
      <origin xyz="0 0 0.00973737" rpy="0 0 0" />
      <mass value="0.00117982" />
      <inertia ixx="6e-08" ixy="0" ixz="0" iyy="8e-08" iyz="0" izz="2e-08" />
    </inertial>
    <visual>
      <origin xyz="0 0 0" rpy="0 0 0" />
      <geometry>
        <mesh filename="../meshes/arm_r_wrist_b_loop.STL" />
      </geometry>
      <material name="">
        <color rgba="1 1 1 1" />
      </material>
    </visual>
    
  </link>
  <joint name="arm_l_wrist_b_loop_joint" type="fixed">
    <origin xyz="0 0 0.0132" rpy="1.5708 -0.028438 0" />
    <parent link="arm_l_wrist_motor_b_link" />
    <child link="arm_l_wrist_b_loop_link" />
    <axis xyz="0 0 0" />
  </joint>
</robot>