<?xml version='1.0' encoding='utf-8'?>
<mujoco model="x1_12dof">
  <compiler angle="radian" meshdir="../meshes/" fusestatic="false" />

  <default><geom contype="0" conaffinity="0" solref="0.005 1" condim="3" friction="1 1" /><joint /><equality solref="0.005 1" /><default class="collision"><geom contype="1" group="3" type="capsule" /><default class="collision-left"><geom contype="2" conaffinity="4" /></default><default class="collision-right"><geom contype="4" conaffinity="2" /></default></default></default><asset>
    <mesh name="base_link_simple" content_type="model/stl" file="base_link_simple.STL" />
    <mesh name="lumbar_yaw" content_type="model/stl" file="lumbar_yaw.STL" />
    <mesh name="lumbar_roll" content_type="model/stl" file="lumbar_roll.STL" />
    <mesh name="lumbar_pitch_x1" content_type="model/stl" file="lumbar_pitch_x1.STL" />
    <mesh name="left_shoulder_pitch" content_type="model/stl" file="left_shoulder_pitch.STL" />
    <mesh name="left_shoulder_roll" content_type="model/stl" file="left_shoulder_roll.STL" />
    <mesh name="left_shoulder_yaw" content_type="model/stl" file="left_shoulder_yaw.STL" />
    <mesh name="left_elbow_pitch" content_type="model/stl" file="left_elbow_pitch.STL" />
    <mesh name="left_elbow_yaw" content_type="model/stl" file="left_elbow_yaw.STL" />
    <mesh name="left_wrist_pitch" content_type="model/stl" file="left_wrist_pitch.STL" />
    <mesh name="right_shoulder_pitch" content_type="model/stl" file="right_shoulder_pitch.STL" />
    <mesh name="right_shoulder_roll" content_type="model/stl" file="right_shoulder_roll.STL" />
    <mesh name="right_shoulder_yaw" content_type="model/stl" file="right_shoulder_yaw.STL" />
    <mesh name="right_elbow_pitch" content_type="model/stl" file="right_elbow_pitch.STL" />
    <mesh name="right_elbow_yaw" content_type="model/stl" file="right_elbow_yaw.STL" />
    <mesh name="right_wrist_pitch" content_type="model/stl" file="right_wrist_pitch.STL" />
    <mesh name="waist_motor_a_link" content_type="model/stl" file="waist_motor_a_link.STL" />
    <mesh name="waist_motor_a_ball" content_type="model/stl" file="waist_motor_a_ball.STL" />
    <mesh name="waist_motor_a_loop" content_type="model/stl" file="waist_motor_a_loop.STL" />
    <mesh name="waist_motor_b_link" content_type="model/stl" file="waist_motor_b_link.STL" />
    <mesh name="waist_motor_b_ball" content_type="model/stl" file="waist_motor_b_ball.STL" />
    <mesh name="waist_motor_b_loop" content_type="model/stl" file="waist_motor_b_loop.STL" />
    <mesh name="left_hip_pitch" content_type="model/stl" file="left_hip_pitch.STL" />
    <mesh name="left_hip_roll" content_type="model/stl" file="left_hip_roll.STL" />
    <mesh name="left_hip_yaw" content_type="model/stl" file="left_hip_yaw.STL" />
    <mesh name="left_knee_pitch" content_type="model/stl" file="left_knee_pitch.STL" />
    <mesh name="left_ankle_pitch" content_type="model/stl" file="left_ankle_pitch.STL" />
    <mesh name="left_ankle_roll" content_type="model/stl" file="left_ankle_roll.STL" />
    <mesh name="leg_l_toe_a_link" content_type="model/stl" file="leg_l_toe_a_link.STL" />
    <mesh name="leg_l_toe_a_ball" content_type="model/stl" file="leg_l_toe_a_ball.STL" />
    <mesh name="leg_l_toe_a_loop" content_type="model/stl" file="leg_l_toe_a_loop.STL" />
    <mesh name="leg_l_toe_b_link" content_type="model/stl" file="leg_l_toe_b_link.STL" />
    <mesh name="leg_l_toe_b_ball" content_type="model/stl" file="leg_l_toe_b_ball.STL" />
    <mesh name="leg_l_toe_b_loop" content_type="model/stl" file="leg_l_toe_b_loop.STL" />
    <mesh name="right_hip_pitch" content_type="model/stl" file="right_hip_pitch.STL" />
    <mesh name="right_hip_roll" content_type="model/stl" file="right_hip_roll.STL" />
    <mesh name="right_hip_yaw" content_type="model/stl" file="right_hip_yaw.STL" />
    <mesh name="right_knee_pitch" content_type="model/stl" file="right_knee_pitch.STL" />
    <mesh name="right_ankle_pitch" content_type="model/stl" file="right_ankle_pitch.STL" />
    <mesh name="right_ankle_roll" content_type="model/stl" file="right_ankle_roll.STL" />
    <mesh name="leg_r_toe_a_link" content_type="model/stl" file="leg_r_toe_a_link.STL" />
    <mesh name="leg_r_toe_a_ball" content_type="model/stl" file="leg_r_toe_a_ball.STL" />
    <mesh name="leg_r_toe_a_loop" content_type="model/stl" file="leg_r_toe_a_loop.STL" />
    <mesh name="leg_r_toe_b_link" content_type="model/stl" file="leg_r_toe_b_link.STL" />
    <mesh name="leg_r_toe_b_ball" content_type="model/stl" file="leg_r_toe_b_ball.STL" />
    <mesh name="leg_r_toe_b_loop" content_type="model/stl" file="leg_r_toe_b_loop.STL" />
    <mesh name="arm_r_wrist_a_ball" content_type="model/stl" file="arm_r_wrist_a_ball.STL" />
    <mesh name="arm_r_wrist_motor_a_link" content_type="model/stl" file="arm_r_wrist_motor_a_link.STL" />
    <mesh name="arm_r_wrist_a_loop" content_type="model/stl" file="arm_r_wrist_a_loop.STL" />
    <mesh name="arm_r_wrist_b_ball" content_type="model/stl" file="arm_r_wrist_b_ball.STL" />
    <mesh name="arm_r_wrist_motor_b_link" content_type="model/stl" file="arm_r_wrist_motor_b_link.STL" />
    <mesh name="arm_r_wrist_b_loop" content_type="model/stl" file="arm_r_wrist_b_loop.STL" />
  </asset>

  <worldbody>
    <body name="base_link" pos="0 0 0.7">
      <freejoint name="floating_base" /><site name="imu" size="0.01" pos="0 0 0" /><inertial pos="0.00252285 -0.00063439 0.0302341" quat="0.703473 0.710702 -0.00394586 0.00368824" mass="4.30416" diaginertia="0.0268062 0.0218101 0.0108301" />
      <geom type="mesh" contype="0" conaffinity="0" group="1" density="0" rgba="0.8 0.4 0 1" mesh="base_link_simple" />
      <geom type="mesh" rgba="0.8 0.4 0 1" mesh="base_link_simple" />
      <body name="lumbar_yaw_link" pos="0.00245 0 0.115534" quat="1 0 0 -2.27456e-05">
        <inertial pos="-0.0180007 1.4e-06 0.0243298" quat="-7.72625e-06 0.78309 -2.54549e-05 0.621909" mass="0.362519" diaginertia="0.000655093 0.00045823 0.000342457" />
        <geom type="mesh" contype="0" conaffinity="0" group="1" density="0" rgba="1 0.4 0.4 1" mesh="lumbar_yaw" />
        <body name="lumbar_roll_link" pos="0 0 0.0405" quat="0.5 0.5 -0.5 -0.5">
          <inertial pos="-0.00029919 0.0003642 -0.00019197" quat="0.773215 -0.138631 -0.0225684 0.618394" mass="0.0341207" diaginertia="5.46439e-06 4.90308e-06 4.81253e-06" />
          <geom type="mesh" contype="0" conaffinity="0" group="1" density="0" rgba="1 0.4 0.4 1" mesh="lumbar_roll" />
          <body name="lumbar_pitch_link" quat="0.707107 0 0.707107 0">
            <inertial pos="0.00070244 0.210726 -0.00117164" quat="0.701682 0.712112 -0.0198998 -0.0119722" mass="8.85711" diaginertia="0.147956 0.111655 0.0606701" />
            <geom type="mesh" contype="0" conaffinity="0" group="1" density="0" rgba="0.4 1 0.4 1" mesh="lumbar_pitch_x1" />
            <body name="left_shoulder_pitch_link" pos="0 0.256 -0.1458" quat="0 0 0 -1">
              <inertial pos="-0.00251212 -0.00149141 -0.0567447" quat="0.995975 -0.00474479 -0.0345991 0.0825443" mass="1.00679" diaginertia="0.00108562 0.000958162 0.000853398" />
              <geom type="mesh" contype="0" conaffinity="0" group="1" density="0" rgba="1 0.4 0.4 1" mesh="left_shoulder_pitch" />
              <body name="left_shoulder_roll_link" pos="-0.0313 0 -0.0592" quat="0.707105 0 -0.707108 0">
                <inertial pos="0.000154 0.0778464 -0.0271134" quat="0.765297 0.643563 -0.00747942 0.00959688" mass="0.691695" diaginertia="0.00133677 0.00119611 0.000636982" />
                <geom type="mesh" contype="0" conaffinity="0" group="1" density="0" rgba="1 1 0.4 1" mesh="left_shoulder_roll" />
                <body name="left_shoulder_yaw_link" pos="0 0.1252 -0.0313" quat="0.5 0.5 0.5 -0.5">
                  <inertial pos="-2.68e-06 0.00182113 -0.00392718" quat="0.695603 -0.0321904 0.0318975 0.716996" mass="0.725594" diaginertia="0.00118335 0.00116041 0.000481204" />
                  <geom type="mesh" contype="0" conaffinity="0" group="1" density="0" rgba="0.4 1 0.4 1" mesh="left_shoulder_yaw" />
                  <body name="left_elbow_pitch_link" pos="0 -0.031 -0.0365" quat="0.707107 -0.707107 0 0">
                    <inertial pos="2.604e-05 0.0752824 0.0268658" quat="0.597053 0.802202 -2.17373e-05 0.000362389" mass="0.697801" diaginertia="0.00116267 0.00100065 0.000614359" />
                    <geom type="mesh" contype="0" conaffinity="0" group="1" density="0" rgba="0 0.5 1 1" mesh="left_elbow_pitch" />
                    <body name="left_elbow_yaw_link" pos="0 0.117 0.031" quat="0.499999 0.499999 -0.500001 0.500001">
                      <inertial pos="3.656e-05 0.00424199 -0.0542142" quat="0.996462 0.0840255 0.000993479 0.00116848" mass="0.287879" diaginertia="0.000714861 0.000702477 0.000540322" />
                      <geom type="mesh" contype="0" conaffinity="0" group="1" density="0" rgba="0.8 1 0.8 1" mesh="left_elbow_yaw" />
                      <body name="left_wrist_pitch_link" pos="0.006 0.0001 -0.1394" quat="0.439542 0.553896 -0.439547 -0.553896">
                        <inertial pos="0.00229425 0 9.994e-05" quat="0.707107 0 0 0.707107" mass="0.00900738" diaginertia="5.7e-07 3.8e-07 2.4e-07" />
                        <geom type="mesh" contype="0" conaffinity="0" group="1" density="0" rgba="1 0.5 1 1" mesh="left_wrist_pitch" />
                        <body name="left_wrist_roll_link" quat="0.690886 -0.150583 0.65524 -0.265823">
                          <inertial pos="-0.0197311 -0.0321776 -0.00133858" quat="0.999268 -0.0353712 -0.000518759 0.0145933" mass="0.370899" diaginertia="0.000404081 0.000356845 0.000211594" />
                        </body>
                      </body>
                      <body name="arm_l_wrist_a_ball_link" pos="-0.009 -0.02 -0.0199" quat="0.707105 0.707108 0 0">
                        <inertial pos="0.00076586 -0.0115683 4.912e-05" quat="0.490941 0.50421 -0.49667 0.508004" mass="0.235987" diaginertia="7.97705e-05 7.63707e-05 2.51588e-05" />
                        <geom type="mesh" contype="0" conaffinity="0" group="1" density="0" rgba="1 1 1 1" mesh="arm_r_wrist_a_ball" />
                        <body name="arm_l_wrist_motor_a_link" pos="0.0027628 -0.097124 0" quat="0.707034 0.707037 0.010054 0.010054">
                          <inertial pos="0 0 0.00973737" quat="0.707107 0 0 0.707107" mass="0.00117982" diaginertia="8e-08 6e-08 2e-08" />
                          <geom type="mesh" contype="0" conaffinity="0" group="1" density="0" rgba="1 1 1 1" mesh="arm_r_wrist_motor_a_link" />
                          <body name="arm_l_wrist_a_loop_link" pos="0 0 0.0132" quat="0.707034 -0.707037 -0.010054 -0.010054">
                            <inertial pos="0 0 -1.922e-05" mass="0.00548041" diaginertia="8e-08 8e-08 7e-08" />
                            <geom type="mesh" contype="0" conaffinity="0" group="1" density="0" rgba="1 1 1 1" mesh="arm_r_wrist_a_loop" />
                          </body>
                        </body>
                      </body>
                      <body name="arm_l_wrist_b_ball_link" pos="-0.009 0.02 -0.0199" quat="0.707105 -0.707108 0 0">
                        <inertial pos="0.00121967 0.0441726 0" quat="0.707014 0.707014 -0.0114787 -0.0114787" mass="0.0361757" diaginertia="1.73133e-05 1.731e-05 4.67668e-06" />
                        <geom type="mesh" contype="0" conaffinity="0" group="1" density="0" rgba="1 1 1 1" mesh="arm_r_wrist_b_ball" />
                        <body name="arm_l_wrist_motor_b_link" pos="0.0027628 0.097124 0" quat="0.707034 -0.707037 0.010054 -0.010054">
                          <inertial pos="0.00076586 0.0115683 -4.912e-05" quat="0.508004 0.49667 -0.50421 0.490941" mass="0.235987" diaginertia="7.97705e-05 7.63707e-05 2.51588e-05" />
                          <geom type="mesh" contype="0" conaffinity="0" group="1" density="0" rgba="1 1 1 1" mesh="arm_r_wrist_motor_b_link" />
                          <body name="arm_l_wrist_b_loop_link" pos="0 0 0.0132" quat="0.707034 0.707037 -0.010054 0.010054">
                            <inertial pos="0 0 0.00973737" quat="0.707107 0 0 0.707107" mass="0.00117982" diaginertia="8e-08 6e-08 2e-08" />
                            <geom type="mesh" contype="0" conaffinity="0" group="1" density="0" rgba="1 1 1 1" mesh="arm_r_wrist_b_loop" />
                          </body>
                        </body>
                      </body>
                    </body>
                  </body>
                </body>
              </body>
            </body>
            <body name="right_shoulder_pitch_link" pos="0 0.256 0.1458" quat="-3.67321e-06 1 0 0">
              <inertial pos="0.00250704 -0.00149173 -0.0567433" quat="0.995977 -0.00568417 0.0346063 -0.0824611" mass="1.00679" diaginertia="0.00108562 0.000958168 0.000853396" />
              <geom type="mesh" contype="0" conaffinity="0" group="1" density="0" rgba="1 0.4 0.4 1" mesh="right_shoulder_pitch" />
              <body name="right_shoulder_roll_link" pos="0.0313 0 -0.0592" quat="-2.59734e-06 0.707105 2.59735e-06 0.707108">
                <inertial pos="0.000154 0.0778464 0.0271134" quat="0.643563 0.765297 0.00959688 -0.00747942" mass="0.691695" diaginertia="0.00133677 0.00119611 0.000636982" />
                <geom type="mesh" contype="0" conaffinity="0" group="1" density="0" rgba="1 0.4 0.4 1" mesh="right_shoulder_roll" />
                <body name="right_shoulder_yaw_link" pos="0 -0.1252 -0.0313" quat="0.707105 0.707108 0 0">
                  <inertial pos="0.00182113 2.68e-06 0.00392718" quat="0.998858 0.000207108 -0.045317 0.0151267" mass="0.725594" diaginertia="0.00118335 0.00116041 0.000481204" />
                  <geom type="mesh" contype="0" conaffinity="0" group="1" density="0" rgba="1 1 0.4 1" mesh="right_shoulder_yaw" />
                  <body name="right_elbow_pitch_link" pos="-0.031 0 0.0365" quat="0.5 -0.5 0.5 -0.5">
                    <inertial pos="-2.604e-05 -0.0752983 0.0268563" quat="0.802034 0.597278 0.000362597 -2.24278e-05" mass="0.697801" diaginertia="0.00116302 0.00100116 0.000614171" />
                    <geom type="mesh" contype="0" conaffinity="0" group="1" density="0" rgba="0.4 1 0.4 1" mesh="right_elbow_pitch" />
                    <body name="right_elbow_yaw_link" pos="0 -0.117 0.031" quat="0.499999 -0.499999 -0.500001 -0.500001">
                      <inertial pos="3.656e-05 -0.00424199 -0.0542142" quat="0.996462 -0.0840255 0.000993479 -0.00116848" mass="0.287879" diaginertia="0.000714861 0.000702477 0.000540322" />
                      <geom type="mesh" contype="0" conaffinity="0" group="1" density="0" rgba="0 0.5 1 1" mesh="right_elbow_yaw" />
                      <body name="right_wrist_pitch_link" pos="0.006 0.0001 -0.1394" quat="0.439542 0.553896 -0.439547 -0.553896">
                        <inertial pos="0.00229425 0 9.994e-05" quat="0.707107 0 0 0.707107" mass="0.00900738" diaginertia="5.7e-07 3.8e-07 2.4e-07" />
                        <geom type="mesh" contype="0" conaffinity="0" group="1" density="0" rgba="0.8 1 0.8 1" mesh="right_wrist_pitch" />
                        <body name="right_wrist_roll_link" quat="0.150584 0.690886 -0.265822 -0.65524">
                          <inertial pos="-0.0201223 0.0187889 -0.0258569" quat="0.510135 0.859971 -0.0125709 -0.00742731" mass="0.370899" diaginertia="0.000404075 0.000356841 0.000211603" />
                        </body>
                      </body>
                      <body name="arm_r_wrist_a_ball_link" pos="-0.009 -0.02 -0.0199" quat="0.707105 0.707108 0 0">
                        <inertial pos="0.00076586 -0.0115683 4.912e-05" quat="0.490941 0.50421 -0.49667 0.508004" mass="0.235987" diaginertia="7.97705e-05 7.63707e-05 2.51588e-05" />
                        <geom type="mesh" contype="0" conaffinity="0" group="1" density="0" rgba="1 1 1 1" mesh="arm_r_wrist_a_ball" />
                        <body name="arm_r_wrist_motor_a_link" pos="0.0027628 -0.097124 0" quat="0.707034 0.707037 0.010054 0.010054">
                          <inertial pos="0 0 0.00973737" quat="0.707107 0 0 0.707107" mass="0.00117982" diaginertia="8e-08 6e-08 2e-08" />
                          <geom type="mesh" contype="0" conaffinity="0" group="1" density="0" rgba="1 1 1 1" mesh="arm_r_wrist_motor_a_link" />
                          <body name="arm_r_wrist_a_loop_link" pos="0 0 0.0132" quat="0.707034 -0.707037 -0.010054 -0.010054">
                            <inertial pos="0 0 -1.922e-05" mass="0.00548041" diaginertia="8e-08 8e-08 7e-08" />
                            <geom type="mesh" contype="0" conaffinity="0" group="1" density="0" rgba="1 1 1 1" mesh="arm_r_wrist_a_loop" />
                          </body>
                        </body>
                      </body>
                      <body name="arm_r_wrist_b_ball_link" pos="-0.009 0.02 -0.0199" quat="0.707105 -0.707108 0 0">
                        <inertial pos="0.00121967 0.0441726 0" quat="0.707014 0.707014 -0.0114787 -0.0114787" mass="0.0361757" diaginertia="1.73133e-05 1.731e-05 4.67668e-06" />
                        <geom type="mesh" contype="0" conaffinity="0" group="1" density="0" rgba="1 1 1 1" mesh="arm_r_wrist_b_ball" />
                        <body name="arm_r_wrist_motor_b_link" pos="0.0027628 0.097124 0" quat="0.707034 -0.707037 0.010054 -0.010054">
                          <inertial pos="0.00076586 0.0115683 4.912e-05" quat="0.50421 0.490941 -0.508004 0.49667" mass="0.235987" diaginertia="7.97705e-05 7.63707e-05 2.51588e-05" />
                          <geom type="mesh" contype="0" conaffinity="0" group="1" density="0" rgba="1 1 1 1" mesh="arm_r_wrist_motor_b_link" />
                          <body name="arm_r_wrist_b_loop_link" pos="0 0 0.0132" quat="0.707034 0.707037 -0.010054 0.010054">
                            <inertial pos="0 0 -0.00973737" quat="0.707107 0 0 0.707107" mass="0.00117982" diaginertia="8e-08 6e-08 2e-08" />
                            <geom type="mesh" contype="0" conaffinity="0" group="1" density="0" rgba="1 1 1 1" mesh="arm_r_wrist_b_loop" />
                          </body>
                        </body>
                      </body>
                    </body>
                  </body>
                </body>
              </body>
            </body>
            <body name="waist_motor_a_link" pos="0 0.075 0.0708">
              <inertial pos="-0.0404684 0 -0.00673515" quat="0.00694635 0.603061 0.00566511 0.797645" mass="0.058187" diaginertia="5.09864e-05 5.05299e-05 6.75372e-06" />
              <geom type="mesh" contype="0" conaffinity="0" group="1" density="0" rgba="0.776471 0.756863 0.737255 1" mesh="waist_motor_a_link" />
              <body name="waist_motor_a_ball_link" pos="-0.065 0 -0.0108" quat="0 1 0 0">
                <inertial pos="-0.00179727 0.0374998 -3.559e-05" quat="0.5 0.5 -0.5 0.5" mass="0.036139" diaginertia="3.624e-05 3.412e-05 2.43e-06" />
                <geom type="mesh" contype="0" conaffinity="0" group="1" density="0" rgba="0.776471 0.756863 0.737255 1" mesh="waist_motor_a_ball" />
                <body name="waist_motor_a_loop_link" pos="0 0.075 0" quat="0 1 0 0">
                  <inertial pos="0 0 0.00052471" mass="0.017653" diaginertia="8e-07 8e-07 3.5e-07" />
                  <geom type="mesh" contype="0" conaffinity="0" group="1" density="0" rgba="1 1 1 1" mesh="waist_motor_a_loop" />
                </body>
              </body>
            </body>
            <body name="waist_motor_b_link" pos="0 0.075 -0.0708" quat="0 1 0 0">
              <inertial pos="-0.0404684 0 -0.00673515" quat="0.00694635 0.603061 0.00566511 0.797645" mass="0.058187" diaginertia="5.09864e-05 5.05299e-05 6.75372e-06" />
              <geom type="mesh" contype="0" conaffinity="0" group="1" density="0" rgba="0.776471 0.756863 0.737255 1" mesh="waist_motor_b_link" />
              <body name="waist_motor_b_ball_link" pos="-0.065 0 -0.0108" quat="0 0.707107 0 -0.707107">
                <inertial pos="3.559e-05 -0.0374998 0.00179727" quat="0.707107 0.707107 0 0" mass="0.036139" diaginertia="3.624e-05 3.412e-05 2.43e-06" />
                <geom type="mesh" contype="0" conaffinity="0" group="1" density="0" rgba="1 1 1 1" mesh="waist_motor_b_ball" />
                <body name="waist_motor_b_loop_link" pos="0 -0.075 0">
                  <inertial pos="-0.00052471 0 0" quat="0.5 0.5 0.5 0.5" mass="0.017653" diaginertia="8e-07 8e-07 3.5e-07" />
                  <geom type="mesh" contype="0" conaffinity="0" group="1" density="0" rgba="1 1 1 1" mesh="waist_motor_b_loop" />
                </body>
              </body>
            </body>
          <geom type="mesh" mesh="lumbar_pitch_x1" contype="1" conaffinity="0" group="3" /></body>
        </body>
      </body>
      <body name="left_hip_pitch_link" pos="0.00245 0.092277 -0.012143" quat="0.65328 0.270599 -0.270598 0.653282">
        <inertial pos="-4.816e-05 -0.0107584 -0.0540778" quat="0.701067 -0.0888726 0.120485 0.697202" mass="1.67336" diaginertia="0.00256418 0.00234466 0.00215142" />
        <joint name="left_hip_pitch_joint" pos="0 0 0" axis="0 0 1" range="-1 2" actuatorfrcrange="-180 180" damping="1" />
        <geom type="mesh" contype="0" conaffinity="0" group="1" density="0" rgba="1 0.4 0.4 1" mesh="left_hip_pitch" />
        <body name="left_hip_roll_link" pos="0 -0.0405 -0.0589" quat="0.653281 0.653281 0.270598 -0.270598">
          <inertial pos="0.00014604 -0.0412348 -0.0101534" quat="0.30122 0.638429 -0.639374 0.304757" mass="0.285622" diaginertia="0.000612958 0.000557294 0.000275288" />
          <joint name="left_hip_roll_joint" pos="0 0 0" axis="0 0 -1" range="-1.5 0.2" actuatorfrcrange="-150 150" damping="1" />
          <geom type="mesh" contype="0" conaffinity="0" group="1" density="0" rgba="1 1 0.4 1" mesh="left_hip_roll" />
          <body name="left_hip_yaw_link" pos="0 -0.0838049 -0.0406" quat="0.707107 0.707107 0 0">
            <inertial pos="-0.00212295 -3.062e-05 0.0916484" quat="0.999467 0.000387515 -0.0324521 -0.0035558" mass="2.73696" diaginertia="0.0127474 0.0124495 0.00338744" />
            <joint name="left_hip_yaw_joint" pos="0 0 0" axis="0 0 -1" range="-1.5 1.5" actuatorfrcrange="-150 150" damping="1" />
            <geom type="mesh" contype="0" conaffinity="0" group="1" density="0" rgba="0.4 1 0.4 1" mesh="left_hip_yaw" />
            <body name="left_knee_pitch_link" pos="-0.0337 0 0.1422" quat="0.5 -0.5 0.5 -0.5">
              <inertial pos="-0.000466573 0 0.0283565" quat="0.508885 0.508885 -0.490954 0.490954" mass="1.68649" diaginertia="0.0097686 0.00938236 0.00210378" />
              <joint name="left_knee_pitch_joint" pos="0 0 0" axis="0 0 1" range="0 2" actuatorfrcrange="-180 180" damping="1" />
              <geom type="mesh" contype="0" conaffinity="0" group="1" density="0" rgba="0 0.5 1 1" mesh="left_knee_pitch" />
              <body name="left_ankle_pitch_link" pos="0 -0.30494 0.0336" quat="0 0 -1 0">
                <inertial pos="-2.32e-06 7.077e-05 -2.048e-05" quat="0.707107 0 0 0.707107" mass="0.0621721" diaginertia="2.373e-05 2.273e-05 6.68e-06" />
                <joint name="left_ankle_pitch_joint" pos="0 0 0" axis="0 0 -1" range="-0.41 0.35" actuatorfrcrange="-80 80" damping="1" />
                <geom type="mesh" contype="0" conaffinity="0" group="1" density="0" rgba="0 0.5 1 1" mesh="left_ankle_pitch" />
                <body name="left_ankle_roll_link" quat="0.707107 0 0.707107 0">
                  <inertial pos="0.00017156 -0.025247 -0.00019936" quat="0.707585 0.0111979 -0.0139853 0.706401" mass="0.589712" diaginertia="0.00190069 0.00152114 0.000541391" />
                  <joint name="left_ankle_roll_joint" pos="0 0 0" axis="0 0 1" range="-0.64 0.64" actuatorfrcrange="-80 80" damping="1" />
                  <geom type="mesh" contype="0" conaffinity="0" group="1" density="0" rgba="1 0.5 1 1" mesh="left_ankle_roll" />
                  <geom type="mesh" rgba="1 0.5 1 1" mesh="left_ankle_roll" />
                  <geom size="0.002" pos="0.03 -0.0408 0.07" type="sphere" contype="1" conaffinity="1" group="3" />
                  <geom size="0.002" pos="0.03 -0.0408 -0.07" type="sphere" contype="1" conaffinity="1" group="3" />
                  <geom size="0.002" pos="-0.03 -0.0408 0.07" type="sphere" contype="1" conaffinity="1" group="3" />
                  <geom size="0.002" pos="-0.03 -0.0408 -0.07" type="sphere" contype="1" conaffinity="1" group="3" />
                <geom type="sphere" size="0.02" pos="0.03 -0.0408 0.07" rgba="255 0 0 0.5" /><geom type="sphere" size="0.02" pos="0.03 -0.0408 -0.07" rgba="255 0 0 0.5" /><geom type="sphere" size="0.02" pos="-0.03 -0.0408 0.07" rgba="255 0 0 0.5" /><geom type="sphere" size="0.02" pos="-0.03 -0.0408 -0.07" rgba="255 0 0 0.5" /></body>
              </body>
              <body name="leg_l_toe_a_link" pos="0.01985 -0.109962 0.0336568" quat="0.707107 0 -0.707107 0">
                <inertial pos="-0.00875902 0.00339112 -0.00875449" quat="0.146527 0.583456 -0.108414 0.791426" mass="0.0311417" diaginertia="9.28705e-06 8.02562e-06 3.25733e-06" />
                <geom type="mesh" contype="0" conaffinity="0" group="1" density="0" rgba="1 1 1 1" mesh="leg_l_toe_a_link" />
                <body name="leg_l_toe_a_ball_link" pos="-0.0233806 0.00902193 -0.02115">
                  <inertial pos="-1.914e-05 -0.0941377 1.9e-06" quat="0.500119 0.499914 -0.500109 0.499859" mass="0.0567471" diaginertia="0.00022113 0.00022106 1.08995e-06" />
                  <geom type="mesh" contype="0" conaffinity="0" group="1" density="0" rgba="1 1 1 1" mesh="leg_l_toe_a_ball" />
                  <body name="leg_l_toe_a_loop_link" pos="0 -0.195 0" quat="0.707107 0 0.707107 0">
                    <inertial pos="0 0 -0.0006502" mass="0.0062017" diaginertia="2.8e-07 2.8e-07 1.2e-07" />
                    <geom type="mesh" contype="0" conaffinity="0" group="1" density="0" rgba="1 1 1 1" mesh="leg_l_toe_a_loop" />
                  </body>
                </body>
              </body>
              <body name="leg_l_toe_b_link" pos="0.01985 -0.164962 0.0335432" quat="0.707107 0 -0.707107 0">
                <inertial pos="0.0089831 0.00345524 -0.00906395" quat="-0.106739 0.798862 0.149404 0.572804" mass="0.03161" diaginertia="9.50881e-06 8.37471e-06 3.40648e-06" />
                <geom type="mesh" contype="0" conaffinity="0" group="1" density="0" rgba="1 1 1 1" mesh="leg_l_toe_b_link" />
                <body name="leg_l_toe_b_ball_link" pos="0.0233806 0.00902193 -0.02115">
                  <inertial pos="-2.566e-05 -0.0667639 2.566e-05" quat="0.500193 0.500193 -0.500193 0.499422" mass="0.0423305" diaginertia="9.17901e-05 9.17201e-05 9.49892e-07" />
                  <geom type="mesh" contype="0" conaffinity="0" group="1" density="0" rgba="1 1 1 1" mesh="leg_l_toe_b_ball" />
                  <body name="leg_l_toe_b_loop_link" pos="0 -0.14 0" quat="0.707107 0 0.707107 0">
                    <inertial pos="0 0 0.00064901" mass="0.0062017" diaginertia="2.8e-07 2.8e-07 1.2e-07" />
                    <geom type="mesh" contype="0" conaffinity="0" group="1" density="0" rgba="1 1 1 1" mesh="leg_l_toe_b_loop" />
                  </body>
                </body>
              </body>
            </body>
          </body>
        </body>
      </body>
      <body name="right_hip_pitch_link" pos="0.00245 -0.092277 -0.012143" quat="0.65328 -0.270599 -0.270598 -0.653282">
        <inertial pos="-4.816e-05 0.0107584 -0.0540778" quat="0.697202 0.120485 -0.0888726 0.701067" mass="1.67336" diaginertia="0.00256418 0.00234466 0.00215142" />
        <joint name="right_hip_pitch_joint" pos="0 0 0" axis="0 0 1" range="-2 1" actuatorfrcrange="-180 180" damping="1" />
        <geom type="mesh" contype="0" conaffinity="0" group="1" density="0" rgba="1 0.4 0.4 1" mesh="right_hip_pitch" />
        <body name="right_hip_roll_link" pos="0 0.0405 -0.0589" quat="0.653281 0.653281 0.270598 -0.270598">
          <inertial pos="0.00014604 -0.0412348 0.0101534" quat="0.639374 0.304757 -0.30122 0.638429" mass="0.285622" diaginertia="0.000612958 0.000557294 0.000275288" />
          <joint name="right_hip_roll_joint" pos="0 0 0" axis="0 0 1" range="-0.2 1.5" actuatorfrcrange="-150 150" damping="1" />
          <geom type="mesh" contype="0" conaffinity="0" group="1" density="0" rgba="1 1 0.4 1" mesh="right_hip_roll" />
          <body name="right_hip_yaw_link" pos="0 -0.0838049 0.0406" quat="0.707107 -0.707107 0 0">
            <inertial pos="-0.00212295 3.062e-05 -0.0916484" quat="0.999467 0.000387515 0.0324521 0.0035558" mass="2.73696" diaginertia="0.0127474 0.0124495 0.00338744" />
            <joint name="right_hip_yaw_joint" pos="0 0 0" axis="0 0 1" range="-1.5 1.5" actuatorfrcrange="-150 150" damping="1" />
            <geom type="mesh" contype="0" conaffinity="0" group="1" density="0" rgba="0.4 1 0.4 1" mesh="right_hip_yaw" />
            <body name="right_knee_pitch_link" pos="-0.0337 0 -0.1422" quat="0.5 0.5 0.5 0.5">
              <inertial pos="-0.00046657 0.136803 0.0283565" quat="0.5048 0.549095 -0.510608 0.427729" mass="1.68649" diaginertia="0.00989796 0.00939201 0.00196477" />
              <joint name="right_knee_pitch_joint" pos="0 0 0" axis="0 0 -1" range="0 2" actuatorfrcrange="-180 180" damping="1" />
              <geom type="mesh" contype="0" conaffinity="0" group="1" density="0" rgba="0 0.5 1 1" mesh="right_knee_pitch" />
              <body name="right_ankle_pitch_link" pos="0 -0.30494 0.0336" quat="0 1 0 0">
                <inertial pos="2.47e-06 -7.076e-05 -1.763e-05" quat="0.707107 -0.000207363 0.000207363 0.707107" mass="0.0621721" diaginertia="2.373e-05 2.273e-05 6.67999e-06" />
                <joint name="right_ankle_pitch_joint" pos="0 0 0" axis="0 0 1" range="-0.41 0.35" actuatorfrcrange="-80 80" damping="1" />
                <geom type="mesh" contype="0" conaffinity="0" group="1" density="0" rgba="0 0.5 1 1" mesh="right_ankle_pitch" />
                <body name="right_ankle_roll_link" quat="0.707107 0 0.707107 0">
                  <inertial pos="0.00017156 0.025247 -0.00019936" quat="0.706401 -0.0139853 0.0111979 0.707585" mass="0.589712" diaginertia="0.00190069 0.00152114 0.000541391" />
                  <joint name="right_ankle_roll_joint" pos="0 0 0" axis="0 0 1" range="-0.64 0.64" actuatorfrcrange="-80 80" damping="1" />
                  <geom type="mesh" contype="0" conaffinity="0" group="1" density="0" rgba="1 0.5 1 1" mesh="right_ankle_roll" />
                  <geom type="mesh" rgba="1 0.5 1 1" mesh="right_ankle_roll" />
                  <geom size="0.002" pos="0.03 0.0408 0.07" type="sphere" contype="1" conaffinity="1" group="3" />
                  <geom size="0.002" pos="0.03 0.0408 -0.07" type="sphere" contype="1" conaffinity="1" group="3" />
                  <geom size="0.002" pos="-0.03 0.0408 0.07" type="sphere" contype="1" conaffinity="1" group="3" />
                  <geom size="0.002" pos="-0.03 0.0408 -0.07" type="sphere" contype="1" conaffinity="1" group="3" />
                <geom type="sphere" size="0.02" pos="0.03 0.0408 0.07" rgba="255 0 0 0.5" /><geom type="sphere" size="0.02" pos="0.03 0.0408 -0.07" rgba="255 0 0 0.5" /><geom type="sphere" size="0.02" pos="-0.03 0.0408 0.07" rgba="255 0 0 0.5" /><geom type="sphere" size="0.02" pos="-0.03 0.0408 -0.07" rgba="255 0 0 0.5" /></body>
              </body>
              <body name="leg_r_toe_a_link" pos="-0.01985 -0.109962 0.0336568" quat="0.707107 0 0.707107 0">
                <inertial pos="0.00876658 0.00337152 -0.00875449" quat="-0.108632 0.791117 0.149032 0.583201" mass="0.0311417" diaginertia="9.28916e-06 8.02493e-06 3.25591e-06" />
                <geom type="mesh" contype="0" conaffinity="0" group="1" density="0" rgba="1 1 1 1" mesh="leg_r_toe_a_link" />
                <body name="leg_r_toe_a_ball_link" pos="0.0233806 0.00902193 -0.02115">
                  <inertial pos="-1.914e-05 -0.0941377 1.914e-05" quat="0.500162 0.500162 -0.500065 0.49961" mass="0.0567471" diaginertia="0.00022113 0.00022106 1.08991e-06" />
                  <geom type="mesh" contype="0" conaffinity="0" group="1" density="0" rgba="1 1 1 1" mesh="leg_r_toe_a_ball" />
                  <body name="leg_r_toe_a_loop_link" pos="0 -0.195 0" quat="0.707107 0 0.707107 0">
                    <inertial pos="0 0 0.00064901" mass="0.0062017" diaginertia="2.8e-07 2.8e-07 1.2e-07" />
                    <geom type="mesh" contype="0" conaffinity="0" group="1" density="0" rgba="1 1 1 1" mesh="leg_r_toe_a_loop" />
                  </body>
                </body>
              </body>
              <body name="leg_r_toe_b_link" pos="-0.01985 -0.164962 0.0335432" quat="0.707107 0 0.707107 0">
                <inertial pos="-0.00897565 0.00347454 -0.00906395" quat="0.149785 0.573148 -0.105705 0.798682" mass="0.03161" diaginertia="9.50806e-06 8.3821e-06 3.39984e-06" />
                <geom type="mesh" contype="0" conaffinity="0" group="1" density="0" rgba="1 1 1 1" mesh="leg_r_toe_b_link" />
                <body name="leg_r_toe_b_ball_link" pos="-0.0233806 0.00902193 -0.02115">
                  <inertial pos="-2.566e-05 -0.0667639 2.566e-05" quat="0.500193 0.500193 -0.500193 0.499422" mass="0.0423305" diaginertia="9.17901e-05 9.17201e-05 9.49892e-07" />
                  <geom type="mesh" contype="0" conaffinity="0" group="1" density="0" rgba="1 1 1 1" mesh="leg_r_toe_b_ball" />
                  <body name="leg_r_toe_b_loop_link" pos="0 -0.14 0" quat="0.707107 0 0.707107 0">
                    <inertial pos="0 0 -0.00064901" mass="0.0062017" diaginertia="2.8e-07 2.8e-07 1.2e-07" />
                    <geom type="mesh" contype="0" conaffinity="0" group="1" density="0" rgba="1 1 1 1" mesh="leg_r_toe_b_loop" />
                  </body>
                </body>
              </body>
            </body>
          </body>
        </body>
      </body>
    <camera name="track" pos="0 -3 1" quat="0.850651 0.525731 0 0" mode="track" /><geom type="mesh" mesh="base_link_simple" contype="1" conaffinity="0" group="3" /></body>
  </worldbody>
<option timestep="0.001" /><visual><global azimuth="150" elevation="-20" /><headlight ambient="0.3 0.3 0.3" diffuse="0.6 0.6 0.6" specular="0 0 0" /></visual><actuator><motor name="motor_left_hip_pitch" joint="left_hip_pitch_joint" ctrlrange="-150 150" gear="1.0" /><motor name="motor_left_hip_roll" joint="left_hip_roll_joint" ctrlrange="-50 50" gear="1.0" /><motor name="motor_left_hip_yaw" joint="left_hip_yaw_joint" ctrlrange="-50 50" gear="1.0" /><motor name="motor_left_knee_pitch" joint="left_knee_pitch_joint" ctrlrange="-150 150" gear="1.0" /><motor name="motor_left_ankle_pitch" joint="left_ankle_pitch_joint" ctrlrange="-18 18" gear="1.0" /><motor name="motor_left_ankle_roll" joint="left_ankle_roll_joint" ctrlrange="-18 18" gear="1.0" /><motor name="motor_right_hip_pitch" joint="right_hip_pitch_joint" ctrlrange="-150 150" gear="1.0" /><motor name="motor_right_hip_roll" joint="right_hip_roll_joint" ctrlrange="-50 50" gear="1.0" /><motor name="motor_right_hip_yaw" joint="right_hip_yaw_joint" ctrlrange="-50 50" gear="1.0" /><motor name="motor_right_knee_pitch" joint="right_knee_pitch_joint" ctrlrange="-150 150" gear="1.0" /><motor name="motor_right_ankle_pitch" joint="right_ankle_pitch_joint" ctrlrange="-18 18" gear="1.0" /><motor name="motor_right_ankle_roll" joint="right_ankle_roll_joint" ctrlrange="-18 18" gear="1.0" /></actuator><sensor><framequat name="body-orientation" objtype="site" objname="imu" noise="0" /><gyro name="body-angular-velocity" site="imu" noise="0.001" /><framepos name="body-linear-pos" objtype="site" objname="imu" /><velocimeter name="body-linear-vel" site="imu" /><accelerometer name="body-linear-acceleration" site="imu" noise="0.001" /><jointpos name="jointpos_left_hip_pitch" joint="left_hip_pitch_joint" noise="0" /><jointpos name="jointpos_left_hip_roll" joint="left_hip_roll_joint" noise="0" /><jointpos name="jointpos_left_hip_yaw" joint="left_hip_yaw_joint" noise="0" /><jointpos name="jointpos_left_knee_pitch" joint="left_knee_pitch_joint" noise="0" /><jointpos name="jointpos_left_ankle_pitch" joint="left_ankle_pitch_joint" noise="0" /><jointpos name="jointpos_left_ankle_roll" joint="left_ankle_roll_joint" noise="0" /><jointpos name="jointpos_right_hip_pitch" joint="right_hip_pitch_joint" noise="0" /><jointpos name="jointpos_right_hip_roll" joint="right_hip_roll_joint" noise="0" /><jointpos name="jointpos_right_hip_yaw" joint="right_hip_yaw_joint" noise="0" /><jointpos name="jointpos_right_knee_pitch" joint="right_knee_pitch_joint" noise="0" /><jointpos name="jointpos_right_ankle_pitch" joint="right_ankle_pitch_joint" noise="0" /><jointpos name="jointpos_right_ankle_roll" joint="right_ankle_roll_joint" noise="0" /><jointvel name="jointvel_left_hip_pitch" joint="left_hip_pitch_joint" noise="0" /><jointvel name="jointvel_left_hip_roll" joint="left_hip_roll_joint" noise="0" /><jointvel name="jointvel_left_hip_yaw" joint="left_hip_yaw_joint" noise="0" /><jointvel name="jointvel_left_knee_pitch" joint="left_knee_pitch_joint" noise="0" /><jointvel name="jointvel_left_ankle_pitch" joint="left_ankle_pitch_joint" noise="0" /><jointvel name="jointvel_left_ankle_roll" joint="left_ankle_roll_joint" noise="0" /><jointvel name="jointvel_right_hip_pitch" joint="right_hip_pitch_joint" noise="0" /><jointvel name="jointvel_right_hip_roll" joint="right_hip_roll_joint" noise="0" /><jointvel name="jointvel_right_hip_yaw" joint="right_hip_yaw_joint" noise="0" /><jointvel name="jointvel_right_knee_pitch" joint="right_knee_pitch_joint" noise="0" /><jointvel name="jointvel_right_ankle_pitch" joint="right_ankle_pitch_joint" noise="0" /><jointvel name="jointvel_right_ankle_roll" joint="right_ankle_roll_joint" noise="0" /></sensor><keyframe><key name="home_default" qpos="0 0 0.7 1 0 0 0 0 0 0 0 0 0 0 0 0 0 0 0" /><key name="check_pose" qpos="0 0 0.7 1 0 0 0 0.0 0.0 0.0 0.0 0.0 0.0 0.0 0.0 0.0 0.0 0.0 0.0" /></keyframe></mujoco>